<mujoco model="MyoHead">
<!-- =================================================
    Copyright 2020 Vikash Kumar, Vittorio Caggiano, Huawei Wang
    Model   :: MyoHead (MuJoCoV2.0)
    Author  :: Vikash Kumar (vikashplus@gmail.com), Vittorio Caggiano, Huawei Wang
    source  :: https://github.com/vikashplus

    This model has been converted from an OpenSim model. Model conversion by MyoConverter https://github.com/MyoHub/myoConverter.

    License :: Under Apache License, Version 2.0 (the "License"); you may not use this file except in compliance with the License. You may obtain a copy of the License at http://www.apache.org/licenses/LICENSE-2.0 Unless required by applicable law or agreed to in writing, software distributed under the License is distributed on an "AS IS" BASIS, WITHOUT WARRANTIES OR CONDITIONS OF ANY KIND, either express or implied. See the License for the specific language governing permissions and limitations under the License.
====================================================== -->

  <compiler angle="radian" />
  <option timestep="0.005" collision="predefined"/>
  <size njmax="1000" nconmax="400" nkey="1" nuser_jnt="1"/>

  <visual>
    <scale framelength="0.5" framewidth="0.01"/>
  </visual>

  <default class="main">
    <joint limited="true" armature="1e-05" damping="0.05"/>
    <geom margin="0.001" rgba="0.8 0.6 0.4 1"/>
    <site size="0.001 0.005 0.005"/>
    <tendon width="0.005" rgba="0.95 0.3 0.3 1"/>
    <default class="muscle">
      <general ctrllimited="true" ctrlrange="0 1" dyntype="muscle" gaintype="muscle" biastype="muscle" dynprm="0.01 0.04 0 0 0 0 0 0 0 0" gainprm="0.75 1.05 -1 200 0.5 1.6 1.5 1.3 1.2 0" biasprm="0.75 1.05 -1 200 0.5 1.6 1.5 1.3 1.2 0"/>
    </default>
  </default>


  <asset>
    <mesh name="spine_geom_1_tlspine" file="Geometry/tlspine.stl"/>
    <mesh name="rscapula_geom_1_rscapula" file="Geometry/rscapula.stl"/>
    <mesh name="rclavicle_geom_1_rclavicle" file="Geometry/rclavicle.stl"/>
    <mesh name="lscapula_geom_1_lscapula" file="Geometry/lscapula.stl"/>
    <mesh name="lclavicle_geom_1_lclavicle" file="Geometry/lclavicle.stl"/>
    <mesh name="ribcage_geom_1_ribcage" file="Geometry/ribcage.stl"/>
    <mesh name="cerv7_geom_1_rotatedcerv7" file="Geometry/rotatedcerv7.stl"/>
    <mesh name="cerv6_geom_1_cerv6" file="Geometry/cerv6.stl"/>
    <mesh name="cerv5_geom_1_cerv5" file="Geometry/cerv5.stl"/>
    <mesh name="cerv4_geom_1_cerv4" file="Geometry/cerv4.stl"/>
    <mesh name="cerv3_geom_1_cerv3" file="Geometry/cerv3.stl"/>
    <mesh name="cerv2_geom_1_cerv2" file="Geometry/cerv2.stl"/>
    <mesh name="cerv1_geom_1_cerv1" file="Geometry/cerv1.stl"/>
    <mesh name="skull_geom_1_skull" file="Geometry/skull.stl"/>
    <mesh name="jaw_geom_1_jaw" file="Geometry/jaw.stl"/>
  </asset>


  <worldbody>
    <light directional="false" diffuse=".5 .5 .5" specular="0.25 0.25 0.25" pos="0 -3 3" dir="0 1 -1" mode="trackcom"/>

    <body name="spine" euler="1.57 -1.57 0 ">
      <geom name="spine_geom_1" type="mesh" rgba="1 1 1 1" mesh="spine_geom_1_tlspine"/>
      <site name="long_col_c1thx_long_col_c1thx-P1" pos="-0.04888 0.30334 0.0037"/>
      <site name="long_col_c1thx_L_long_col_c1thx_L-P1" pos="-0.04888 0.30334 -0.0037"/>
      <site name="long_col_c5thx_long_col_c5thx-P1" pos="-0.04981 0.30296 0.0068"/>
      <site name="long_col_c5thx_long_col_c5thx-P2" pos="-0.04825 0.32027 0.01022"/>
      <site name="long_col_c5thx_long_col_c5thx-P3" pos="-0.04566 0.33463 0.01337"/>
      <site name="long_col_c5thx_long_col_c5thx-P4" pos="-0.04466 0.3436 0.01508"/>
      <site name="long_col_c5thx_long_col_c5thx-P5" pos="-0.04239 0.35783 0.01778"/>
      <site name="long_col_c5thx_L_long_col_c5thx_L-P1" pos="-0.04981 0.30296 -0.0068"/>
      <site name="long_col_c5thx_L_long_col_c5thx_L-P2" pos="-0.04825 0.32027 -0.01022"/>
      <site name="long_col_c5thx_L_long_col_c5thx_L-P3" pos="-0.04566 0.33463 -0.01337"/>
      <site name="long_col_c5thx_L_long_col_c5thx_L-P4" pos="-0.04466 0.3436 -0.01508"/>
      <site name="long_col_c5thx_L_long_col_c5thx_L-P5" pos="-0.04239 0.35783 -0.01778"/>
      <site name="splen_cap_sklthx_splen_cap_sklthx-P1" pos="-0.10384 0.33902 0.003"/>
      <site name="splen_cap_sklthx_L_splen_cap_sklthx_L-P1" pos="-0.10384 0.33902 -0.003"/>
      <site name="splen_cerv_c3thx_splen_cerv_c3thx-P1" pos="-0.12848 0.26222 0.0041"/>
      <site name="splen_cerv_c3thx_L_splen_cerv_c3thx_L-P1" pos="-0.12848 0.26222 -0.0041"/>
      <site name="semi_cap_sklthx_semi_cap_sklthx-P1" pos="-0.08539 0.37732 0.0347"/>
      <site name="semi_cap_sklthx_L_semi_cap_sklthx_L-P1" pos="-0.08539 0.37732 -0.0347"/>
      <site name="semi_cerv_c3thx_semi_cerv_c3thx-P1" pos="-0.08896 0.34997 0.02607"/>
      <site name="semi_cerv_c3thx_L_semi_cerv_c3thx_L-P1" pos="-0.08896 0.34997 -0.02607"/>
      <site name="longissi_cerv_c4thx_longissi_cerv_c4thx-P1" pos="-0.10994 0.27586 0.03215"/>
      <site name="longissi_cerv_c4thx_longissi_cerv_c4thx-P2" pos="-0.10918 0.30238 0.03041"/>
      <site name="longissi_cerv_c4thx_longissi_cerv_c4thx-P3" pos="-0.09978 0.32692 0.02919"/>
      <site name="longissi_cerv_c4thx_longissi_cerv_c4thx-P4" pos="-0.0813 0.373 0.0279"/>
      <site name="longissi_cerv_c4thx_L_longissi_cerv_c4thx_L-P1" pos="-0.10994 0.27586 -0.03215"/>
      <site name="longissi_cerv_c4thx_L_longissi_cerv_c4thx_L-P2" pos="-0.10918 0.30238 -0.03041"/>
      <site name="longissi_cerv_c4thx_L_longissi_cerv_c4thx_L-P3" pos="-0.09978 0.32692 -0.02919"/>
      <site name="longissi_cerv_c4thx_L_longissi_cerv_c4thx_L-P4" pos="-0.0813 0.373 -0.0279"/>
      <site name="iliocost_cerv_c5rib_iliocost_cerv_c5rib-P1" pos="-0.10349 0.32797 0.0533"/>
      <site name="iliocost_cerv_c5rib_iliocost_cerv_c5rib-P2" pos="-0.08374 0.37638 0.04035"/>
      <site name="iliocost_cerv_c5rib_L_iliocost_cerv_c5rib_L-P1" pos="-0.10349 0.32797 -0.0533"/>
      <site name="iliocost_cerv_c5rib_L_iliocost_cerv_c5rib_L-P2" pos="-0.08374 0.37638 -0.04035"/>
      <body name="rscapula" pos="-0.0366 0.3623 0.1837" quat="0.980384 0.0986852 -0.139174 -0.0986852">
        <inertial pos="0 0 0" mass="1" diaginertia="1 1 0.5"/>
        <geom name="rscapula_geom_1" type="mesh" rgba="1 1 1 1" mesh="rscapula_geom_1_rscapula"/>
        <site name="trap_acr_trap_acr-P1" pos="-0.02379 -0.00916 -0.00736"/>
        <site name="levator_scap_levator_scap-P1" pos="-0.09749 -0.03624 -0.08146"/>
        <site name="RCAJ_marker" pos="0 0.01 0.02" size="0.01" group="4" rgba="1 0.1 0.5 0.5"/>
      </body>
      <body name="rclavicle" pos="-0.0118 0.3353 0.022" quat="0.997565 0 0.0697433 0">
        <inertial pos="0 0 0" mass="1" diaginertia="1 1 0.5"/>
        <geom name="rclavicle_geom_1" type="mesh" rgba="1 1 1 1" mesh="rclavicle_geom_1_rclavicle"/>
        <site name="cleid_mast_cleid_mast-P1" pos="0.00388 0.00542 0.0352"/>
        <site name="cleid_occ_cleid_occ-P1" pos="0.00388 0.00542 0.0352"/>
        <site name="trap_cl_trap_cl-P1" pos="-0.0294 0.0232 0.0869"/>
      </body>
      <body name="lscapula" pos="-0.0366 0.3623 -0.1837" quat="0.980384 -0.0986852 0.139174 -0.0986852">
        <inertial pos="0 0 0" mass="1" diaginertia="1 1 0.5"/>
        <geom name="lscapula_geom_1" type="mesh" rgba="1 1 1 1" mesh="lscapula_geom_1_lscapula"/>
        <site name="trap_acr_L_trap_acr_L-P1" pos="-0.02379 -0.00916 0.00736"/>
        <site name="levator_scap_L_levator_scap_L-P1" pos="-0.09749 -0.03624 0.08146"/>
        <site name="LCAJ_marker" pos="0 0.01 -0.02" size="0.01" group="4" rgba="1 0.1 0.5 0.5"/>
      </body>
      <body name="lclavicle" pos="-0.0118 0.3353 -0.022" quat="0.997565 0 -0.0697433 0">
        <inertial pos="0 0 0" mass="1" diaginertia="1 1 0.5"/>
        <geom name="lclavicle_geom_1" type="mesh" rgba="1 1 1 1" mesh="lclavicle_geom_1_lclavicle"/>
        <site name="cleid_mast_L_cleid_mast_L-P1" pos="0.00388 0.00542 -0.0352"/>
        <site name="cleid_occ_L_cleid_occ_L-P1" pos="0.00388 0.00542 -0.0352"/>
        <site name="trap_cl_L_trap_cl_L-P1" pos="-0.0294 0.0232 -0.0869"/>
      </body>
      <body name="ribcage">
        <inertial pos="0 0 0" mass="1" diaginertia="1 1 0.75"/>
        <geom name="ribcage_geom_1" type="mesh" rgba="1 1 1 1" mesh="ribcage_geom_1_ribcage"/>
        <site name="Sterno_hyoid_default" pos="-0.014033 0.31252 0.01984"/>
        <site name="SternoThyroid_default" pos="-0.014643 0.30575 0.0153"/>
        <site name="Omo_hyoid_default" pos="-0.021033 0.37083 0.03774"/>
        <site name="Sterno_hyoid_L_default" pos="-0.014033 0.31252 -0.01984"/>
        <site name="SternoThyroid_L_default" pos="-0.014643 0.30575 -0.0153"/>
        <site name="Omo_hyoid_L_default" pos="-0.021033 0.37083 -0.03774"/>
        <site name="stern_mast_stern_mast-P1" pos="-0.0007 0.3269 0.0096"/>
        <site name="stern_mast_L_stern_mast_L-P1" pos="-0.0007 0.3269 -0.0096"/>
        <site name="scalenus_ant_scalenus_ant-P1" pos="-0.02139 0.33246 0.0529"/>
        <site name="scalenus_ant_L_scalenus_ant_L-P1" pos="-0.02139 0.33246 -0.0529"/>
        <site name="scalenus_med_scalenus_med-P1" pos="-0.03398 0.34333 0.0627"/>
        <site name="scalenus_med_L_scalenus_med_L-P1" pos="-0.03398 0.34333 -0.0627"/>
        <site name="scalenus_post_scalenus_post-P1" pos="-0.03638 0.3127 0.1062"/>
        <site name="scalenus_post_L_scalenus_post_L-P1" pos="-0.03638 0.3127 -0.1062"/>
        <site name="SJN_marker" pos="0.02 0.3516 0" size="0.01" group="4" rgba="1 0.1 0.5 0.5"/>
      </body>
      <body name="cerv7" pos="-0.05434 0.367 0">
        <inertial pos="-0.0002 0.0071 0" quat="0.707107 0 0 0.707107" mass="0.584085" diaginertia="0.04 0.04 0.04"/>
        <joint name="pitch2" pos="0 0 0" axis="0 0 1" range="-0.05702 0.08294" user="1.18003e-07"/>
        <joint name="roll2" pos="0 0 0" axis="1 0 0" range="-0.04492 0.04492"/>
        <joint name="yaw2" pos="0 0 0" axis="0 1 0" range="-0.02969 0.02969"/>
        <geom name="cerv7_geom_1" type="mesh" rgba="1 1 1 1" mesh="cerv7_geom_1_rotatedcerv7"/>
        <site name="long_col_c1thx_long_col_c1thx-P2" pos="0.0232 0.0011 0.004"/>
        <site name="long_col_c1thx_L_long_col_c1thx_L-P2" pos="0.0232 0.0011 -0.004"/>
        <site name="long_col_c5thx_long_col_c5thx-P6" pos="0.01111 0.00731 0.01979"/>
        <site name="long_col_c5thx_L_long_col_c5thx_L-P6" pos="0.01111 0.00731 -0.01979"/>
        <site name="trap_acr_trap_acr-P2" pos="-0.0477 0.019 0.00305"/>
        <site name="trap_acr_L_trap_acr_L-P2" pos="-0.0477 0.019 -0.00305"/>
        <body name="cerv6" pos="0.003837 0.01645 0">
          <inertial pos="0.0002 0.0064 0" quat="0.707107 0 0 0.707107" mass="0.507749" diaginertia="0.04 0.04 0.04"/>
          <joint name="aux7jnt_r3" pos="0 0 0" axis="0 0 1" limited="true" range="-1.57 1.57" user="2.22895e-07"/>
          <joint name="aux7jnt_r1" pos="0 0 0" axis="1 0 0" limited="true" range="-1.57 1.57"/>
          <joint name="aux7jnt_r2" pos="0 0 0" axis="0 1 0" limited="true" range="-1.57 1.57"/>
          <geom name="cerv6_geom_1" type="mesh" rgba="1 1 1 1" mesh="cerv6_geom_1_cerv6"/>
          <site name="long_col_c1thx_long_col_c1thx-P3" pos="0.02314 0.00231 0.00402"/>
          <site name="long_col_c1thx_L_long_col_c1thx_L-P3" pos="0.02314 0.00231 -0.00402"/>
          <site name="long_col_c5thx_long_col_c5thx-P7" pos="0.00961 0.00713 0.02216"/>
          <site name="long_col_c5thx_L_long_col_c5thx_L-P7" pos="0.00961 0.00713 -0.02216"/>
          <site name="splen_cap_sklc6_splen_cap_sklc6-P1" pos="-0.0486 0.01647 0.00305"/>
          <site name="splen_cap_sklc6_L_splen_cap_sklc6_L-P1" pos="-0.0486 0.01647 -0.00305"/>
          <site name="longissi_cap_sklc6_longissi_cap_sklc6-P1" pos="-0.00817 0.01515 0.02759"/>
          <site name="longissi_cap_sklc6_L_longissi_cap_sklc6_L-P1" pos="-0.00817 0.01515 -0.02759"/>
          <body name="cerv5" pos="0.00418 0.0179 0">
            <inertial pos="0.0001 0.0063 0" quat="0.707107 0 0 0.707107" mass="0.4291" diaginertia="0.04 0.04 0.04"/>
            <joint name="aux6jnt_r3" pos="0 0 0" axis="0 0 1" limited="true" range="-1.57 1.57" user="2.62229e-07"/>
            <joint name="aux6jnt_r1" pos="0 0 0" axis="1 0 0" limited="true" range="-1.57 1.57"/>
            <joint name="aux6jnt_r2" pos="0 0 0" axis="0 1 0" limited="true" range="-1.57 1.57"/>
            <geom name="cerv5_geom_1" type="mesh" rgba="1 1 1 1" mesh="cerv5_geom_1_cerv5"/>
            <site name="scalenus_post_scalenus_post-P2" pos="-0.0032 0.01371 0.0257"/>
            <site name="scalenus_post_L_scalenus_post_L-P2" pos="-0.0032 0.01371 -0.0257"/>
            <site name="long_col_c1thx_long_col_c1thx-P4" pos="0.02228 0.00228 0.0039"/>
            <site name="long_col_c1thx_L_long_col_c1thx_L-P4" pos="0.02228 0.00228 -0.0039"/>
            <site name="long_col_c1c5_long_col_c1c5-P1" pos="0.00669 0.00889 0.0238"/>
            <site name="long_col_c1c5_L_long_col_c1c5_L-P1" pos="0.00669 0.00889 -0.0238"/>
            <site name="long_col_c5thx_long_col_c5thx-P8" pos="0.00669 0.00889 0.0238"/>
            <site name="long_col_c5thx_L_long_col_c5thx_L-P8" pos="0.00669 0.00889 -0.0238"/>
            <site name="semi_cap_sklc5_semi_cap_sklc5-P1" pos="-0.00931 0.01154 0.0235"/>
            <site name="semi_cap_sklc5_L_semi_cap_sklc5_L-P1" pos="-0.00931 0.01154 -0.0235"/>
            <site name="iliocost_cerv_c5rib_iliocost_cerv_c5rib-P3" pos="-0.0094 0.01258 0.026"/>
            <site name="iliocost_cerv_c5rib_L_iliocost_cerv_c5rib_L-P3" pos="-0.0094 0.01258 -0.026"/>
            <body name="cerv4" pos="0.00341 0.01917 0">
              <inertial pos="-0.0003 0.0067 0" quat="0.707107 0 0 0.707107" mass="0.423317" diaginertia="0.04 0.04 0.04"/>
              <joint name="aux5jnt_r3" pos="0 0 0" axis="0 0 1" limited="true" range="-1.57 1.57" user="2.62229e-07"/>
              <joint name="aux5jnt_r1" pos="0 0 0" axis="1 0 0" limited="true" range="-1.57 1.57"/>
              <joint name="aux5jnt_r2" pos="0 0 0" axis="0 1 0" limited="true" range="-1.57 1.57"/>
              <geom name="cerv4_geom_1" type="mesh" rgba="1 1 1 1" mesh="cerv4_geom_1_cerv4"/>
              <site name="scalenus_ant_scalenus_ant-P2" pos="0.00713 0.0079 0.02323"/>
              <site name="scalenus_ant_L_scalenus_ant_L-P2" pos="0.00713 0.0079 -0.02323"/>
              <site name="long_cap_sklc4_long_cap_sklc4-P1" pos="0.00652 0.01164 0.0242"/>
              <site name="long_cap_sklc4_L_long_cap_sklc4_L-P1" pos="0.00652 0.01164 -0.0242"/>
              <site name="long_col_c1thx_long_col_c1thx-P5" pos="0.02205 0.00331 0.00379"/>
              <site name="long_col_c1thx_L_long_col_c1thx_L-P5" pos="0.02205 0.00331 -0.00379"/>
              <site name="long_col_c1c5_long_col_c1c5-P2" pos="0.01121 0.00749 0.0207"/>
              <site name="long_col_c1c5_L_long_col_c1c5_L-P2" pos="0.01121 0.00749 -0.0207"/>
              <site name="longissi_cerv_c4thx_longissi_cerv_c4thx-P5" pos="-0.00709 0.01157 0.0261"/>
              <site name="longissi_cerv_c4thx_L_longissi_cerv_c4thx_L-P5" pos="-0.00709 0.01157 -0.0261"/>
              <body name="cerv3" pos="0.00261 0.0154 0">
                <inertial pos="-0.0008 0.0071 0" quat="0.707107 0 0 0.707107" mass="0.419847" diaginertia="0.04 0.04 0.04"/>
                <joint name="aux4jnt_r3" pos="0 0 0" axis="0 0 1" limited="true" range="-1.57 1.57" user="1.96672e-07"/>
                <joint name="aux4jnt_r1" pos="0 0 0" axis="1 0 0" limited="true" range="-1.57 1.57"/>
                <joint name="aux4jnt_r2" pos="0 0 0" axis="0 1 0" limited="true" range="-1.57 1.57"/>
                <geom name="cerv3_geom_1" type="mesh" rgba="1 1 1 1" mesh="cerv3_geom_1_cerv3"/>
                <site name="digastric_post_digastricpost-P2" pos="0.02321 0.00597 0.0287"/>
                <site name="Sterno_hyoid_stern_mast-P1" pos="0.05742 -0.02314 0.00629"/>
                <site name="SternoThyroid_stern_mast-P1" pos="0.0404201 -0.04316 0.0133"/>
                <site name="Omo_hyoid_stern_mast-P1" pos="0.05212 -0.0139 0.0132"/>
                <site name="digastric_post_L_digastricpost-P2" pos="0.02321 0.00597 -0.0287"/>
                <site name="Sterno_hyoid_L_stern_mast-P1" pos="0.05742 -0.02314 -0.00629"/>
                <site name="SternoThyroid_L_stern_mast-P1" pos="0.0404201 -0.04316 -0.0133"/>
                <site name="Omo_hyoid_L_stern_mast-P1" pos="0.05212 -0.0139 -0.0132"/>
                <site name="scalenus_med_scalenus_med-P2" pos="-0.00902 0.00981 0.02119"/>
                <site name="scalenus_med_L_scalenus_med_L-P2" pos="-0.00902 0.00981 -0.02119"/>
                <site name="long_cap_sklc4_long_cap_sklc4-P2" pos="0.01197 0.01009 0.01897"/>
                <site name="long_cap_sklc4_L_long_cap_sklc4_L-P2" pos="0.01197 0.01009 -0.01897"/>
                <site name="long_col_c1thx_long_col_c1thx-P6" pos="0.02212 0.00603 0.00368"/>
                <site name="long_col_c1thx_L_long_col_c1thx_L-P6" pos="0.02212 0.00603 -0.00368"/>
                <site name="splen_cerv_c3thx_splen_cerv_c3thx-P2" pos="-0.00787 0.01005 0.02365"/>
                <site name="splen_cerv_c3thx_L_splen_cerv_c3thx_L-P2" pos="-0.00787 0.01005 -0.02365"/>
                <site name="semi_cerv_c3thx_semi_cerv_c3thx-P2" pos="-0.04064 -0.00322 0.0024"/>
                <site name="semi_cerv_c3thx_L_semi_cerv_c3thx_L-P2" pos="-0.04064 -0.00322 -0.0024"/>
                <body name="cerv2" pos="-0.00018 0.01629 0">
                  <inertial pos="-0.001 0.0059 0" quat="0.707107 0 0 0.707107" mass="0.587554" diaginertia="0.04 0.04 0.04"/>
                  <joint name="aux3jnt_r3" pos="0 0 0" axis="0 0 1" limited="true" range="-1.57 1.57" user="1.31115e-07"/>
                  <joint name="aux3jnt_r1" pos="0 0 0" axis="1 0 0" limited="true" range="-1.57 1.57"/>
                  <joint name="aux3jnt_r2" pos="0 0 0" axis="0 1 0" limited="true" range="-1.57 1.57"/>
                  <geom name="cerv2_geom_1" type="mesh" rgba="1 1 1 1" mesh="cerv2_geom_1_cerv2"/>
                  <site name="long_cap_sklc4_long_cap_sklc4-P3" pos="0.0172 0.00829 0.01477"/>
                  <site name="long_cap_sklc4_L_long_cap_sklc4_L-P3" pos="0.0172 0.00829 -0.01477"/>
                  <site name="long_col_c1thx_long_col_c1thx-P7" pos="0.02122 0.00973 0.00356"/>
                  <site name="long_col_c1thx_L_long_col_c1thx_L-P7" pos="0.02122 0.00973 -0.00356"/>
                  <site name="long_col_c1c5_long_col_c1c5-P3" pos="0.01739 0.00159 0.01365"/>
                  <site name="long_col_c1c5_L_long_col_c1c5_L-P3" pos="0.01739 0.00159 -0.01365"/>
                  <site name="levator_scap_levator_scap-P2" pos="-0.01186 0.00725 0.02121"/>
                  <site name="levator_scap_L_levator_scap_L-P2" pos="-0.01186 0.00725 -0.02121"/>
                  <site name="rectcap_post_maj_rectcap_post_maj-P1" pos="-0.03637 -0.00647 0.0024"/>
                  <site name="rectcap_post_maj_L_rectcap_post_maj_L-P1" pos="-0.03637 -0.00647 -0.0024"/>
                  <site name="obl_cap_inf_obl_cap_inf-P1" pos="-0.03637 -0.00647 0.00547"/>
                  <site name="obl_cap_inf_L_obl_cap_inf_L-P1" pos="-0.03637 -0.00647 -0.00547"/>
                  <body name="cerv1" pos="-0.03556 0.01776 0">
                    <inertial pos="0.0312 0.0019 0" quat="0.707107 0 0 0.707107" mass="0.467268" diaginertia="0.04 0.04 0.04"/>
                    <joint name="pitch1" pos="0 0 0" axis="0 0 1" range="-0.124 0.186" user="6.98927e-07"/>
                    <joint name="roll1" pos="0 0 0" axis="1 0 0" range="-0.05236 0.05236"/>
                    <joint name="yaw1" pos="0 0 0" axis="0 1 0" range="-0.5896 0.5896"/>
                    <geom name="cerv1_geom_1" type="mesh" rgba="1 1 1 1" mesh="cerv1_geom_1_cerv1"/>
                    <site name="digastric_ant_digastricpost-P2" pos="0.07289 -0.05758 0.0057"/>
                    <site name="Geniohyoid_digastricpost-P1" pos="0.0717298 -0.0537906 0.00509443"/>
                    <site name="Mylohyoid_Post_digastricpost-P1" pos="0.07525 -0.05588 0.0031"/>
                    <site name="Mylohyoid_Ant_digastricpost-P1" pos="0.09725 -0.05668 -0.0031"/>
                    <site name="Stylohyoid_Lat_digastricpost-P2" pos="0.0643381 -0.0496832 0.01544"/>
                    <site name="Stylohyoid_Med_digastricpost-P2" pos="0.0632661 -0.0450538 0.0162521"/>
                    <site name="digastric_ant_L_digastricpost-P2" pos="0.07289 -0.05758 -0.0057"/>
                    <site name="Geniohyoid_L_digastricpost-P1" pos="0.0714947 -0.0538159 -0.00630312"/>
                    <site name="Mylohyoid_Post_L_digastricpost-P1" pos="0.07525 -0.05588 -0.0031"/>
                    <site name="Mylohyoid_Ant_L_digastricpost-P1" pos="0.09725 -0.05668 0.0031"/>
                    <site name="Stylohyoid_Lat_L_digastricpost-P2" pos="0.0636822 -0.0497536 -0.0163531"/>
                    <site name="Stylohyoid_Med_L_digastricpost-P2" pos="0.0625772 -0.0451277 -0.0171408"/>
                    <site name="long_cap_sklc4_long_cap_sklc4-P4" pos="0.05818 0.00309 0.01159"/>
                    <site name="long_cap_sklc4_L_long_cap_sklc4_L-P4" pos="0.05818 0.00309 -0.01159"/>
                    <site name="long_col_c1thx_long_col_c1thx-P8" pos="0.05825 0.00482 0.0031"/>
                    <site name="long_col_c1thx_L_long_col_c1thx_L-P8" pos="0.05825 0.00482 -0.0031"/>
                    <site name="long_col_c1c5_long_col_c1c5-P4" pos="0.05725 0.00482 0.0062"/>
                    <site name="long_col_c1c5_L_long_col_c1c5_L-P4" pos="0.05725 0.00482 -0.0062"/>
                    <site name="rectcap_post_min_rectcap_post_min-P1" pos="7e-05 0.0009 0.0061"/>
                    <site name="rectcap_post_min_L_rectcap_post_min_L-P1" pos="7e-05 0.0009 -0.0061"/>
                    <site name="obl_cap_sup_obl_cap_sup-P1" pos="0.03505 0.00385 0.042"/>
                    <site name="obl_cap_sup_L_obl_cap_sup_L-P1" pos="0.03505 0.00385 -0.042"/>
                    <site name="obl_cap_inf_obl_cap_inf-P2" pos="0.02996 0.00349 0.03791"/>
                    <site name="obl_cap_inf_L_obl_cap_inf_L-P2" pos="0.02996 0.00349 -0.03791"/>
                    <body name="skull" pos="0.04335 0.01492 0">
                      <inertial pos="0.0173 0.063 0" quat="0.5 0.5 -0.5 0.5" mass="4.3" diaginertia="0.022605 0.02073 0.015"/>
                      <joint name="aux1jnt_r3" pos="0 0 0" axis="0 0 1" limited="true" range="-1.57 1.57" user="8.75233e-07"/>
                      <joint name="aux1jnt_r1" pos="0 0 0" axis="1 0 0" limited="true" range="-1.57 1.57"/>
                      <joint name="aux1jnt_r2" pos="0 0 0" axis="0 1 0" limited="true" range="-1.57 1.57"/>
                      <geom name="skull_geom_1" type="mesh" rgba="1 1 1 1" mesh="skull_geom_1_skull"/>
                      <site name="digastric_post_digastricpost-P1" pos="-0.0061 0.0034 0.0477"/>
                      <site name="digastric_ant_digastricpost-P1" pos="0.0303 -0.0643 0.0173"/>
                      <site name="Geniohyoid_digastricpost-P2" pos="0.0691 -0.0673 0.0016"/>
                      <site name="Mylohyoid_Post_digastricpost-P2" pos="0.0413 -0.0389 0.0291"/>
                      <site name="Mylohyoid_Ant_digastricpost-P2" pos="0.0579 -0.0596 0.0158"/>
                      <site name="Stylohyoid_Lat_digastricpost-P1" pos="0.0113 -0.0008 0.0376"/>
                      <site name="Stylohyoid_Med_digastricpost-P1" pos="0.0118 -0.002 0.0376"/>
                      <site name="digastric_post_L_digastricpost-P1" pos="-0.0061 0.0034 -0.0477"/>
                      <site name="digastric_ant_L_digastricpost-P1" pos="0.0303 -0.0643 -0.0173"/>
                      <site name="Geniohyoid_L_digastricpost-P2" pos="0.0691 -0.0673 -0.0016"/>
                      <site name="Mylohyoid_Post_L_digastricpost-P2" pos="0.0413 -0.0389 -0.0291"/>
                      <site name="Mylohyoid_Ant_L_digastricpost-P2" pos="0.0579 -0.0596 -0.0158"/>
                      <site name="Stylohyoid_Lat_L_digastricpost-P1" pos="0.0113 -0.0008 -0.0376"/>
                      <site name="Stylohyoid_Med_L_digastricpost-P1" pos="0.0118 -0.002 -0.0376"/>
                      <site name="stern_mast_stern_mast-P2" pos="-0.0051 0.00693 0.0643"/>
                      <site name="stern_mast_L_stern_mast_L-P2" pos="-0.0051 0.00693 -0.0643"/>
                      <site name="cleid_mast_cleid_mast-P2" pos="-0.0051 0.00693 0.0643"/>
                      <site name="cleid_mast_L_cleid_mast_L-P2" pos="-0.0051 0.00693 -0.0643"/>
                      <site name="cleid_occ_cleid_occ-P2" pos="-0.035 0.023 0.0664"/>
                      <site name="cleid_occ_L_cleid_occ_L-P2" pos="-0.035 0.023 -0.0664"/>
                      <site name="long_cap_sklc4_long_cap_sklc4-P5" pos="0.0098 0.01596 0.0036"/>
                      <site name="long_cap_sklc4_L_long_cap_sklc4_L-P5" pos="0.0098 0.01596 -0.0036"/>
                      <site name="trap_cl_trap_cl-P2" pos="-0.08031 0.02604 0.01324"/>
                      <site name="trap_cl_L_trap_cl_L-P2" pos="-0.08031 0.02604 -0.01324"/>
                      <site name="splen_cap_sklc6_splen_cap_sklc6-P2" pos="-0.06164 0.01918 0.044"/>
                      <site name="splen_cap_sklc6_L_splen_cap_sklc6_L-P2" pos="-0.06164 0.01918 -0.044"/>
                      <site name="splen_cap_sklthx_splen_cap_sklthx-P2" pos="-0.04016 0.011 0.05423"/>
                      <site name="splen_cap_sklthx_L_splen_cap_sklthx_L-P2" pos="-0.04016 0.011 -0.05423"/>
                      <site name="semi_cap_sklc5_semi_cap_sklc5-P2" pos="-0.07441 0.02 0.018"/>
                      <site name="semi_cap_sklc5_L_semi_cap_sklc5_L-P2" pos="-0.07441 0.02 -0.018"/>
                      <site name="semi_cap_sklthx_semi_cap_sklthx-P2" pos="-0.07671 0.02 0.0111"/>
                      <site name="semi_cap_sklthx_L_semi_cap_sklthx_L-P2" pos="-0.07671 0.02 -0.0111"/>
                      <site name="longissi_cap_sklc6_longissi_cap_sklc6-P2" pos="-0.0344 0.0051 0.055"/>
                      <site name="longissi_cap_sklc6_L_longissi_cap_sklc6_L-P2" pos="-0.0344 0.0051 -0.055"/>
                      <site name="rectcap_post_maj_rectcap_post_maj-P2" pos="-0.0604 0.009 0.023"/>
                      <site name="rectcap_post_maj_L_rectcap_post_maj_L-P2" pos="-0.0604 0.009 -0.023"/>
                      <site name="rectcap_post_min_rectcap_post_min-P2" pos="-0.0667 0.009 0.0145"/>
                      <site name="rectcap_post_min_L_rectcap_post_min_L-P2" pos="-0.0667 0.009 -0.0145"/>
                      <site name="obl_cap_sup_obl_cap_sup-P2" pos="-0.04758 0.00931 0.03818"/>
                      <site name="obl_cap_sup_L_obl_cap_sup_L-P2" pos="-0.04758 0.00931 -0.03818"/>
                      <site name="RAH_marker" pos="0.1 0.1 0.05" size="0.01" group="4" rgba="1 0.1 0.5 0.5"/>
                      <site name="LAH_marker" pos="0.1 0.1 -0.06" size="0.01" group="4" rgba="1 0.1 0.5 0.5"/>
                      <site name="RPH_marker" pos="-0.09 0.1 0.045" size="0.01" group="4" rgba="1 0.1 0.5 0.5"/>
                      <site name="LPH_marker" pos="-0.09 0.1 -0.045" size="0.01" group="4" rgba="1 0.1 0.5 0.5"/>
                      <body name="jaw">
                        <inertial pos="0 0.05 0" mass="0.5" diaginertia="0.001 0.001 0.001"/>
                        <geom name="jaw_geom_1" type="mesh" rgba="1 1 1 1" mesh="jaw_geom_1_jaw"/>
                      </body>
                    </body>
                  </body>
                </body>
              </body>
            </body>
          </body>
        </body>
      </body>
    </body>
  </worldbody>


  <equality>
    <joint name="aux7jnt_r1_con" joint1="aux7jnt_r1" joint2="roll2" polycoef="0 1.756 0 0 0" solimp="0.9999 0.9999 0.001 0.5 2"/>
    <joint name="aux7jnt_r2_con" joint1="aux7jnt_r2" joint2="yaw2" polycoef="0 2.984 0 0 0" solimp="0.9999 0.9999 0.001 0.5 2"/>
    <joint name="aux7jnt_r3_con" joint1="aux7jnt_r3" joint2="pitch2" polycoef="0 1.889 0 0 0" solimp="0.9999 0.9999 0.001 0.5 2"/>
    <joint name="aux6jnt_r1_con" joint1="aux6jnt_r1" joint2="roll2" polycoef="0 2.013 0 0 0" solimp="0.9999 0.9999 0.001 0.5 2"/>
    <joint name="aux6jnt_r2_con" joint1="aux6jnt_r2" joint2="yaw2" polycoef="0 3.476 0 0 0" solimp="0.9999 0.9999 0.001 0.5 2"/>
    <joint name="aux6jnt_r3_con" joint1="aux6jnt_r3" joint2="pitch2" polycoef="0 2.222 0 0 0" solimp="0.9999 0.9999 0.001 0.5 2"/>
    <joint name="aux5jnt_r1_con" joint1="aux5jnt_r1" joint2="roll2" polycoef="0 2.769 0 0 0" solimp="0.9999 0.9999 0.001 0.5 2"/>
    <joint name="aux5jnt_r2_con" joint1="aux5jnt_r2" joint2="yaw2" polycoef="0 3.476 0 0 0" solimp="0.9999 0.9999 0.001 0.5 2"/>
    <joint name="aux5jnt_r3_con" joint1="aux5jnt_r3" joint2="pitch2" polycoef="0 2.222 0 0 0" solimp="0.9999 0.9999 0.001 0.5 2"/>
    <joint name="aux4jnt_r1_con" joint1="aux4jnt_r1" joint2="roll2" polycoef="0 2.769 0 0 0" solimp="0.9999 0.9999 0.001 0.5 2"/>
    <joint name="aux4jnt_r2_con" joint1="aux4jnt_r2" joint2="yaw2" polycoef="0 3.476 0 0 0" solimp="0.9999 0.9999 0.001 0.5 2"/>
    <joint name="aux4jnt_r3_con" joint1="aux4jnt_r3" joint2="pitch2" polycoef="0 1.667 0 0 0" solimp="0.9999 0.9999 0.001 0.5 2"/>
    <joint name="aux3jnt_r1_con" joint1="aux3jnt_r1" joint2="roll2" polycoef="0 2.513 0 0 0" solimp="0.9999 0.9999 0.001 0.5 2"/>
    <joint name="aux3jnt_r2_con" joint1="aux3jnt_r2" joint2="yaw2" polycoef="0 1.492 0 0 0" solimp="0.9999 0.9999 0.001 0.5 2"/>
    <joint name="aux3jnt_r3_con" joint1="aux3jnt_r3" joint2="pitch2" polycoef="0 1.111 0 0 0" solimp="0.9999 0.9999 0.001 0.5 2"/>
    <joint name="aux1jnt_r1_con" joint1="aux1jnt_r1" joint2="roll1" polycoef="0 1 0 0 0" solimp="0.9999 0.9999 0.001 0.5 2"/>
    <joint name="aux1jnt_r2_con" joint1="aux1jnt_r2" joint2="yaw1" polycoef="0 0.1249 0 0 0" solimp="0.9999 0.9999 0.001 0.5 2"/>
    <joint name="aux1jnt_r3_con" joint1="aux1jnt_r3" joint2="pitch1" polycoef="0 1.252 0 0 0" solimp="0.9999 0.9999 0.001 0.5 2"/>
  </equality>

  <tendon>
    <spatial name="digastric_post_tendon">
      <site site="digastric_post_digastricpost-P1"/>
      <site site="digastric_post_digastricpost-P2"/>
    </spatial>
    <spatial name="digastric_ant_tendon">
      <site site="digastric_ant_digastricpost-P1"/>
      <site site="digastric_ant_digastricpost-P2"/>
    </spatial>
    <spatial name="Geniohyoid_tendon">
      <site site="Geniohyoid_digastricpost-P1"/>
      <site site="Geniohyoid_digastricpost-P2"/>
    </spatial>
    <spatial name="Mylohyoid_Post_tendon">
      <site site="Mylohyoid_Post_digastricpost-P1"/>
      <site site="Mylohyoid_Post_digastricpost-P2"/>
    </spatial>
    <spatial name="Mylohyoid_Ant_tendon">
      <site site="Mylohyoid_Ant_digastricpost-P1"/>
      <site site="Mylohyoid_Ant_digastricpost-P2"/>
    </spatial>
    <spatial name="Stylohyoid_Lat_tendon">
      <site site="Stylohyoid_Lat_digastricpost-P1"/>
      <site site="Stylohyoid_Lat_digastricpost-P2"/>
    </spatial>
    <spatial name="Stylohyoid_Med_tendon">
      <site site="Stylohyoid_Med_digastricpost-P1"/>
      <site site="Stylohyoid_Med_digastricpost-P2"/>
    </spatial>
    <spatial name="Sterno_hyoid_tendon">
      <site site="Sterno_hyoid_stern_mast-P1"/>
      <site site="Sterno_hyoid_default"/>
    </spatial>
    <spatial name="SternoThyroid_tendon">
      <site site="SternoThyroid_stern_mast-P1"/>
      <site site="SternoThyroid_default"/>
    </spatial>
    <spatial name="Omo_hyoid_tendon">
      <site site="Omo_hyoid_stern_mast-P1"/>
      <site site="Omo_hyoid_default"/>
    </spatial>
    <spatial name="digastric_post_L_tendon">
      <site site="digastric_post_L_digastricpost-P1"/>
      <site site="digastric_post_L_digastricpost-P2"/>
    </spatial>
    <spatial name="digastric_ant_L_tendon">
      <site site="digastric_ant_L_digastricpost-P1"/>
      <site site="digastric_ant_L_digastricpost-P2"/>
    </spatial>
    <spatial name="Geniohyoid_L_tendon">
      <site site="Geniohyoid_L_digastricpost-P1"/>
      <site site="Geniohyoid_L_digastricpost-P2"/>
    </spatial>
    <spatial name="Mylohyoid_Post_L_tendon">
      <site site="Mylohyoid_Post_L_digastricpost-P1"/>
      <site site="Mylohyoid_Post_L_digastricpost-P2"/>
    </spatial>
    <spatial name="Mylohyoid_Ant_L_tendon">
      <site site="Mylohyoid_Ant_L_digastricpost-P1"/>
      <site site="Mylohyoid_Ant_L_digastricpost-P2"/>
    </spatial>
    <spatial name="Stylohyoid_Lat_L_tendon">
      <site site="Stylohyoid_Lat_L_digastricpost-P1"/>
      <site site="Stylohyoid_Lat_L_digastricpost-P2"/>
    </spatial>
    <spatial name="Stylohyoid_Med_L_tendon">
      <site site="Stylohyoid_Med_L_digastricpost-P1"/>
      <site site="Stylohyoid_Med_L_digastricpost-P2"/>
    </spatial>
    <spatial name="Sterno_hyoid_L_tendon">
      <site site="Sterno_hyoid_L_stern_mast-P1"/>
      <site site="Sterno_hyoid_L_default"/>
    </spatial>
    <spatial name="SternoThyroid_L_tendon">
      <site site="SternoThyroid_L_stern_mast-P1"/>
      <site site="SternoThyroid_L_default"/>
    </spatial>
    <spatial name="Omo_hyoid_L_tendon">
      <site site="Omo_hyoid_L_stern_mast-P1"/>
      <site site="Omo_hyoid_L_default"/>
    </spatial>
    <spatial name="stern_mast_tendon">
      <site site="stern_mast_stern_mast-P1"/>
      <site site="stern_mast_stern_mast-P2"/>
    </spatial>
    <spatial name="stern_mast_L_tendon">
      <site site="stern_mast_L_stern_mast_L-P1"/>
      <site site="stern_mast_L_stern_mast_L-P2"/>
    </spatial>
    <spatial name="cleid_mast_tendon">
      <site site="cleid_mast_cleid_mast-P1"/>
      <site site="cleid_mast_cleid_mast-P2"/>
    </spatial>
    <spatial name="cleid_mast_L_tendon">
      <site site="cleid_mast_L_cleid_mast_L-P1"/>
      <site site="cleid_mast_L_cleid_mast_L-P2"/>
    </spatial>
    <spatial name="cleid_occ_tendon">
      <site site="cleid_occ_cleid_occ-P1"/>
      <site site="cleid_occ_cleid_occ-P2"/>
    </spatial>
    <spatial name="cleid_occ_L_tendon">
      <site site="cleid_occ_L_cleid_occ_L-P1"/>
      <site site="cleid_occ_L_cleid_occ_L-P2"/>
    </spatial>
    <spatial name="scalenus_ant_tendon">
      <site site="scalenus_ant_scalenus_ant-P1"/>
      <site site="scalenus_ant_scalenus_ant-P2"/>
    </spatial>
    <spatial name="scalenus_ant_L_tendon">
      <site site="scalenus_ant_L_scalenus_ant_L-P1"/>
      <site site="scalenus_ant_L_scalenus_ant_L-P2"/>
    </spatial>
    <spatial name="scalenus_med_tendon">
      <site site="scalenus_med_scalenus_med-P1"/>
      <site site="scalenus_med_scalenus_med-P2"/>
    </spatial>
    <spatial name="scalenus_med_L_tendon">
      <site site="scalenus_med_L_scalenus_med_L-P1"/>
      <site site="scalenus_med_L_scalenus_med_L-P2"/>
    </spatial>
    <spatial name="scalenus_post_tendon">
      <site site="scalenus_post_scalenus_post-P1"/>
      <site site="scalenus_post_scalenus_post-P2"/>
    </spatial>
    <spatial name="scalenus_post_L_tendon">
      <site site="scalenus_post_L_scalenus_post_L-P1"/>
      <site site="scalenus_post_L_scalenus_post_L-P2"/>
    </spatial>
    <spatial name="long_cap_sklc4_tendon">
      <site site="long_cap_sklc4_long_cap_sklc4-P1"/>
      <site site="long_cap_sklc4_long_cap_sklc4-P2"/>
      <site site="long_cap_sklc4_long_cap_sklc4-P3"/>
      <site site="long_cap_sklc4_long_cap_sklc4-P4"/>
      <site site="long_cap_sklc4_long_cap_sklc4-P5"/>
    </spatial>
    <spatial name="long_cap_sklc4_L_tendon">
      <site site="long_cap_sklc4_L_long_cap_sklc4_L-P1"/>
      <site site="long_cap_sklc4_L_long_cap_sklc4_L-P2"/>
      <site site="long_cap_sklc4_L_long_cap_sklc4_L-P3"/>
      <site site="long_cap_sklc4_L_long_cap_sklc4_L-P4"/>
      <site site="long_cap_sklc4_L_long_cap_sklc4_L-P5"/>
    </spatial>
    <spatial name="long_col_c1thx_tendon">
      <site site="long_col_c1thx_long_col_c1thx-P1"/>
      <site site="long_col_c1thx_long_col_c1thx-P2"/>
      <site site="long_col_c1thx_long_col_c1thx-P3"/>
      <site site="long_col_c1thx_long_col_c1thx-P4"/>
      <site site="long_col_c1thx_long_col_c1thx-P5"/>
      <site site="long_col_c1thx_long_col_c1thx-P6"/>
      <site site="long_col_c1thx_long_col_c1thx-P7"/>
      <site site="long_col_c1thx_long_col_c1thx-P8"/>
    </spatial>
    <spatial name="long_col_c1thx_L_tendon">
      <site site="long_col_c1thx_L_long_col_c1thx_L-P1"/>
      <site site="long_col_c1thx_L_long_col_c1thx_L-P2"/>
      <site site="long_col_c1thx_L_long_col_c1thx_L-P3"/>
      <site site="long_col_c1thx_L_long_col_c1thx_L-P4"/>
      <site site="long_col_c1thx_L_long_col_c1thx_L-P5"/>
      <site site="long_col_c1thx_L_long_col_c1thx_L-P6"/>
      <site site="long_col_c1thx_L_long_col_c1thx_L-P7"/>
      <site site="long_col_c1thx_L_long_col_c1thx_L-P8"/>
    </spatial>
    <spatial name="long_col_c1c5_tendon">
      <site site="long_col_c1c5_long_col_c1c5-P1"/>
      <site site="long_col_c1c5_long_col_c1c5-P2"/>
      <site site="long_col_c1c5_long_col_c1c5-P3"/>
      <site site="long_col_c1c5_long_col_c1c5-P4"/>
    </spatial>
    <spatial name="long_col_c1c5_L_tendon">
      <site site="long_col_c1c5_L_long_col_c1c5_L-P1"/>
      <site site="long_col_c1c5_L_long_col_c1c5_L-P2"/>
      <site site="long_col_c1c5_L_long_col_c1c5_L-P3"/>
      <site site="long_col_c1c5_L_long_col_c1c5_L-P4"/>
    </spatial>
    <spatial name="long_col_c5thx_tendon">
      <site site="long_col_c5thx_long_col_c5thx-P1"/>
      <site site="long_col_c5thx_long_col_c5thx-P2"/>
      <site site="long_col_c5thx_long_col_c5thx-P3"/>
      <site site="long_col_c5thx_long_col_c5thx-P4"/>
      <site site="long_col_c5thx_long_col_c5thx-P5"/>
      <site site="long_col_c5thx_long_col_c5thx-P6"/>
      <site site="long_col_c5thx_long_col_c5thx-P7"/>
      <site site="long_col_c5thx_long_col_c5thx-P8"/>
    </spatial>
    <spatial name="long_col_c5thx_L_tendon">
      <site site="long_col_c5thx_L_long_col_c5thx_L-P1"/>
      <site site="long_col_c5thx_L_long_col_c5thx_L-P2"/>
      <site site="long_col_c5thx_L_long_col_c5thx_L-P3"/>
      <site site="long_col_c5thx_L_long_col_c5thx_L-P4"/>
      <site site="long_col_c5thx_L_long_col_c5thx_L-P5"/>
      <site site="long_col_c5thx_L_long_col_c5thx_L-P6"/>
      <site site="long_col_c5thx_L_long_col_c5thx_L-P7"/>
      <site site="long_col_c5thx_L_long_col_c5thx_L-P8"/>
    </spatial>
    <spatial name="trap_cl_tendon">
      <site site="trap_cl_trap_cl-P1"/>
      <site site="trap_cl_trap_cl-P2"/>
    </spatial>
    <spatial name="trap_cl_L_tendon">
      <site site="trap_cl_L_trap_cl_L-P1"/>
      <site site="trap_cl_L_trap_cl_L-P2"/>
    </spatial>
    <spatial name="trap_acr_tendon">
      <site site="trap_acr_trap_acr-P1"/>
      <site site="trap_acr_trap_acr-P2"/>
    </spatial>
    <spatial name="trap_acr_L_tendon">
      <site site="trap_acr_L_trap_acr_L-P1"/>
      <site site="trap_acr_L_trap_acr_L-P2"/>
    </spatial>
    <spatial name="splen_cap_sklc6_tendon">
      <site site="splen_cap_sklc6_splen_cap_sklc6-P1"/>
      <site site="splen_cap_sklc6_splen_cap_sklc6-P2"/>
    </spatial>
    <spatial name="splen_cap_sklc6_L_tendon">
      <site site="splen_cap_sklc6_L_splen_cap_sklc6_L-P1"/>
      <site site="splen_cap_sklc6_L_splen_cap_sklc6_L-P2"/>
    </spatial>
    <spatial name="splen_cap_sklthx_tendon">
      <site site="splen_cap_sklthx_splen_cap_sklthx-P1"/>
      <site site="splen_cap_sklthx_splen_cap_sklthx-P2"/>
    </spatial>
    <spatial name="splen_cap_sklthx_L_tendon">
      <site site="splen_cap_sklthx_L_splen_cap_sklthx_L-P1"/>
      <site site="splen_cap_sklthx_L_splen_cap_sklthx_L-P2"/>
    </spatial>
    <spatial name="splen_cerv_c3thx_tendon">
      <site site="splen_cerv_c3thx_splen_cerv_c3thx-P1"/>
      <site site="splen_cerv_c3thx_splen_cerv_c3thx-P2"/>
    </spatial>
    <spatial name="splen_cerv_c3thx_L_tendon">
      <site site="splen_cerv_c3thx_L_splen_cerv_c3thx_L-P1"/>
      <site site="splen_cerv_c3thx_L_splen_cerv_c3thx_L-P2"/>
    </spatial>
    <spatial name="semi_cap_sklc5_tendon">
      <site site="semi_cap_sklc5_semi_cap_sklc5-P1"/>
      <site site="semi_cap_sklc5_semi_cap_sklc5-P2"/>
    </spatial>
    <spatial name="semi_cap_sklc5_L_tendon">
      <site site="semi_cap_sklc5_L_semi_cap_sklc5_L-P1"/>
      <site site="semi_cap_sklc5_L_semi_cap_sklc5_L-P2"/>
    </spatial>
    <spatial name="semi_cap_sklthx_tendon">
      <site site="semi_cap_sklthx_semi_cap_sklthx-P1"/>
      <site site="semi_cap_sklthx_semi_cap_sklthx-P2"/>
    </spatial>
    <spatial name="semi_cap_sklthx_L_tendon">
      <site site="semi_cap_sklthx_L_semi_cap_sklthx_L-P1"/>
      <site site="semi_cap_sklthx_L_semi_cap_sklthx_L-P2"/>
    </spatial>
    <spatial name="semi_cerv_c3thx_tendon">
      <site site="semi_cerv_c3thx_semi_cerv_c3thx-P1"/>
      <site site="semi_cerv_c3thx_semi_cerv_c3thx-P2"/>
    </spatial>
    <spatial name="semi_cerv_c3thx_L_tendon">
      <site site="semi_cerv_c3thx_L_semi_cerv_c3thx_L-P1"/>
      <site site="semi_cerv_c3thx_L_semi_cerv_c3thx_L-P2"/>
    </spatial>
    <spatial name="levator_scap_tendon">
      <site site="levator_scap_levator_scap-P1"/>
      <site site="levator_scap_levator_scap-P2"/>
    </spatial>
    <spatial name="levator_scap_L_tendon">
      <site site="levator_scap_L_levator_scap_L-P1"/>
      <site site="levator_scap_L_levator_scap_L-P2"/>
    </spatial>
    <spatial name="longissi_cap_sklc6_tendon">
      <site site="longissi_cap_sklc6_longissi_cap_sklc6-P1"/>
      <site site="longissi_cap_sklc6_longissi_cap_sklc6-P2"/>
    </spatial>
    <spatial name="longissi_cap_sklc6_L_tendon">
      <site site="longissi_cap_sklc6_L_longissi_cap_sklc6_L-P1"/>
      <site site="longissi_cap_sklc6_L_longissi_cap_sklc6_L-P2"/>
    </spatial>
    <spatial name="longissi_cerv_c4thx_tendon">
      <site site="longissi_cerv_c4thx_longissi_cerv_c4thx-P1"/>
      <site site="longissi_cerv_c4thx_longissi_cerv_c4thx-P2"/>
      <site site="longissi_cerv_c4thx_longissi_cerv_c4thx-P3"/>
      <site site="longissi_cerv_c4thx_longissi_cerv_c4thx-P4"/>
      <site site="longissi_cerv_c4thx_longissi_cerv_c4thx-P5"/>
    </spatial>
    <spatial name="longissi_cerv_c4thx_L_tendon">
      <site site="longissi_cerv_c4thx_L_longissi_cerv_c4thx_L-P1"/>
      <site site="longissi_cerv_c4thx_L_longissi_cerv_c4thx_L-P2"/>
      <site site="longissi_cerv_c4thx_L_longissi_cerv_c4thx_L-P3"/>
      <site site="longissi_cerv_c4thx_L_longissi_cerv_c4thx_L-P4"/>
      <site site="longissi_cerv_c4thx_L_longissi_cerv_c4thx_L-P5"/>
    </spatial>
    <spatial name="iliocost_cerv_c5rib_tendon">
      <site site="iliocost_cerv_c5rib_iliocost_cerv_c5rib-P1"/>
      <site site="iliocost_cerv_c5rib_iliocost_cerv_c5rib-P2"/>
      <site site="iliocost_cerv_c5rib_iliocost_cerv_c5rib-P3"/>
    </spatial>
    <spatial name="iliocost_cerv_c5rib_L_tendon">
      <site site="iliocost_cerv_c5rib_L_iliocost_cerv_c5rib_L-P1"/>
      <site site="iliocost_cerv_c5rib_L_iliocost_cerv_c5rib_L-P2"/>
      <site site="iliocost_cerv_c5rib_L_iliocost_cerv_c5rib_L-P3"/>
    </spatial>
    <spatial name="rectcap_post_maj_tendon">
      <site site="rectcap_post_maj_rectcap_post_maj-P1"/>
      <site site="rectcap_post_maj_rectcap_post_maj-P2"/>
    </spatial>
    <spatial name="rectcap_post_maj_L_tendon">
      <site site="rectcap_post_maj_L_rectcap_post_maj_L-P1"/>
      <site site="rectcap_post_maj_L_rectcap_post_maj_L-P2"/>
    </spatial>
    <spatial name="rectcap_post_min_tendon">
      <site site="rectcap_post_min_rectcap_post_min-P1"/>
      <site site="rectcap_post_min_rectcap_post_min-P2"/>
    </spatial>
    <spatial name="rectcap_post_min_L_tendon">
      <site site="rectcap_post_min_L_rectcap_post_min_L-P1"/>
      <site site="rectcap_post_min_L_rectcap_post_min_L-P2"/>
    </spatial>
    <spatial name="obl_cap_sup_tendon">
      <site site="obl_cap_sup_obl_cap_sup-P1"/>
      <site site="obl_cap_sup_obl_cap_sup-P2"/>
    </spatial>
    <spatial name="obl_cap_sup_L_tendon">
      <site site="obl_cap_sup_L_obl_cap_sup_L-P1"/>
      <site site="obl_cap_sup_L_obl_cap_sup_L-P2"/>
    </spatial>
    <spatial name="obl_cap_inf_tendon">
      <site site="obl_cap_inf_obl_cap_inf-P1"/>
      <site site="obl_cap_inf_obl_cap_inf-P2"/>
    </spatial>
    <spatial name="obl_cap_inf_L_tendon">
      <site site="obl_cap_inf_L_obl_cap_inf_L-P1"/>
      <site site="obl_cap_inf_L_obl_cap_inf_L-P2"/>
    </spatial>
  </tendon>

  <actuator>
    <general name="digastric_post" class="muscle" tendon="digastric_post_tendon" lengthrange="0.0326346 0.0878346" gainprm="0.149902 1.59872 94.5938 1 0 2 10 2.10261 1.4 0" biasprm="0.149902 1.59872 94.5938 1 0 2 10 2.10261 1.4 0"/>
    <general name="digastric_ant" class="muscle" tendon="digastric_ant_tendon" lengthrange="0.00871147 0.0279411" gainprm="0.154826 1.49709 105.351 1 0 2 10 0.872241 1.4 0" biasprm="0.154826 1.49709 105.351 1 0 2 10 0.872241 1.4 0"/>
    <general name="Geniohyoid" class="muscle" tendon="Geniohyoid_tendon" lengthrange="0.0303876 0.0588847" gainprm="0.826106 1.07348 82.1288 1 0 2 10 3.47861 1.4 0" biasprm="0.826106 1.07348 82.1288 1 0 2 10 3.47861 1.4 0"/>
    <general name="Mylohyoid_Post" class="muscle" tendon="Mylohyoid_Post_tendon" lengthrange="0.032392 0.055483" gainprm="0.568265 1.68722 48.6498 1 0 2 10 0.721323 1.4 0" biasprm="0.568265 1.68722 48.6498 1 0 2 10 0.721323 1.4 0"/>
    <general name="Mylohyoid_Ant" class="muscle" tendon="Mylohyoid_Ant_tendon" lengthrange="0.0128799 0.0408961" gainprm="0.437388 1.63266 133.673 1 0 2 10 1.76633 1.4 0" biasprm="0.437388 1.63266 133.673 1 0 2 10 1.76633 1.4 0"/>
    <general name="Stylohyoid_Lat" class="muscle" tendon="Stylohyoid_Lat_tendon" lengthrange="0.0638213 0.0726717" gainprm="0.637246 1.08706 18.0977 1 0 2 10 2.71549 1.4 0" biasprm="0.637246 1.08706 18.0977 1 0 2 10 2.71549 1.4 0"/>
    <general name="Stylohyoid_Med" class="muscle" tendon="Stylohyoid_Med_tendon" lengthrange="0.0578583 0.066841" gainprm="0.662859 1.18532 17.7204 1 0 2 10 1.52616 1.4 0" biasprm="0.662859 1.18532 17.7204 1 0 2 10 1.52616 1.4 0"/>
    <general name="Sterno_hyoid" class="muscle" tendon="Sterno_hyoid_tendon" lengthrange="0.0672714 0.149742" gainprm="0.372445 1.69963 53.6996 1 0 2 10 0.716851 1.4 0" biasprm="0.372445 1.69963 53.6996 1 0 2 10 0.716851 1.4 0"/>
    <general name="SternoThyroid" class="muscle" tendon="SternoThyroid_tendon" lengthrange="0.0632237 0.133333" gainprm="0.57373 1.48696 56.3633 1 0 2 10 0.969687 1.4 0" biasprm="0.57373 1.48696 56.3633 1 0 2 10 0.969687 1.4 0"/>
    <general name="Omo_hyoid" class="muscle" tendon="Omo_hyoid_tendon" lengthrange="0.0264532 0.107604" gainprm="0.207737 1.33823 66.9403 1 0 2 10 2.27381 1.4 0" biasprm="0.207737 1.33823 66.9403 1 0 2 10 2.27381 1.4 0"/>
    <general name="digastric_post_L" class="muscle" tendon="digastric_post_L_tendon" lengthrange="0.0326346 0.0878346" gainprm="0.177763 1.42815 101.548 1 0 2 10 2.97952 1.4 0" biasprm="0.177763 1.42815 101.548 1 0 2 10 2.97952 1.4 0"/>
    <general name="digastric_ant_L" class="muscle" tendon="digastric_ant_L_tendon" lengthrange="0.00871147 0.0279411" gainprm="0.102724 1.60968 105.043 1 0 2 10 0.836923 1.4 0" biasprm="0.102724 1.60968 105.043 1 0 2 10 0.836923 1.4 0"/>
    <general name="Geniohyoid_L" class="muscle" tendon="Geniohyoid_L_tendon" lengthrange="0.0305926 0.059369" gainprm="0.953846 1.03071 81.699 1 0 2 10 3.79785 1.4 0" biasprm="0.953846 1.03071 81.699 1 0 2 10 3.79785 1.4 0"/>
    <general name="Mylohyoid_Post_L" class="muscle" tendon="Mylohyoid_Post_L_tendon" lengthrange="0.032392 0.055483" gainprm="0.588804 1.44403 48.4011 1 0 2 10 0.429335 1.4 0" biasprm="0.588804 1.44403 48.4011 1 0 2 10 0.429335 1.4 0"/>
    <general name="Mylohyoid_Ant_L" class="muscle" tendon="Mylohyoid_Ant_L_tendon" lengthrange="0.0128799 0.0408961" gainprm="0.437363 1.57363 137.316 1 0 2 10 1.88214 1.4 0" biasprm="0.437363 1.57363 137.316 1 0 2 10 1.88214 1.4 0"/>
    <general name="Stylohyoid_Lat_L" class="muscle" tendon="Stylohyoid_Lat_L_tendon" lengthrange="0.0635165 0.0723406" gainprm="0.615348 1.07765 18.1826 1 0 2 10 2.25202 1.4 0" biasprm="0.615348 1.07765 18.1826 1 0 2 10 2.25202 1.4 0"/>
    <general name="Stylohyoid_Med_L" class="muscle" tendon="Stylohyoid_Med_L_tendon" lengthrange="0.0575533 0.0665085" gainprm="0.613537 1.42647 17.7024 1 0 2 10 1.02216 1.4 0" biasprm="0.613537 1.42647 17.7024 1 0 2 10 1.02216 1.4 0"/>
    <general name="Sterno_hyoid_L" class="muscle" tendon="Sterno_hyoid_L_tendon" lengthrange="0.0672714 0.149742" gainprm="0.39711 1.51266 53.4926 1 0 2 10 0.623484 1.4 0" biasprm="0.39711 1.51266 53.4926 1 0 2 10 0.623484 1.4 0"/>
    <general name="SternoThyroid_L" class="muscle" tendon="SternoThyroid_L_tendon" lengthrange="0.0632237 0.133333" gainprm="0.571258 1.45597 57.3551 1 0 2 10 0.873719 1.4 0" biasprm="0.571258 1.45597 57.3551 1 0 2 10 0.873719 1.4 0"/>
    <general name="Omo_hyoid_L" class="muscle" tendon="Omo_hyoid_L_tendon" lengthrange="0.0264532 0.107604" gainprm="0.143632 1.67787 64.7265 1 0 2 10 1.21319 1.4 0" biasprm="0.143632 1.67787 64.7265 1 0 2 10 1.21319 1.4 0"/>
    <general name="stern_mast" class="muscle" tendon="stern_mast_tendon" lengthrange="0.106866 0.209867" gainprm="0.424926 1.44934 172.862 1 0 2 10 0.576343 1.4 0" biasprm="0.424926 1.44934 172.862 1 0 2 10 0.576343 1.4 0"/>
    <general name="stern_mast_L" class="muscle" tendon="stern_mast_L_tendon" lengthrange="0.106866 0.209867" gainprm="0.459993 1.24362 165.751 1 0 2 10 1.41168 1.4 0" biasprm="0.459993 1.24362 165.751 1 0 2 10 1.41168 1.4 0"/>
    <general name="cleid_mast" class="muscle" tendon="cleid_mast_tendon" lengthrange="0.0821549 0.211425" gainprm="0.434898 1.25463 82.4032 1 0 2 10 2.2798 1.4 0" biasprm="0.434898 1.25463 82.4032 1 0 2 10 2.2798 1.4 0"/>
    <general name="cleid_mast_L" class="muscle" tendon="cleid_mast_L_tendon" lengthrange="0.0821549 0.211425" gainprm="0.337582 1.79297 87.6197 1 0 2 10 0.821965 1.4 0" biasprm="0.337582 1.79297 87.6197 1 0 2 10 0.821965 1.4 0"/>
    <general name="cleid_occ" class="muscle" tendon="cleid_occ_tendon" lengthrange="0.10553 0.234637" gainprm="0.227121 1.3638 83.551 1 0 2 10 0.972479 1.4 0" biasprm="0.227121 1.3638 83.551 1 0 2 10 0.972479 1.4 0"/>
    <general name="cleid_occ_L" class="muscle" tendon="cleid_occ_L_tendon" lengthrange="0.10553 0.234637" gainprm="0.161928 1.61646 85.7571 1 0 2 10 0.746741 1.4 0" biasprm="0.161928 1.61646 85.7571 1 0 2 10 0.746741 1.4 0"/>
    <general name="scalenus_ant" class="muscle" tendon="scalenus_ant_tendon" lengthrange="0.0841604 0.119901" gainprm="0.769529 1.61943 126.018 1 0 2 10 0.834035 1.4 0" biasprm="0.769529 1.61943 126.018 1 0 2 10 0.834035 1.4 0"/>
    <general name="scalenus_ant_L" class="muscle" tendon="scalenus_ant_L_tendon" lengthrange="0.0841604 0.119901" gainprm="0.606344 1.76385 133.094 1 0 2 10 0.701016 1.4 0" biasprm="0.606344 1.76385 133.094 1 0 2 10 0.701016 1.4 0"/>
    <general name="scalenus_med" class="muscle" tendon="scalenus_med_tendon" lengthrange="0.0948363 0.127121" gainprm="0.445179 1.51884 94.3834 1 0 2 10 0.948014 1.4 0" biasprm="0.445179 1.51884 94.3834 1 0 2 10 0.948014 1.4 0"/>
    <general name="scalenus_med_L" class="muscle" tendon="scalenus_med_L_tendon" lengthrange="0.0948363 0.127121" gainprm="0.431467 1.54391 98.6233 1 0 2 10 0.752781 1.4 0" biasprm="0.431467 1.54391 98.6233 1 0 2 10 0.752781 1.4 0"/>
    <general name="scalenus_post" class="muscle" tendon="scalenus_post_tendon" lengthrange="0.122446 0.139303" gainprm="0.691138 1.3371 72.1142 1 0 2 10 1.362 1.4 0" biasprm="0.691138 1.3371 72.1142 1 0 2 10 1.362 1.4 0"/>
    <general name="scalenus_post_L" class="muscle" tendon="scalenus_post_L_tendon" lengthrange="0.122446 0.139303" gainprm="0.691896 1.11627 74.0234 1 0 2 10 2.39179 1.4 0" biasprm="0.691896 1.11627 74.0234 1 0 2 10 2.39179 1.4 0"/>
    <general name="long_cap_sklc4" class="muscle" tendon="long_cap_sklc4_tendon" lengthrange="0.0618166 0.114714" gainprm="0.555866 1.40216 84.8261 1 0 2 10 0.542452 1.4 0" biasprm="0.555866 1.40216 84.8261 1 0 2 10 0.542452 1.4 0"/>
    <general name="long_cap_sklc4_L" class="muscle" tendon="long_cap_sklc4_L_tendon" lengthrange="0.0618166 0.114714" gainprm="0.540261 1.63308 84.9133 1 0 2 10 0.805205 1.4 0" biasprm="0.540261 1.63308 84.9133 1 0 2 10 0.805205 1.4 0"/>
    <general name="long_col_c1thx" class="muscle" tendon="long_col_c1thx_tendon" lengthrange="0.152628 0.223492" gainprm="0.763918 1.22984 31.3575 1 0 2 10 0.82411 1.4 0" biasprm="0.763918 1.22984 31.3575 1 0 2 10 0.82411 1.4 0"/>
    <general name="long_col_c1thx_L" class="muscle" tendon="long_col_c1thx_L_tendon" lengthrange="0.152628 0.223492" gainprm="0.766885 1.09496 31.3811 1 0 2 10 0.863284 1.4 0" biasprm="0.766885 1.09496 31.3811 1 0 2 10 0.863284 1.4 0"/>
    <general name="long_col_c1c5" class="muscle" tendon="long_col_c1c5_tendon" lengthrange="0.0558309 0.111051" gainprm="0.594413 1.34805 30.8077 1 0 2 10 0.273924 1.4 0" biasprm="0.594413 1.34805 30.8077 1 0 2 10 0.273924 1.4 0"/>
    <general name="long_col_c1c5_L" class="muscle" tendon="long_col_c1c5_L_tendon" lengthrange="0.0558309 0.111051" gainprm="0.679441 1.08401 28.8747 1 0 2 10 1.85634 1.4 0" biasprm="0.679441 1.08401 28.8747 1 0 2 10 1.85634 1.4 0"/>
    <general name="long_col_c5thx" class="muscle" tendon="long_col_c5thx_tendon" lengthrange="0.102701 0.117898" gainprm="0.755499 1.22812 31.3183 1 0 2 10 1.58351 1.4 0" biasprm="0.755499 1.22812 31.3183 1 0 2 10 1.58351 1.4 0"/>
    <general name="long_col_c5thx_L" class="muscle" tendon="long_col_c5thx_L_tendon" lengthrange="0.102701 0.117898" gainprm="0.798924 1.29989 30.9574 1 0 2 10 1.2952 1.4 0" biasprm="0.798924 1.29989 30.9574 1 0 2 10 1.2952 1.4 0"/>
    <general name="trap_cl" class="muscle" tendon="trap_cl_tendon" lengthrange="0.0869857 0.250144" gainprm="0.01 1.04234 97.7989 1 0 2 10 1.76758 1.4 0" biasprm="0.01 1.04234 97.7989 1 0 2 10 1.76758 1.4 0"/>
    <general name="trap_cl_L" class="muscle" tendon="trap_cl_L_tendon" lengthrange="0.0869857 0.250144" gainprm="0.056455 1.37764 76.0557 1 0 2 10 2.353 1.4 0" biasprm="0.056455 1.37764 76.0557 1 0 2 10 2.353 1.4 0"/>
    <general name="trap_acr" class="muscle" tendon="trap_acr_tendon" lengthrange="0.170867 0.175622" gainprm="0.870501 1.12327 526.749 1 0 2 10 2.42658 1.4 0" biasprm="0.870501 1.12327 526.749 1 0 2 10 2.42658 1.4 0"/>
    <general name="trap_acr_L" class="muscle" tendon="trap_acr_L_tendon" lengthrange="0.170867 0.175622" gainprm="0.965275 1.57596 528.372 1 0 2 10 0.995409 1.4 0" biasprm="0.965275 1.57596 528.372 1 0 2 10 0.995409 1.4 0"/>
    <general name="splen_cap_sklc6" class="muscle" tendon="splen_cap_sklc6_tendon" lengthrange="0.048352 0.154009" gainprm="0.01 1.55946 68.2396 1 0 2 10 0.748678 1.4 0" biasprm="0.01 1.55946 68.2396 1 0 2 10 0.748678 1.4 0"/>
    <general name="splen_cap_sklc6_L" class="muscle" tendon="splen_cap_sklc6_L_tendon" lengthrange="0.048352 0.154009" gainprm="0.0923094 1.41019 65.9723 1 0 2 10 0.823305 1.4 0" biasprm="0.0923094 1.41019 65.9723 1 0 2 10 0.823305 1.4 0"/>
    <general name="splen_cap_sklthx" class="muscle" tendon="splen_cap_sklthx_tendon" lengthrange="0.0645221 0.197191" gainprm="0.0936568 1.33729 40.1438 1 0 2 10 3.60192 1.4 0" biasprm="0.0936568 1.33729 40.1438 1 0 2 10 3.60192 1.4 0"/>
    <general name="splen_cap_sklthx_L" class="muscle" tendon="splen_cap_sklthx_L_tendon" lengthrange="0.0645221 0.197191" gainprm="0.0200369 1 57.7845 1 0 2 10 1.89858 1.4 0" biasprm="0.0200369 1 57.7845 1 0 2 10 1.89858 1.4 0"/>
    <general name="splen_cerv_c3thx" class="muscle" tendon="splen_cerv_c3thx_tendon" lengthrange="0.169487 0.216461" gainprm="0.38448 1.14749 69.2614 1 0 2 10 1.92903 1.4 0" biasprm="0.38448 1.14749 69.2614 1 0 2 10 1.92903 1.4 0"/>
    <general name="splen_cerv_c3thx_L" class="muscle" tendon="splen_cerv_c3thx_L_tendon" lengthrange="0.169487 0.216461" gainprm="0.381773 1.15371 68.9004 1 0 2 10 2.47342 1.4 0" biasprm="0.381773 1.15371 68.9004 1 0 2 10 2.47342 1.4 0"/>
    <general name="semi_cap_sklc5" class="muscle" tendon="semi_cap_sklc5_tendon" lengthrange="0.0668629 0.13178" gainprm="0.0748306 1.61942 87.1691 1 0 2 10 0.691125 1.4 0" biasprm="0.0748306 1.61942 87.1691 1 0 2 10 0.691125 1.4 0"/>
    <general name="semi_cap_sklc5_L" class="muscle" tendon="semi_cap_sklc5_L_tendon" lengthrange="0.0668629 0.13178" gainprm="0.201384 1.33446 82.898 1 0 2 10 1.10831 1.4 0" biasprm="0.201384 1.33446 82.898 1 0 2 10 1.10831 1.4 0"/>
    <general name="semi_cap_sklthx" class="muscle" tendon="semi_cap_sklthx_tendon" lengthrange="0.0480834 0.183271" gainprm="0.104703 1.52025 64.3597 1 0 2 10 2.37681 1.4 0" biasprm="0.104703 1.52025 64.3597 1 0 2 10 2.37681 1.4 0"/>
    <general name="semi_cap_sklthx_L" class="muscle" tendon="semi_cap_sklthx_L_tendon" lengthrange="0.0480834 0.183271" gainprm="0.01 1.06532 93.2803 1 0 2 10 4.11372 1.4 0" biasprm="0.01 1.06532 93.2803 1 0 2 10 4.11372 1.4 0"/>
    <general name="semi_cerv_c3thx" class="muscle" tendon="semi_cerv_c3thx_tendon" lengthrange="0.0519347 0.109386" gainprm="0.0348633 1.34244 86.888 1 0 2 10 1.18995 1.4 0" biasprm="0.0348633 1.34244 86.888 1 0 2 10 1.18995 1.4 0"/>
    <general name="semi_cerv_c3thx_L" class="muscle" tendon="semi_cerv_c3thx_L_tendon" lengthrange="0.0519347 0.109386" gainprm="0.0250121 1.37072 86.2561 1 0 2 10 0.890243 1.4 0" biasprm="0.0250121 1.37072 86.2561 1 0 2 10 0.890243 1.4 0"/>
    <general name="levator_scap" class="muscle" tendon="levator_scap_tendon" lengthrange="0.0806657 0.160891" gainprm="0.191155 1.5377 106.948 1 0 2 10 0.687807 1.4 0" biasprm="0.191155 1.5377 106.948 1 0 2 10 0.687807 1.4 0"/>
    <general name="levator_scap_L" class="muscle" tendon="levator_scap_L_tendon" lengthrange="0.0806657 0.160891" gainprm="0.175363 1.57139 106.486 1 0 2 10 0.723213 1.4 0" biasprm="0.175363 1.57139 106.486 1 0 2 10 0.723213 1.4 0"/>
    <general name="longissi_cap_sklc6" class="muscle" tendon="longissi_cap_sklc6_tendon" lengthrange="0.0570738 0.130629" gainprm="0.300144 1.52711 41.8375 1 0 2 10 0.711264 1.4 0" biasprm="0.300144 1.52711 41.8375 1 0 2 10 0.711264 1.4 0"/>
    <general name="longissi_cap_sklc6_L" class="muscle" tendon="longissi_cap_sklc6_L_tendon" lengthrange="0.0570738 0.130629" gainprm="0.291051 1.46998 41.4344 1 0 2 10 1.01537 1.4 0" biasprm="0.291051 1.46998 41.4344 1 0 2 10 1.01537 1.4 0"/>
    <general name="longissi_cerv_c4thx" class="muscle" tendon="longissi_cerv_c4thx_tendon" lengthrange="0.1452 0.187656" gainprm="0.678666 1.32661 26.8587 1 0 2 10 1.40344 1.4 0" biasprm="0.678666 1.32661 26.8587 1 0 2 10 1.40344 1.4 0"/>
    <general name="longissi_cerv_c4thx_L" class="muscle" tendon="longissi_cerv_c4thx_L_tendon" lengthrange="0.1452 0.187656" gainprm="0.670353 1.29749 27.158 1 0 2 10 1.14878 1.4 0" biasprm="0.670353 1.29749 27.158 1 0 2 10 1.14878 1.4 0"/>
    <general name="iliocost_cerv_c5rib" class="muscle" tendon="iliocost_cerv_c5rib_tendon" lengthrange="0.08607 0.117171" gainprm="0.659733 1.1263 27.2992 1 0 2 10 2.89327 1.4 0" biasprm="0.659733 1.1263 27.2992 1 0 2 10 2.89327 1.4 0"/>
    <general name="iliocost_cerv_c5rib_L" class="muscle" tendon="iliocost_cerv_c5rib_L_tendon" lengthrange="0.08607 0.117171" gainprm="0.631068 1.3297 27.2987 1 0 2 10 0.961735 1.4 0" biasprm="0.631068 1.3297 27.2987 1 0 2 10 0.961735 1.4 0"/>
    <general name="rectcap_post_maj" class="muscle" tendon="rectcap_post_maj_tendon" lengthrange="0.038764 0.0650508" gainprm="0.0899278 1.44551 42.3639 1 0 2 10 0.970843 1.4 0" biasprm="0.0899278 1.44551 42.3639 1 0 2 10 0.970843 1.4 0"/>
    <general name="rectcap_post_maj_L" class="muscle" tendon="rectcap_post_maj_L_tendon" lengthrange="0.038764 0.0650508" gainprm="0.0310839 1.59319 42.2093 1 0 2 10 0.984736 1.4 0" biasprm="0.0310839 1.59319 42.2093 1 0 2 10 0.984736 1.4 0"/>
    <general name="rectcap_post_min" class="muscle" tendon="rectcap_post_min_tendon" lengthrange="0.0256373 0.0414025" gainprm="0.295329 1.15947 24.6201 1 0 2 10 2.50839 1.4 0" biasprm="0.295329 1.15947 24.6201 1 0 2 10 2.50839 1.4 0"/>
    <general name="rectcap_post_min_L" class="muscle" tendon="rectcap_post_min_L_tendon" lengthrange="0.0256373 0.0414025" gainprm="0.236104 1.42231 24.7882 1 0 2 10 0.650589 1.4 0" biasprm="0.236104 1.42231 24.7882 1 0 2 10 0.650589 1.4 0"/>
    <general name="obl_cap_sup" class="muscle" tendon="obl_cap_sup_tendon" lengthrange="0.0375764 0.0502347" gainprm="0.638559 1.06992 49.5389 1 0 2 10 3.32806 1.4 0" biasprm="0.638559 1.06992 49.5389 1 0 2 10 3.32806 1.4 0"/>
    <general name="obl_cap_sup_L" class="muscle" tendon="obl_cap_sup_L_tendon" lengthrange="0.0375764 0.0502347" gainprm="0.642987 1.06676 49.3729 1 0 2 10 3.94356 1.4 0" biasprm="0.642987 1.06676 49.3729 1 0 2 10 3.94356 1.4 0"/>
    <general name="obl_cap_inf" class="muscle" tendon="obl_cap_inf_tendon" lengthrange="0.049474 0.059088" gainprm="0.347223 1.37125 63.2233 1 0 2 10 0.473339 1.4 0" biasprm="0.347223 1.37125 63.2233 1 0 2 10 0.473339 1.4 0"/>
    <general name="obl_cap_inf_L" class="muscle" tendon="obl_cap_inf_L_tendon" lengthrange="0.049474 0.059088" gainprm="0.320696 1.55091 61.0629 1 0 2 10 0.697064 1.4 0" biasprm="0.320696 1.55091 61.0629 1 0 2 10 0.697064 1.4 0"/>
  </actuator>

  <keyframe>
    <key name="default-pose" qpos="1.18e-07 0 0 2.229e-07 0 0 2.622e-07 0 0 2.622e-07 0 0 1.967e-07 0 0 1.311e-07 0 0 6.989e-07 0 0 8.751e-07 0 0"/>
  </keyframe>

</mujoco>
