<mujoco model="template">
  <!-- This model has been converted from an OpenSim model. Model conversion by MyoConverter https://github.com/MyoHub/myoconverter. This model is licensed under Apache 2.0. -->
  <!-- Credits from the original OpenSim model. Note! If the following has any license information, it applies to the original OpenSim model. Credits: Jonathan Camargo -->
  <!-- Note: inertiagrouprange="0 1" means that groups 0-1 will be used to infer masses/inertias, and groups 2-5 are
  only for visualisation (e.g. wrapping objects) !-->
  <compiler inertiafromgeom="auto" angle="radian" balanceinertia="true" boundmass="0.001" boundinertia="0.001" inertiagrouprange="0 1">
    <lengthrange inttotal="50" useexisting="true"/>
  </compiler>
  <option collision="predefined"/>
  <visual>
    <scale framelength="0.5" framewidth="0.01"/>
  </visual>
  <default>
    <joint limited="true" damping="0.05" armature="0.00001" stiffness="0"/>
    <geom rgba="0.8 0.6 .4 1" margin="0.001"/>
    <site size="0.001"/>
    <tendon width="0.005" rgba=".95 .3 .3 1" limited="false"/>
    <default class="muscle">
      <muscle ctrllimited="true" ctrlrange="0 1" scale="200"/>
    </default>
    <default class="motor">
      <general gainprm="5 0 0 0 0 0 0 0 0 0"/>
    </default>
  </default>
  <option timestep="0.002"/>
  <!-- nuser_jnt=1, the parameter is used to store default value of the joint, and nkey=1 to store keyframe with
   default joint positions set !-->
  <size njmax="1000" nconmax="400" nuser_jnt="1" nkey="1"/>
  <worldbody>
    <!-- The converter script assumes a body named 'ground' exists as a child element of worldbody -->
    <body name="ground" euler="1.571 0 0">
      <geom name="ground-plane" pos="0 0 0" euler="-1.571 0 0" size="10 10 0.125" type="plane" rgba="1.0 0.7 0.4 1.0" condim="3"/>
      <geom name="ground_geom_1" type="mesh" pos="0 0 0" euler="0 0 0" mesh="ground_geom_1_treadmill" rgba="1 1 1 0" group="0"/>
    </body>
    <light directional="true"/>
    <body name="pelvis" pos="0 0 0" euler="1.571 0 0">
      <inertial mass="11.776999999999999" pos="-0.070699999999999999 0 0" fullinertia="0.1028 0.087099999999999997 0.0579 0 0 0"/>
      <geom name="pelvis_geom_1" type="mesh" mesh="pelvis_geom_1_sacrum" rgba="1 1 1 1" group="0"/>
      <geom name="pelvis_geom_2" type="mesh" mesh="pelvis_geom_2_pelvis" rgba="1 1 1 1" group="0"/>
      <geom name="pelvis_geom_3" type="mesh" mesh="pelvis_geom_3_l_pelvis" rgba="1 1 1 1" group="0"/>
      <joint name="pelvis_tx" range="-5 5" limited="false" user="0.0" ref="0" axis="1 0 0" type="slide" damping="0" stiffness="0"/>
      <joint name="pelvis_ty" range="-1 2" limited="false" user="0.95" ref="0" axis="0 1 0" type="slide" damping="0" stiffness="0"/>
      <joint name="pelvis_tz" range="-3 3" limited="false" user="0.0" ref="0" axis="0 0 1" type="slide" damping="0" stiffness="0"/>
      <joint name="pelvis_tilt" range="-1.571 1.571" limited="false" user="0.0" ref="0" axis="0 0 1" type="hinge" damping="0" stiffness="0"/>
      <joint name="pelvis_list" range="-1.571 1.571" limited="false" user="0.0" ref="0" axis="1 0 0" type="hinge" damping="0" stiffness="0"/>
      <joint name="pelvis_rotation" range="-1.571 1.571" limited="false" user="0.0" ref="0" axis="0 1 0" type="hinge" damping="0" stiffness="0"/>
      <body name="femur_r" pos="-0.0707 -0.0661 0.0835" euler="-0 0 0">
        <inertial mass="9.3013999999999992" pos="0 -0.17000000000000001 0" fullinertia="0.13389999999999999 0.035099999999999999 0.14119999999999999 0 0 0"/>
        <geom name="femur_r_geom_1" type="mesh" mesh="femur_r_geom_1_femur_r" rgba="1 1 1 1" group="0"/>
        <joint name="hip_flexion_r" range="-2.094 2.094" limited="false" user="0.0" ref="0" axis="0 0 1" type="hinge"/>
        <joint name="hip_adduction_r" range="-2.094 2.094" limited="false" user="0.0" ref="0" axis="1 0 0" type="hinge"/>
        <joint name="hip_rotation_r" range="-2.094 2.094" limited="false" user="0.0" ref="0" axis="0 1 0" type="hinge"/>
        <body name="tibia_r" pos="0 0 0" euler="-0 0 0">
          <inertial mass="3.7075" pos="0 -0.1867 0" fullinertia="0.0504 0.0051000000000000004 0.0511 0 0 0"/>
          <geom name="tibia_r_geom_1" type="mesh" mesh="tibia_r_geom_1_tibia_r" rgba="1 1 1 1" group="0"/>
          <geom name="tibia_r_geom_2" type="mesh" mesh="tibia_r_geom_2_fibula" rgba="1 1 1 1" group="0"/>
          <joint name="knee_r_translation1" range="-0.005574 0.00411" limited="true" user="-0.0036392466304026047" ref="0" axis="1 0 0" type="slide"/>
          <joint name="knee_r_translation2" range="-0.4226 -0.3953" limited="true" user="-0.395713445137591" ref="0" axis="0 1 0" type="slide"/>
          <joint name="knee_angle_r" range="-2.094 0.1745" limited="false" user="0.0" ref="0" axis="0 0 1" type="hinge"/>
          <body name="talus_r" pos="0 -0.43 0" euler="-0 0 0">
            <inertial mass="0.10000000000000001" pos="0 0 0" fullinertia="0.001 0.001 0.001 0 0 0"/>
            <geom name="talus_r_geom_1" type="mesh" mesh="talus_r_geom_1_talus" rgba="1 1 1 1" group="0"/>
            <joint name="ankle_angle_r" range="-1.571 1.571" limited="false" user="0.0" ref="0" axis="-0.105 -0.174 0.9791" type="hinge"/>
            <body name="calcn_r" pos="-0.04877 -0.04195 0.00792" euler="-0 0 0">
              <inertial mass="1.25" pos="0.10000000000000001 0.029999999999999999 0" fullinertia="0.0014 0.0038999999999999998 0.0041000000000000003 0 0 0"/>
              <geom name="calcn_r_geom_1" type="mesh" mesh="calcn_r_geom_1_foot" rgba="1 1 1 1" group="0"/>
              <joint name="subtalar_angle_r" range="-1.571 1.571" limited="false" user="0.0" ref="0" axis="0.7872 0.6047 -0.1209" type="hinge"/>
              <body name="toes_r" pos="0.1788 -0.002 0.00108" euler="-0 0 0">
                <inertial mass="0.21659999999999999" pos="0.034599999999999999 0.0060000000000000001 -0.017500000000000002" fullinertia="0.0001 0.00020000000000000001 0.0001 0 0 0"/>
                <geom name="toes_r_geom_1" type="mesh" mesh="toes_r_geom_1_bofoot" rgba="1 1 1 1" group="0"/>
                <joint name="mtp_angle_r" range="-1.571 1.571" limited="false" user="0.0" ref="0" axis="-0.581 0 0.8139" type="hinge"/>
                <site name="flex_dig_r_flex_dig_r-P6" pos="-0.0019 -0.0077999999999999996 0.0147"/>
                <site name="flex_dig_r_flex_dig_r-P7" pos="0.028500000000000001 -0.0071000000000000004 0.021499999999999998"/>
                <site name="flex_dig_r_flex_dig_r-P8" pos="0.0441 -0.0060000000000000001 0.024199999999999999"/>
                <site name="flex_hal_r_flex_hal_r-P6" pos="0.0155 -0.0064000000000000003 -0.026499999999999999"/>
                <site name="flex_hal_r_flex_hal_r-P7" pos="0.0562 -0.010200000000000001 -0.018100000000000002"/>
                <site name="ext_dig_r_ext_dig_r-P5" pos="0.00029999999999999997 0.0047000000000000002 0.015299999999999999"/>
                <site name="ext_dig_r_ext_dig_r-P6" pos="0.044299999999999999 -0.00040000000000000002 0.025000000000000001"/>
                <site name="ext_hal_r_ext_hal_r-P6" pos="0.0298 0.0041000000000000003 -0.024500000000000001"/>
                <site name="ext_hal_r_ext_hal_r-P7" pos="0.056300000000000003 0.0033999999999999998 -0.018599999999999998"/>
              </body>
              <site name="med_gas_r_med_gas_r-P3" pos="0 0.031 -0.0053"/>
              <site name="lat_gas_r_lat_gas_r-P3" pos="0 0.031 -0.0053"/>
              <site name="soleus_r_soleus_r-P2" pos="0 0.031 -0.0053"/>
              <site name="tib_post_r_tib_post_r-P3" pos="0.041700000000000001 0.033399999999999999 -0.0286"/>
              <site name="tib_post_r_tib_post_r-P4" pos="0.077200000000000005 0.015900000000000001 -0.0281"/>
              <site name="flex_dig_r_flex_dig_r-P3" pos="0.0436 0.0315 -0.028000000000000001"/>
              <site name="flex_dig_r_flex_dig_r-P4" pos="0.070800000000000002 0.017600000000000001 -0.0263"/>
              <site name="flex_dig_r_flex_dig_r-P5" pos="0.1658 -0.0080999999999999996 0.011599999999999999"/>
              <site name="flex_hal_r_flex_hal_r-P3" pos="0.037400000000000003 0.0276 -0.0241"/>
              <site name="flex_hal_r_flex_hal_r-P4" pos="0.1038 0.0067999999999999996 -0.025600000000000001"/>
              <site name="flex_hal_r_flex_hal_r-P5" pos="0.1726 -0.0053 -0.0269"/>
              <site name="tib_ant_r_tib_ant_r-P3" pos="0.1166 0.0178 -0.030499999999999999"/>
              <site name="per_brev_r_per_brev_r-P4" pos="0.047100000000000003 0.027 0.023300000000000001"/>
              <site name="per_brev_r_per_brev_r-P5" pos="0.067699999999999996 0.021899999999999999 0.034299999999999997"/>
              <site name="per_long_r_per_long_r-P4" pos="0.043799999999999999 0.023 0.022100000000000002"/>
              <site name="per_long_r_per_long_r-P5" pos="0.068099999999999994 0.0106 0.028400000000000002"/>
              <site name="per_long_r_per_long_r-P6" pos="0.085199999999999998 0.0068999999999999999 0.0118"/>
              <site name="per_long_r_per_long_r-P7" pos="0.1203 0.0085000000000000006 -0.0184"/>
              <site name="per_tert_r_per_tert_r-P3" pos="0.085699999999999998 0.022800000000000001 0.029899999999999999"/>
              <site name="ext_dig_r_ext_dig_r-P3" pos="0.092200000000000004 0.038800000000000001 -0.0001"/>
              <site name="ext_dig_r_ext_dig_r-P4" pos="0.16159999999999999 0.0054999999999999997 0.012999999999999999"/>
              <site name="ext_hal_r_ext_hal_r-P3" pos="0.097000000000000003 0.038899999999999997 -0.021100000000000001"/>
              <site name="ext_hal_r_ext_hal_r-P4" pos="0.1293 0.0309 -0.025700000000000001"/>
              <site name="ext_hal_r_ext_hal_r-P5" pos="0.1734 0.013899999999999999 -0.028000000000000001"/>
            </body>
          </body>
          <body name="semimem_r_semimem_r-P2" pos="0 0 -0.01957">
            <geom size="0.0005 0.0005 0.0005" rgba="0.0 0.0 1.0 0.0" contype="2" conaffinity="2"/>
            <joint name="semimem_r_semimem_r-P2_x" type="slide" axis="1 0 0" range="-0.0348 -0.027"/>
            <joint name="semimem_r_semimem_r-P2_y" type="slide" axis="0 1 0" range="-0.04771 -0.03519"/>
            <site name="semimem_r_semimem_r-P2"/>
          </body>
          <site name="semimem_r_semimem_r-P3" pos="-0.027 -0.047710000000000002 -0.019570000000000001"/>
          <body name="semiten_r_semiten_r-P2" pos="0 0 -0.02288">
            <geom size="0.0005 0.0005 0.0005" rgba="0.0 0.0 1.0 0.0" contype="2" conaffinity="2"/>
            <joint name="semiten_r_semiten_r-P2_x" type="slide" axis="1 0 0" range="-0.04203 -0.03322"/>
            <joint name="semiten_r_semiten_r-P2_y" type="slide" axis="0 1 0" range="-0.05282 -0.02859"/>
            <site name="semiten_r_semiten_r-P2"/>
          </body>
          <site name="semiten_r_semiten_r-P3" pos="-0.03322 -0.052819999999999999 -0.022880000000000001"/>
          <site name="semiten_r_semiten_r-P4" pos="-0.011299999999999999 -0.0746 -0.024500000000000001"/>
          <site name="semiten_r_semiten_r-P5" pos="0.0027000000000000001 -0.095600000000000004 -0.019300000000000001"/>
          <site name="bifemlh_r_bifemlh_r-P2" pos="-0.030099999999999998 -0.035999999999999997 0.029430000000000001"/>
          <site name="bifemlh_r_bifemlh_r-P3" pos="-0.023400000000000001 -0.056300000000000003 0.034299999999999997"/>
          <site name="bifemsh_r_bifemsh_r-P2" pos="-0.030099999999999998 -0.035999999999999997 0.029430000000000001"/>
          <site name="bifemsh_r_bifemsh_r-P3" pos="-0.023400000000000001 -0.056300000000000003 0.034299999999999997"/>
          <site name="sar_r_sar_r-P3" pos="-0.0055999999999999999 -0.0419 -0.039899999999999998"/>
          <site name="sar_r_sar_r-P4" pos="0.0060000000000000001 -0.058900000000000001 -0.038300000000000001"/>
          <site name="sar_r_sar_r-P5" pos="0.024299999999999999 -0.084000000000000005 -0.0252"/>
          <site name="tfl_r_tfl_r-P4" pos="0.0060000000000000001 -0.0487 0.029700000000000001"/>
          <body name="grac_r_grac_r-P2" pos="0 0 0">
            <geom size="0.0005 0.0005 0.0005" rgba="0.0 0.0 1.0 0.0" contype="2" conaffinity="2"/>
            <joint name="grac_r_grac_r-P2_x" type="slide" axis="1 0 0" range="-0.02657 -0.01943"/>
            <joint name="grac_r_grac_r-P2_y" type="slide" axis="0 1 0" range="-0.05153 -0.0319"/>
            <joint name="grac_r_grac_r-P2_z" type="slide" axis="0 0 1" range="-0.03774 -0.0358"/>
            <site name="grac_r_grac_r-P2"/>
          </body>
          <site name="grac_r_grac_r-P3" pos="-0.019429999999999999 -0.051529999999999999 -0.035799999999999998"/>
          <site name="grac_r_grac_r-P4" pos="0.0060000000000000001 -0.083599999999999994 -0.022800000000000001"/>
          <body name="rect_fem_r_rect_fem_r-P3" pos="0 0 0.001399">
            <geom size="0.0005 0.0005 0.0005" rgba="0.0 0.0 1.0 0.0" contype="2" conaffinity="2"/>
            <joint name="rect_fem_r_rect_fem_r-P3_x" type="slide" axis="1 0 0" range="0.01558 0.0733"/>
            <joint name="rect_fem_r_rect_fem_r-P3_y" type="slide" axis="0 1 0" range="-0.06738 0.02531"/>
            <site name="rect_fem_r_rect_fem_r-P3"/>
          </body>
          <body name="vas_int_r_vas_int_r-P4" pos="0 0 0.001799">
            <geom size="0.0005 0.0005 0.0005" rgba="0.0 0.0 1.0 0.0" contype="2" conaffinity="2"/>
            <joint name="vas_int_r_vas_int_r-P4_x" type="slide" axis="1 0 0" range="0.008273 0.06844"/>
            <joint name="vas_int_r_vas_int_r-P4_y" type="slide" axis="0 1 0" range="-0.06857 0.02752"/>
            <site name="vas_int_r_vas_int_r-P4"/>
          </body>
          <body name="vas_lat_r_vas_lat_r-P5" pos="0 0 0.0165">
            <geom size="0.0005 0.0005 0.0005" rgba="0.0 0.0 1.0 0.0" contype="2" conaffinity="2"/>
            <joint name="vas_lat_r_vas_lat_r-P5_x" type="slide" axis="1 0 0" range="0.01429 0.07119"/>
            <joint name="vas_lat_r_vas_lat_r-P5_y" type="slide" axis="0 1 0" range="-0.06534 0.02344"/>
            <site name="vas_lat_r_vas_lat_r-P5"/>
          </body>
          <site name="soleus_r_soleus_r-P1" pos="-0.0023999999999999998 -0.15329999999999999 0.0071000000000000004"/>
          <site name="tib_post_r_tib_post_r-P1" pos="-0.0094000000000000004 -0.1348 0.0019"/>
          <site name="tib_post_r_tib_post_r-P2" pos="-0.0144 -0.40510000000000002 -0.0229"/>
          <site name="flex_dig_r_flex_dig_r-P1" pos="-0.0083000000000000001 -0.2046 -0.0018"/>
          <site name="flex_dig_r_flex_dig_r-P2" pos="-0.0154 -0.40510000000000002 -0.019599999999999999"/>
          <site name="flex_hal_r_flex_hal_r-P1" pos="-0.0079000000000000008 -0.2334 0.024400000000000002"/>
          <site name="flex_hal_r_flex_hal_r-P2" pos="-0.018599999999999998 -0.40789999999999998 -0.017399999999999999"/>
          <site name="tib_ant_r_tib_ant_r-P1" pos="0.017899999999999999 -0.16239999999999999 0.0115"/>
          <site name="tib_ant_r_tib_ant_r-P2" pos="0.032899999999999999 -0.39510000000000001 -0.0177"/>
          <site name="per_brev_r_per_brev_r-P1" pos="-0.0070000000000000001 -0.2646 0.032500000000000001"/>
          <site name="per_brev_r_per_brev_r-P2" pos="-0.019800000000000002 -0.41839999999999999 0.028299999999999999"/>
          <site name="per_brev_r_per_brev_r-P3" pos="-0.0144 -0.42949999999999999 0.028899999999999999"/>
          <site name="per_long_r_per_long_r-P1" pos="0.00050000000000000001 -0.15679999999999999 0.036200000000000003"/>
          <site name="per_long_r_per_long_r-P2" pos="-0.0207 -0.42049999999999998 0.0286"/>
          <site name="per_long_r_per_long_r-P3" pos="-0.016199999999999999 -0.43190000000000001 0.028899999999999999"/>
          <site name="per_tert_r_per_tert_r-P1" pos="0.001 -0.28039999999999998 0.023099999999999999"/>
          <site name="per_tert_r_per_tert_r-P2" pos="0.0229 -0.40689999999999998 0.015900000000000001"/>
          <site name="ext_dig_r_ext_dig_r-P1" pos="0.0032000000000000002 -0.1381 0.0276"/>
          <site name="ext_dig_r_ext_dig_r-P2" pos="0.028899999999999999 -0.4007 0.0071999999999999998"/>
          <site name="ext_hal_r_ext_hal_r-P1" pos="0.0011999999999999999 -0.1767 0.022800000000000001"/>
          <site name="ext_hal_r_ext_hal_r-P2" pos="0.032599999999999997 -0.39850000000000002 -0.0085000000000000006"/>
        </body>
        <site name="glut_med1_r_glut_med1_r-P2" pos="-0.0218 -0.0117 0.055500000000000001"/>
        <site name="glut_med2_r_glut_med2_r-P2" pos="-0.0258 -0.0057999999999999996 0.052699999999999997"/>
        <site name="glut_med3_r_glut_med3_r-P2" pos="-0.0309 -0.0047000000000000002 0.051799999999999999"/>
        <site name="glut_min1_r_glut_min1_r-P2" pos="-0.0071999999999999998 -0.0104 0.056000000000000001"/>
        <site name="glut_min2_r_glut_min2_r-P2" pos="-0.0095999999999999992 -0.0104 0.056000000000000001"/>
        <site name="glut_min3_r_glut_min3_r-P2" pos="-0.0135 -0.0083000000000000001 0.055"/>
        <site name="bifemsh_r_bifemsh_r-P1" pos="0.0050000000000000001 -0.21110000000000001 0.023400000000000001"/>
        <site name="sar_r_sar_r-P2" pos="-0.0030000000000000001 -0.35680000000000001 -0.042099999999999999"/>
        <site name="add_long_r_add_long_r-P2" pos="0.0050000000000000001 -0.21110000000000001 0.023400000000000001"/>
        <site name="add_brev_r_add_brev_r-P2" pos="0.00089999999999999998 -0.1196 0.029399999999999999"/>
        <site name="add_mag1_r_add_mag1_r-P2" pos="-0.0044999999999999997 -0.1211 0.0339"/>
        <site name="add_mag2_r_add_mag2_r-P2" pos="0.0054000000000000003 -0.22850000000000001 0.022700000000000001"/>
        <site name="add_mag3_r_add_mag3_r-P2" pos="0.0070000000000000001 -0.38369999999999999 -0.026599999999999999"/>
        <site name="tfl_r_tfl_r-P2" pos="0.029399999999999999 -0.099500000000000005 0.059700000000000003"/>
        <site name="tfl_r_tfl_r-P3" pos="0.0054000000000000003 -0.40489999999999998 0.035700000000000003"/>
        <site name="pect_r_pect_r-P2" pos="-0.012200000000000001 -0.082199999999999995 0.0253"/>
        <site name="glut_max1_r_glut_max1_r-P3" pos="-0.045699999999999998 -0.024799999999999999 0.039199999999999999"/>
        <site name="glut_max1_r_glut_max1_r-P4" pos="-0.027699999999999999 -0.056599999999999998 0.047"/>
        <site name="glut_max2_r_glut_max2_r-P3" pos="-0.042599999999999999 -0.052999999999999999 0.0293"/>
        <site name="glut_max2_r_glut_max2_r-P4" pos="-0.015599999999999999 -0.1016 0.0419"/>
        <site name="glut_max3_r_glut_max3_r-P3" pos="-0.029899999999999999 -0.1041 0.0135"/>
        <site name="glut_max3_r_glut_max3_r-P4" pos="-0.0060000000000000001 -0.1419 0.041099999999999998"/>
        <site name="iliacus_r_iliacus_r-P4" pos="0.0016999999999999999 -0.054300000000000001 0.0057000000000000002"/>
        <site name="iliacus_r_iliacus_r-P5" pos="-0.019300000000000001 -0.062100000000000002 0.0129"/>
        <site name="psoas_r_psoas_r-P4" pos="0.0016000000000000001 -0.050700000000000002 0.0038"/>
        <site name="psoas_r_psoas_r-P5" pos="-0.018800000000000001 -0.059700000000000003 0.0104"/>
        <site name="quad_fem_r_quad_fem_r-P2" pos="-0.038100000000000002 -0.035900000000000001 0.036600000000000001"/>
        <site name="gem_r_gem_r-P2" pos="-0.014200000000000001 -0.0033 0.044299999999999999"/>
        <site name="peri_r_peri_r-P3" pos="-0.014800000000000001 -0.0035999999999999999 0.043700000000000003"/>
        <site name="rect_fem_r_rect_fem_r-P2" pos="0.033399999999999999 -0.40300000000000002 0.0019"/>
        <site name="vas_int_r_vas_int_r-P1" pos="0.029000000000000001 -0.19239999999999999 0.031"/>
        <site name="vas_int_r_vas_int_r-P2" pos="0.033500000000000002 -0.2084 0.028500000000000001"/>
        <body name="vas_int_r_vas_int_r-P3" pos="0.0335 0 0">
          <geom size="0.0005 0.0005 0.0005" rgba="0.0 0.0 1.0 0.0" contype="2" conaffinity="2"/>
          <joint name="vas_int_r_vas_int_r-P3_y" type="slide" axis="0 1 0" range="-0.403 -0.2084"/>
          <joint name="vas_int_r_vas_int_r-P3_z" type="slide" axis="0 0 1" range="0.0055 0.0285"/>
          <site name="vas_int_r_vas_int_r-P3"/>
        </body>
        <site name="vas_lat_r_vas_lat_r-P1" pos="0.0047999999999999996 -0.18540000000000001 0.0349"/>
        <site name="vas_lat_r_vas_lat_r-P2" pos="0.0269 -0.2591 0.040899999999999999"/>
        <body name="vas_lat_r_vas_lat_r-P3" pos="0 0 0">
          <geom size="0.0005 0.0005 0.0005" rgba="0.0 0.0 1.0 0.0" contype="2" conaffinity="2"/>
          <joint name="vas_lat_r_vas_lat_r-P3_x" type="slide" axis="1 0 0" range="0.0269 0.0361"/>
          <joint name="vas_lat_r_vas_lat_r-P3_y" type="slide" axis="0 1 0" range="-0.403 -0.2591"/>
          <joint name="vas_lat_r_vas_lat_r-P3_z" type="slide" axis="0 0 1" range="0.0205 0.0409"/>
          <site name="vas_lat_r_vas_lat_r-P3"/>
        </body>
        <body name="vas_lat_r_vas_lat_r-P4" pos="0 0 0">
          <geom size="0.0005 0.0005 0.0005" rgba="0.0 0.0 1.0 0.0" contype="2" conaffinity="2"/>
          <joint name="vas_lat_r_vas_lat_r-P4_x" type="slide" axis="1 0 0" range="0.0253 0.0269"/>
          <joint name="vas_lat_r_vas_lat_r-P4_y" type="slide" axis="0 1 0" range="-0.4243 -0.2591"/>
          <joint name="vas_lat_r_vas_lat_r-P4_z" type="slide" axis="0 0 1" range="0.0184 0.0409"/>
          <site name="vas_lat_r_vas_lat_r-P4"/>
        </body>
        <site name="med_gas_r_med_gas_r-P1" pos="-0.019 -0.39290000000000003 -0.0235"/>
        <body name="med_gas_r_med_gas_r-P2" pos="0 0 0">
          <geom size="0.0005 0.0005 0.0005" rgba="0.0 0.0 1.0 0.0" contype="2" conaffinity="2"/>
          <joint name="med_gas_r_med_gas_r-P2_x" type="slide" axis="1 0 0" range="-0.03 -0.019"/>
          <joint name="med_gas_r_med_gas_r-P2_y" type="slide" axis="0 1 0" range="-0.4022 -0.3929"/>
          <joint name="med_gas_r_med_gas_r-P2_z" type="slide" axis="0 0 1" range="-0.0258 -0.0235"/>
          <site name="med_gas_r_med_gas_r-P2"/>
        </body>
        <site name="lat_gas_r_lat_gas_r-P1" pos="-0.021999999999999999 -0.39460000000000001 0.027199999999999998"/>
        <body name="lat_gas_r_lat_gas_r-P2" pos="0 0 0.0272">
          <geom size="0.0005 0.0005 0.0005" rgba="0.0 0.0 1.0 0.0" contype="2" conaffinity="2"/>
          <joint name="lat_gas_r_lat_gas_r-P2_x" type="slide" axis="1 0 0" range="-0.03 -0.022"/>
          <joint name="lat_gas_r_lat_gas_r-P2_y" type="slide" axis="0 1 0" range="-0.4018 -0.3946"/>
          <site name="lat_gas_r_lat_gas_r-P2"/>
        </body>
      </body>
      <body name="femur_l" pos="-0.0707 -0.0661 -0.0835" euler="-0 0 0">
        <inertial mass="9.3013999999999992" pos="0 -0.17000000000000001 0" fullinertia="0.13389999999999999 0.035099999999999999 0.14119999999999999 0 0 0"/>
        <geom name="femur_l_geom_1" type="mesh" mesh="femur_l_geom_1_femur_l" rgba="1 1 1 1" group="0"/>
        <joint name="hip_flexion_l" range="-2.094 2.094" limited="false" user="0.0" ref="0" axis="0 0 1" type="hinge"/>
        <joint name="hip_adduction_l" range="-2.094 2.094" limited="false" user="0.0" ref="0" axis="-1 0 0" type="hinge"/>
        <joint name="hip_rotation_l" range="-2.094 2.094" limited="false" user="0.0" ref="0" axis="0 -1 0" type="hinge"/>
        <body name="tibia_l" pos="0 0 0" euler="-0 0 0">
          <inertial mass="3.7075" pos="0 -0.1867 0" fullinertia="0.0504 0.0051000000000000004 0.0511 0 0 0"/>
          <geom name="tibia_l_geom_1" type="mesh" mesh="tibia_l_geom_1_tibia_l" rgba="1 1 1 1" group="0"/>
          <geom name="tibia_l_geom_2" type="mesh" mesh="tibia_l_geom_2_l_fibula" rgba="1 1 1 1" group="0"/>
          <joint name="knee_l_translation1" range="-0.005574 0.00411" limited="true" user="-0.0036392466304026047" ref="0" axis="1 0 0" type="slide"/>
          <joint name="knee_l_translation2" range="-0.4226 -0.3953" limited="true" user="-0.395713445137591" ref="0" axis="0 1 0" type="slide"/>
          <joint name="knee_angle_l" range="-2.094 0.1745" limited="false" user="0.0" ref="0" axis="0 0 1" type="hinge"/>
          <body name="AnkleAssembly" pos="-0.04 -0.124 -0.05" euler="-0 0 0">
            <inertial mass="1.71" pos="0.041360000000000001 -0.24932000000000001 0.040059999999999998" fullinertia="2.073e-3 1.51e-3 1.99e-3 -9.66e-5 -1.03e-4 -3.59e-4"/>
            <geom name="AnkleAssembly_geom_1" type="mesh" mesh="AnkleAssembly_geom_1_AnkleAssembly" rgba="0.87 0.56000000000000005 0.34000000000000002 1" group="0"/>
            <body name="Foot" pos="0 0 0" euler="-0 0 0">
              <inertial mass="0.76" pos="0.062149999999999997 -0.35314000000000001 0.04496" fullinertia="0.245e-3 1.78e-3 1.83e-3 -1.82e-4 4.53e-5 2.83e-5"/>
              <geom name="Foot_geom_1" type="mesh" mesh="Foot_geom_1_Foot_Amp" rgba="0.30196099999999998 0.30196099999999998 0.30196099999999998 1" group="0"/>
              <joint name="yR_FootToAnkleAssembly" range="-0.8727 0.5236" limited="true" user="-0.0" ref="0" axis="1 -2.654e-06 -7.041e-12" type="hinge"/>
              <joint name="zR_FootToAnkleAssembly" range="-0.45 0.6" limited="true" user="0.0" ref="0" axis="-1.225e-16 -2.654e-06 1" type="hinge"/>
            </body>
          </body>
          <body name="semimem_l_semimem_l-P2" pos="0 0 0.01891">
            <geom size="0.0005 0.0005 0.0005" rgba="0.0 0.0 1.0 0.0" contype="2" conaffinity="2"/>
            <joint name="semimem_l_semimem_l-P2_x" type="slide" axis="1 0 0" range="-0.0348 -0.027"/>
            <joint name="semimem_l_semimem_l-P2_y" type="slide" axis="0 1 0" range="-0.04771 -0.03519"/>
            <site name="semimem_l_semimem_l-P2"/>
          </body>
          <site name="semimem_l_semimem_l-P3" pos="-0.027 -0.047710000000000002 0.019570000000000001"/>
          <body name="semiten_l_semiten_l-P2" pos="0 0 0.02277">
            <geom size="0.0005 0.0005 0.0005" rgba="0.0 0.0 1.0 0.0" contype="2" conaffinity="2"/>
            <joint name="semiten_l_semiten_l-P2_x" type="slide" axis="1 0 0" range="-0.04203 -0.03322"/>
            <joint name="semiten_l_semiten_l-P2_y" type="slide" axis="0 1 0" range="-0.05282 -0.02859"/>
            <site name="semiten_l_semiten_l-P2"/>
          </body>
          <site name="semiten_l_semiten_l-P3" pos="-0.03322 -0.052819999999999999 0.022880000000000001"/>
          <site name="semiten_l_semiten_l-P4" pos="-0.011299999999999999 -0.0746 0.024500000000000001"/>
          <site name="semiten_l_semiten_l-P5" pos="0.0027000000000000001 -0.095600000000000004 0.019300000000000001"/>
          <site name="bifemlh_l_bifemlh_l-P2" pos="-0.030099999999999998 -0.035999999999999997 -0.029430000000000001"/>
          <site name="bifemlh_l_bifemlh_l-P3" pos="-0.023400000000000001 -0.056300000000000003 -0.034299999999999997"/>
          <site name="bifemsh_l_bifemsh_l-P2" pos="-0.030099999999999998 -0.035999999999999997 -0.029430000000000001"/>
          <site name="bifemsh_l_bifemsh_l-P3" pos="-0.023400000000000001 -0.056300000000000003 -0.034299999999999997"/>
          <site name="sar_l_sar_l-P3" pos="-0.0055999999999999999 -0.0419 0.039899999999999998"/>
          <site name="sar_l_sar_l-P4" pos="0.0060000000000000001 -0.058900000000000001 0.038300000000000001"/>
          <site name="sar_l_sar_l-P5" pos="0.024299999999999999 -0.084000000000000005 0.0252"/>
          <body name="rect_fem_l_rect_fem_l-P3" pos="0 0 0.001399">
            <geom size="0.0005 0.0005 0.0005" rgba="0.0 0.0 1.0 0.0" contype="2" conaffinity="2"/>
            <joint name="rect_fem_l_rect_fem_l-P3_x" type="slide" axis="1 0 0" range="0.01558 0.0733"/>
            <joint name="rect_fem_l_rect_fem_l-P3_y" type="slide" axis="0 1 0" range="-0.06738 0.02531"/>
            <site name="rect_fem_l_rect_fem_l-P3"/>
          </body>
          <body name="vas_int_l_vas_int_l-P4" pos="0 0 0.001799">
            <geom size="0.0005 0.0005 0.0005" rgba="0.0 0.0 1.0 0.0" contype="2" conaffinity="2"/>
            <joint name="vas_int_l_vas_int_l-P4_x" type="slide" axis="1 0 0" range="0.008273 0.06844"/>
            <joint name="vas_int_l_vas_int_l-P4_y" type="slide" axis="0 1 0" range="-0.06857 0.02752"/>
            <site name="vas_int_l_vas_int_l-P4"/>
          </body>
          <body name="vas_lat_l_vas_lat_l-P5" pos="0 0 0.0165">
            <geom size="0.0005 0.0005 0.0005" rgba="0.0 0.0 1.0 0.0" contype="2" conaffinity="2"/>
            <joint name="vas_lat_l_vas_lat_l-P5_x" type="slide" axis="1 0 0" range="0.01429 0.07119"/>
            <joint name="vas_lat_l_vas_lat_l-P5_y" type="slide" axis="0 1 0" range="-0.06534 0.02344"/>
            <site name="vas_lat_l_vas_lat_l-P5"/>
          </body>
        </body>
        <site name="glut_med1_l_glut_med1_l-P2" pos="-0.0218 -0.0117 -0.055500000000000001"/>
        <site name="glut_med2_l_glut_med2_l-P2" pos="-0.0258 -0.0057999999999999996 -0.052699999999999997"/>
        <site name="glut_med3_l_glut_med3_l-P2" pos="-0.0309 -0.0047000000000000002 -0.051799999999999999"/>
        <site name="glut_min1_l_glut_min1_l-P2" pos="-0.0071999999999999998 -0.0104 -0.056000000000000001"/>
        <site name="glut_min2_l_glut_min2_l-P2" pos="-0.0095999999999999992 -0.0104 -0.056000000000000001"/>
        <site name="glut_min3_l_glut_min3_l-P2" pos="-0.0135 -0.0083000000000000001 -0.055"/>
        <site name="bifemsh_l_bifemsh_l-P1" pos="0.0050000000000000001 -0.21110000000000001 -0.023400000000000001"/>
        <site name="sar_l_sar_l-P2" pos="-0.0030000000000000001 -0.35680000000000001 0.042099999999999999"/>
        <site name="add_long_l_add_long_l-P2" pos="0.0050000000000000001 -0.21110000000000001 -0.023400000000000001"/>
        <site name="add_brev_l_add_brev_l-P2" pos="0.00089999999999999998 -0.1196 -0.029399999999999999"/>
        <site name="add_mag1_l_add_mag1_l-P2" pos="-0.0044999999999999997 -0.1211 -0.0339"/>
        <site name="add_mag2_l_add_mag2_l-P2" pos="0.0054000000000000003 -0.22850000000000001 -0.022700000000000001"/>
        <site name="add_mag3_l_add_mag3_l-P2" pos="0.0070000000000000001 -0.38369999999999999 0.026599999999999999"/>
        <site name="pect_l_pect_l-P2" pos="-0.012200000000000001 -0.082199999999999995 -0.0253"/>
        <site name="glut_max1_l_glut_max1_l-P3" pos="-0.045699999999999998 -0.024799999999999999 -0.039199999999999999"/>
        <site name="glut_max1_l_glut_max1_l-P4" pos="-0.027699999999999999 -0.056599999999999998 -0.047"/>
        <site name="glut_max2_l_glut_max2_l-P3" pos="-0.042599999999999999 -0.052999999999999999 -0.0293"/>
        <site name="glut_max2_l_glut_max2_l-P4" pos="-0.015599999999999999 -0.1016 -0.0419"/>
        <site name="glut_max3_l_glut_max3_l-P3" pos="-0.029899999999999999 -0.1041 -0.0135"/>
        <site name="glut_max3_l_glut_max3_l-P4" pos="-0.0060000000000000001 -0.1419 -0.041099999999999998"/>
        <site name="iliacus_l_iliacus_l-P4" pos="0.0016999999999999999 -0.054300000000000001 -0.0057000000000000002"/>
        <site name="iliacus_l_iliacus_l-P5" pos="-0.019300000000000001 -0.062100000000000002 -0.0129"/>
        <site name="psoas_l_psoas_l-P4" pos="0.0016000000000000001 -0.050700000000000002 -0.0038"/>
        <site name="psoas_l_psoas_l-P5" pos="-0.018800000000000001 -0.059700000000000003 -0.0104"/>
        <site name="quad_fem_l_quad_fem_l-P2" pos="-0.038100000000000002 -0.035900000000000001 -0.036600000000000001"/>
        <site name="gem_l_gem_l-P2" pos="-0.014200000000000001 -0.0033 -0.044299999999999999"/>
        <site name="peri_l_peri_l-P3" pos="-0.014800000000000001 -0.0035999999999999999 -0.043700000000000003"/>
        <site name="rect_fem_l_rect_fem_l-P2" pos="0.033399999999999999 -0.40300000000000002 0.0019"/>
        <site name="vas_int_l_vas_int_l-P1" pos="0.029000000000000001 -0.19239999999999999 0.031"/>
        <site name="vas_int_l_vas_int_l-P2" pos="0.033500000000000002 -0.2084 0.028500000000000001"/>
        <body name="vas_int_l_vas_int_l-P3" pos="0.0335 0 0">
          <geom size="0.0005 0.0005 0.0005" rgba="0.0 0.0 1.0 0.0" contype="2" conaffinity="2"/>
          <joint name="vas_int_l_vas_int_l-P3_y" type="slide" axis="0 1 0" range="-0.403 -0.2084"/>
          <joint name="vas_int_l_vas_int_l-P3_z" type="slide" axis="0 0 1" range="0.0055 0.0285"/>
          <site name="vas_int_l_vas_int_l-P3"/>
        </body>
        <site name="vas_lat_l_vas_lat_l-P1" pos="0.0047999999999999996 -0.18540000000000001 0.0349"/>
        <site name="vas_lat_l_vas_lat_l-P2" pos="0.0269 -0.2591 0.040899999999999999"/>
        <body name="vas_lat_l_vas_lat_l-P3" pos="0 0 0">
          <geom size="0.0005 0.0005 0.0005" rgba="0.0 0.0 1.0 0.0" contype="2" conaffinity="2"/>
          <joint name="vas_lat_l_vas_lat_l-P3_x" type="slide" axis="1 0 0" range="0.0269 0.0361"/>
          <joint name="vas_lat_l_vas_lat_l-P3_y" type="slide" axis="0 1 0" range="-0.403 -0.2591"/>
          <joint name="vas_lat_l_vas_lat_l-P3_z" type="slide" axis="0 0 1" range="0.0205 0.0409"/>
          <site name="vas_lat_l_vas_lat_l-P3"/>
        </body>
        <body name="vas_lat_l_vas_lat_l-P4" pos="0 0 0">
          <geom size="0.0005 0.0005 0.0005" rgba="0.0 0.0 1.0 0.0" contype="2" conaffinity="2"/>
          <joint name="vas_lat_l_vas_lat_l-P4_x" type="slide" axis="1 0 0" range="0.0253 0.0269"/>
          <joint name="vas_lat_l_vas_lat_l-P4_y" type="slide" axis="0 1 0" range="-0.4243 -0.2591"/>
          <joint name="vas_lat_l_vas_lat_l-P4_z" type="slide" axis="0 0 1" range="0.0184 0.0409"/>
          <site name="vas_lat_l_vas_lat_l-P4"/>
        </body>
      </body>
      <body name="torso" pos="-0.1007 0.0815 0" euler="-0 0 0">
        <inertial mass="34.236600000000003" pos="-0.029999999999999999 0.32000000000000001 0" fullinertia="1.4744999999999999 0.75549999999999995 1.4314 0 0 0"/>
        <geom name="torso_geom_1" type="mesh" mesh="torso_geom_1_hat_spine" rgba="1 1 1 1" group="0"/>
        <geom name="torso_geom_2" type="mesh" mesh="torso_geom_2_hat_jaw" rgba="1 1 1 1" group="0"/>
        <geom name="torso_geom_3" type="mesh" mesh="torso_geom_3_hat_skull" rgba="1 1 1 1" group="0"/>
        <geom name="torso_geom_4" type="mesh" mesh="torso_geom_4_hat_ribs" rgba="1 1 1 1" group="0"/>
        <joint name="lumbar_extension" range="-1.571 1.571" limited="false" user="0.0" ref="0" axis="0 0 1" type="hinge"/>
        <joint name="lumbar_bending" range="-1.571 1.571" limited="false" user="0.0" ref="0" axis="1 0 0" type="hinge"/>
        <joint name="lumbar_rotation" range="-1.571 1.571" limited="false" user="0.0" ref="0" axis="0 1 0" type="hinge"/>
        <site name="ercspn_r_ercspn_r-P2" pos="-0.055 0.11 0.0241"/>
        <site name="ercspn_l_ercspn_l-P2" pos="-0.055 0.11 -0.0241"/>
        <site name="intobl_r_intobl_r-P2" pos="0.070000000000000007 0.16 0.014999999999999999"/>
        <site name="intobl_l_intobl_l-P2" pos="0.070000000000000007 0.16 -0.014999999999999999"/>
        <site name="extobl_r_extobl_r-P2" pos="0.065000000000000002 0.11 0.11"/>
        <site name="extobl_l_extobl_l-P2" pos="0.065000000000000002 0.11 -0.11"/>
      </body>
      <site name="glut_med1_r_glut_med1_r-P1" pos="-0.040800000000000003 0.0304 0.12089999999999999"/>
      <site name="glut_med2_r_glut_med2_r-P1" pos="-0.085500000000000007 0.044499999999999998 0.076600000000000001"/>
      <site name="glut_med3_r_glut_med3_r-P1" pos="-0.12230000000000001 0.010500000000000001 0.064799999999999996"/>
      <site name="glut_min1_r_glut_min1_r-P1" pos="-0.046699999999999998 -0.0080000000000000002 0.1056"/>
      <site name="glut_min2_r_glut_min2_r-P1" pos="-0.063299999999999995 -0.0064999999999999997 0.099099999999999994"/>
      <site name="glut_min3_r_glut_min3_r-P1" pos="-0.083400000000000002 -0.0063 0.085599999999999996"/>
      <site name="semimem_r_semimem_r-P1" pos="-0.1192 -0.097470000000000001 0.071510000000000004"/>
      <site name="semiten_r_semiten_r-P1" pos="-0.12634999999999999 -0.10988000000000001 0.060389999999999999"/>
      <site name="bifemlh_r_bifemlh_r-P1" pos="-0.12595999999999999 -0.10256999999999999 0.069440000000000002"/>
      <site name="sar_r_sar_r-P1" pos="-0.015299999999999999 -0.0012999999999999999 0.1242"/>
      <site name="add_long_r_add_long_r-P1" pos="-0.031600000000000003 -0.083599999999999994 0.016899999999999998"/>
      <site name="add_brev_r_add_brev_r-P1" pos="-0.058700000000000002 -0.091499999999999998 0.016400000000000001"/>
      <site name="add_mag1_r_add_mag1_r-P1" pos="-0.073200000000000001 -0.1174 0.025499999999999998"/>
      <site name="add_mag2_r_add_mag2_r-P1" pos="-0.083099999999999993 -0.1192 0.030800000000000001"/>
      <site name="add_mag3_r_add_mag3_r-P1" pos="-0.11108 -0.11413 0.048820000000000002"/>
      <site name="tfl_r_tfl_r-P1" pos="-0.031099999999999999 0.021399999999999999 0.1241"/>
      <site name="pect_r_pect_r-P1" pos="-0.043099999999999999 -0.076799999999999993 0.045100000000000001"/>
      <site name="grac_r_grac_r-P1" pos="-0.074010000000000006 -0.1187 0.02794"/>
      <site name="glut_max1_r_glut_max1_r-P1" pos="-0.1195 0.061199999999999997 0.070000000000000007"/>
      <site name="glut_max1_r_glut_max1_r-P2" pos="-0.12909999999999999 0.0011999999999999999 0.088599999999999998"/>
      <site name="glut_max2_r_glut_max2_r-P1" pos="-0.13489999999999999 0.017600000000000001 0.056300000000000003"/>
      <site name="glut_max2_r_glut_max2_r-P2" pos="-0.1376 -0.051999999999999998 0.091399999999999995"/>
      <site name="glut_max3_r_glut_max3_r-P1" pos="-0.15559999999999999 -0.031399999999999997 0.0057999999999999996"/>
      <site name="glut_max3_r_glut_max3_r-P2" pos="-0.15290000000000001 -0.1052 0.040300000000000002"/>
      <site name="iliacus_r_iliacus_r-P1" pos="-0.067400000000000002 0.036499999999999998 0.085400000000000004"/>
      <site name="iliacus_r_iliacus_r-P2" pos="-0.0258 -0.055 0.081100000000000005"/>
      <body name="iliacus_r_iliacus_r-P3" pos="0 0 0.0811">
        <geom size="0.0005 0.0005 0.0005" rgba="0.0 0.0 1.0 0.0" contype="2" conaffinity="2"/>
        <joint name="iliacus_r_iliacus_r-P3_x" type="slide" axis="1 0 0" range="-0.0288 -0.0258"/>
        <joint name="iliacus_r_iliacus_r-P3_y" type="slide" axis="0 1 0" range="-0.0805 -0.055"/>
        <site name="iliacus_r_iliacus_r-P3"/>
      </body>
      <site name="psoas_r_psoas_r-P1" pos="-0.064699999999999994 0.088700000000000001 0.028899999999999999"/>
      <site name="psoas_r_psoas_r-P2" pos="-0.023800000000000002 -0.057000000000000002 0.075899999999999995"/>
      <body name="psoas_r_psoas_r-P3" pos="0 0 0">
        <geom size="0.0005 0.0005 0.0005" rgba="0.0 0.0 1.0 0.0" contype="2" conaffinity="2"/>
        <joint name="psoas_r_psoas_r-P3_x" type="slide" axis="1 0 0" range="-0.0288 -0.0238"/>
        <joint name="psoas_r_psoas_r-P3_y" type="slide" axis="0 1 0" range="-0.0805 -0.057"/>
        <joint name="psoas_r_psoas_r-P3_z" type="slide" axis="0 0 1" range="0.0759 0.0816"/>
        <site name="psoas_r_psoas_r-P3"/>
      </body>
      <site name="quad_fem_r_quad_fem_r-P1" pos="-0.1143 -0.11509999999999999 0.051999999999999998"/>
      <site name="gem_r_gem_r-P1" pos="-0.1133 -0.082000000000000003 0.071400000000000005"/>
      <site name="peri_r_peri_r-P1" pos="-0.1396 0.00029999999999999997 0.0235"/>
      <site name="peri_r_peri_r-P2" pos="-0.1193 -0.0276 0.065699999999999995"/>
      <site name="rect_fem_r_rect_fem_r-P1" pos="-0.029499999999999998 -0.031099999999999999 0.096799999999999997"/>
      <site name="glut_med1_l_glut_med1_l-P1" pos="-0.040800000000000003 0.0304 -0.12089999999999999"/>
      <site name="glut_med2_l_glut_med2_l-P1" pos="-0.085500000000000007 0.044499999999999998 -0.076600000000000001"/>
      <site name="glut_med3_l_glut_med3_l-P1" pos="-0.12230000000000001 0.010500000000000001 -0.064799999999999996"/>
      <site name="glut_min1_l_glut_min1_l-P1" pos="-0.046699999999999998 -0.0080000000000000002 -0.1056"/>
      <site name="glut_min2_l_glut_min2_l-P1" pos="-0.063299999999999995 -0.0064999999999999997 -0.099099999999999994"/>
      <site name="glut_min3_l_glut_min3_l-P1" pos="-0.083400000000000002 -0.0063 -0.085599999999999996"/>
      <site name="semimem_l_semimem_l-P1" pos="-0.1192 -0.097470000000000001 -0.071510000000000004"/>
      <site name="semiten_l_semiten_l-P1" pos="-0.12634999999999999 -0.10988000000000001 -0.060389999999999999"/>
      <site name="bifemlh_l_bifemlh_l-P1" pos="-0.12595999999999999 -0.10256999999999999 -0.069440000000000002"/>
      <site name="sar_l_sar_l-P1" pos="-0.015299999999999999 -0.0012999999999999999 -0.1242"/>
      <site name="add_long_l_add_long_l-P1" pos="-0.031600000000000003 -0.083599999999999994 -0.016899999999999998"/>
      <site name="add_brev_l_add_brev_l-P1" pos="-0.058700000000000002 -0.091499999999999998 -0.016400000000000001"/>
      <site name="add_mag1_l_add_mag1_l-P1" pos="-0.073200000000000001 -0.1174 -0.025499999999999998"/>
      <site name="add_mag2_l_add_mag2_l-P1" pos="-0.083099999999999993 -0.1192 -0.030800000000000001"/>
      <site name="add_mag3_l_add_mag3_l-P1" pos="-0.11108 -0.11413 -0.048820000000000002"/>
      <site name="pect_l_pect_l-P1" pos="-0.043099999999999999 -0.076799999999999993 -0.045100000000000001"/>
      <site name="glut_max1_l_glut_max1_l-P1" pos="-0.1195 0.061199999999999997 -0.070000000000000007"/>
      <site name="glut_max1_l_glut_max1_l-P2" pos="-0.12909999999999999 0.0011999999999999999 -0.088599999999999998"/>
      <site name="glut_max2_l_glut_max2_l-P1" pos="-0.13489999999999999 0.017600000000000001 -0.056300000000000003"/>
      <site name="glut_max2_l_glut_max2_l-P2" pos="-0.1376 -0.051999999999999998 -0.091399999999999995"/>
      <site name="glut_max3_l_glut_max3_l-P1" pos="-0.15559999999999999 -0.031399999999999997 -0.0057999999999999996"/>
      <site name="glut_max3_l_glut_max3_l-P2" pos="-0.15290000000000001 -0.1052 -0.040300000000000002"/>
      <site name="iliacus_l_iliacus_l-P1" pos="-0.067400000000000002 0.036499999999999998 -0.085400000000000004"/>
      <site name="iliacus_l_iliacus_l-P2" pos="-0.0258 -0.055 -0.081100000000000005"/>
      <body name="iliacus_l_iliacus_l-P3" pos="0 0 -0.0816">
        <geom size="0.0005 0.0005 0.0005" rgba="0.0 0.0 1.0 0.0" contype="2" conaffinity="2"/>
        <joint name="iliacus_l_iliacus_l-P3_x" type="slide" axis="1 0 0" range="-0.0288 -0.0258"/>
        <joint name="iliacus_l_iliacus_l-P3_y" type="slide" axis="0 1 0" range="-0.0805 -0.055"/>
        <site name="iliacus_l_iliacus_l-P3"/>
      </body>
      <site name="psoas_l_psoas_l-P1" pos="-0.064699999999999994 0.088700000000000001 -0.028899999999999999"/>
      <site name="psoas_l_psoas_l-P2" pos="-0.023800000000000002 -0.057000000000000002 -0.075899999999999995"/>
      <body name="psoas_l_psoas_l-P3" pos="0 0 0">
        <geom size="0.0005 0.0005 0.0005" rgba="0.0 0.0 1.0 0.0" contype="2" conaffinity="2"/>
        <joint name="psoas_l_psoas_l-P3_x" type="slide" axis="1 0 0" range="-0.0288 -0.0238"/>
        <joint name="psoas_l_psoas_l-P3_y" type="slide" axis="0 1 0" range="-0.0805 -0.057"/>
        <joint name="psoas_l_psoas_l-P3_z" type="slide" axis="0 0 1" range="-0.0816 -0.0759"/>
        <site name="psoas_l_psoas_l-P3"/>
      </body>
      <site name="quad_fem_l_quad_fem_l-P1" pos="-0.1143 -0.11509999999999999 -0.051999999999999998"/>
      <site name="gem_l_gem_l-P1" pos="-0.1133 -0.082000000000000003 -0.071400000000000005"/>
      <site name="peri_l_peri_l-P1" pos="-0.1396 0.00029999999999999997 -0.0235"/>
      <site name="peri_l_peri_l-P2" pos="-0.1193 -0.0276 -0.065699999999999995"/>
      <site name="rect_fem_l_rect_fem_l-P1" pos="-0.029499999999999998 -0.031099999999999999 0.096799999999999997"/>
      <site name="ercspn_r_ercspn_r-P1" pos="-0.14000000000000001 0.043900000000000002 0.0436"/>
      <site name="ercspn_l_ercspn_l-P1" pos="-0.14000000000000001 0.043900000000000002 -0.0436"/>
      <site name="intobl_r_intobl_r-P1" pos="-0.040000000000000001 0.070000000000000007 0.1157"/>
      <site name="intobl_l_intobl_l-P1" pos="-0.040000000000000001 0.070000000000000007 -0.1157"/>
      <site name="extobl_r_extobl_r-P1" pos="-0.029999999999999999 -0.063600000000000004 0.01"/>
      <site name="extobl_l_extobl_l-P1" pos="-0.029999999999999999 -0.063600000000000004 -0.01"/>
    </body>
  </worldbody>
  <asset>
    <texture type="skybox" builtin="gradient" rgb1="1 1 1" rgb2="0.6 0.8 1" width="256" height="256"/>
    <mesh name="ground_geom_1_treadmill" file="Geometry/treadmill.stl" scale="1 1 1"/>
    <mesh name="pelvis_geom_1_sacrum" file="Geometry/sacrum.stl" scale="1 1 1"/>
    <mesh name="pelvis_geom_2_pelvis" file="Geometry/pelvis.stl" scale="1 1 1"/>
    <mesh name="pelvis_geom_3_l_pelvis" file="Geometry/l_pelvis.stl" scale="1 1 1"/>
    <mesh name="femur_r_geom_1_femur_r" file="Geometry/femur_r.stl" scale="1 1 1"/>
    <mesh name="tibia_r_geom_1_tibia_r" file="Geometry/tibia_r.stl" scale="1 1 1"/>
    <mesh name="tibia_r_geom_2_fibula" file="Geometry/fibula.stl" scale="1 1 1"/>
    <mesh name="talus_r_geom_1_talus" file="Geometry/talus.stl" scale="1 1 1"/>
    <mesh name="calcn_r_geom_1_foot" file="Geometry/foot.stl" scale="1 1 1"/>
    <mesh name="toes_r_geom_1_bofoot" file="Geometry/bofoot.stl" scale="1 1 1"/>
    <mesh name="femur_l_geom_1_femur_l" file="Geometry/femur_l.stl" scale="1 1 1"/>
    <mesh name="tibia_l_geom_1_tibia_l" file="Geometry/tibia_l.stl" scale="1 1 1"/>
    <mesh name="tibia_l_geom_2_l_fibula" file="Geometry/l_fibula.stl" scale="1 1 1"/>
    <mesh name="AnkleAssembly_geom_1_AnkleAssembly" file="Geometry/AnkleAssembly.stl" scale="1 1 1"/>
    <mesh name="Foot_geom_1_Foot_Amp" file="Geometry/Foot_Amp.stl" scale="1 1 1"/>
    <mesh name="torso_geom_1_hat_spine" file="Geometry/hat_spine.stl" scale="1 1 1"/>
    <mesh name="torso_geom_2_hat_jaw" file="Geometry/hat_jaw.stl" scale="1 1 1"/>
    <mesh name="torso_geom_3_hat_skull" file="Geometry/hat_skull.stl" scale="1 1 1"/>
    <mesh name="torso_geom_4_hat_ribs" file="Geometry/hat_ribs.stl" scale="1 1 1"/>
  </asset>
  <tendon>
    <!-- Leave this comment here to make 'tendon' element pretty printed !-->
    <spatial name="glut_med1_r_tendon">
      <site site="glut_med1_r_glut_med1_r-P1"/>
      <site site="glut_med1_r_glut_med1_r-P2"/>
    </spatial>
    <spatial name="glut_med2_r_tendon">
      <site site="glut_med2_r_glut_med2_r-P1"/>
      <site site="glut_med2_r_glut_med2_r-P2"/>
    </spatial>
    <spatial name="glut_med3_r_tendon">
      <site site="glut_med3_r_glut_med3_r-P1"/>
      <site site="glut_med3_r_glut_med3_r-P2"/>
    </spatial>
    <spatial name="glut_min1_r_tendon">
      <site site="glut_min1_r_glut_min1_r-P1"/>
      <site site="glut_min1_r_glut_min1_r-P2"/>
    </spatial>
    <spatial name="glut_min2_r_tendon">
      <site site="glut_min2_r_glut_min2_r-P1"/>
      <site site="glut_min2_r_glut_min2_r-P2"/>
    </spatial>
    <spatial name="glut_min3_r_tendon">
      <site site="glut_min3_r_glut_min3_r-P1"/>
      <site site="glut_min3_r_glut_min3_r-P2"/>
    </spatial>
    <spatial name="semimem_r_tendon">
      <site site="semimem_r_semimem_r-P1"/>
      <site site="semimem_r_semimem_r-P2"/>
      <site site="semimem_r_semimem_r-P3"/>
    </spatial>
    <spatial name="semiten_r_tendon">
      <site site="semiten_r_semiten_r-P1"/>
      <site site="semiten_r_semiten_r-P2"/>
      <site site="semiten_r_semiten_r-P3"/>
      <site site="semiten_r_semiten_r-P4"/>
      <site site="semiten_r_semiten_r-P5"/>
    </spatial>
    <spatial name="bifemlh_r_tendon">
      <site site="bifemlh_r_bifemlh_r-P1"/>
      <site site="bifemlh_r_bifemlh_r-P2"/>
      <site site="bifemlh_r_bifemlh_r-P3"/>
    </spatial>
    <spatial name="bifemsh_r_tendon">
      <site site="bifemsh_r_bifemsh_r-P1"/>
      <site site="bifemsh_r_bifemsh_r-P2"/>
      <site site="bifemsh_r_bifemsh_r-P3"/>
    </spatial>
    <spatial name="sar_r_tendon">
      <site site="sar_r_sar_r-P1"/>
      <site site="sar_r_sar_r-P2"/>
      <site site="sar_r_sar_r-P3"/>
      <site site="sar_r_sar_r-P4"/>
      <site site="sar_r_sar_r-P5"/>
    </spatial>
    <spatial name="add_long_r_tendon">
      <site site="add_long_r_add_long_r-P1"/>
      <site site="add_long_r_add_long_r-P2"/>
    </spatial>
    <spatial name="add_brev_r_tendon">
      <site site="add_brev_r_add_brev_r-P1"/>
      <site site="add_brev_r_add_brev_r-P2"/>
    </spatial>
    <spatial name="add_mag1_r_tendon">
      <site site="add_mag1_r_add_mag1_r-P1"/>
      <site site="add_mag1_r_add_mag1_r-P2"/>
    </spatial>
    <spatial name="add_mag2_r_tendon">
      <site site="add_mag2_r_add_mag2_r-P1"/>
      <site site="add_mag2_r_add_mag2_r-P2"/>
    </spatial>
    <spatial name="add_mag3_r_tendon">
      <site site="add_mag3_r_add_mag3_r-P1"/>
      <site site="add_mag3_r_add_mag3_r-P2"/>
    </spatial>
    <spatial name="tfl_r_tendon">
      <site site="tfl_r_tfl_r-P1"/>
      <site site="tfl_r_tfl_r-P2"/>
      <site site="tfl_r_tfl_r-P3"/>
      <site site="tfl_r_tfl_r-P4"/>
    </spatial>
    <spatial name="pect_r_tendon">
      <site site="pect_r_pect_r-P1"/>
      <site site="pect_r_pect_r-P2"/>
    </spatial>
    <spatial name="grac_r_tendon">
      <site site="grac_r_grac_r-P1"/>
      <site site="grac_r_grac_r-P2"/>
      <site site="grac_r_grac_r-P3"/>
      <site site="grac_r_grac_r-P4"/>
    </spatial>
    <spatial name="glut_max1_r_tendon">
      <site site="glut_max1_r_glut_max1_r-P1"/>
      <site site="glut_max1_r_glut_max1_r-P2"/>
      <site site="glut_max1_r_glut_max1_r-P3"/>
      <site site="glut_max1_r_glut_max1_r-P4"/>
    </spatial>
    <spatial name="glut_max2_r_tendon">
      <site site="glut_max2_r_glut_max2_r-P1"/>
      <site site="glut_max2_r_glut_max2_r-P2"/>
      <site site="glut_max2_r_glut_max2_r-P3"/>
      <site site="glut_max2_r_glut_max2_r-P4"/>
    </spatial>
    <spatial name="glut_max3_r_tendon">
      <site site="glut_max3_r_glut_max3_r-P1"/>
      <site site="glut_max3_r_glut_max3_r-P2"/>
      <site site="glut_max3_r_glut_max3_r-P3"/>
      <site site="glut_max3_r_glut_max3_r-P4"/>
    </spatial>
    <spatial name="iliacus_r_tendon">
      <site site="iliacus_r_iliacus_r-P1"/>
      <site site="iliacus_r_iliacus_r-P2"/>
      <site site="iliacus_r_iliacus_r-P3"/>
      <site site="iliacus_r_iliacus_r-P4"/>
      <site site="iliacus_r_iliacus_r-P5"/>
    </spatial>
    <spatial name="psoas_r_tendon">
      <site site="psoas_r_psoas_r-P1"/>
      <site site="psoas_r_psoas_r-P2"/>
      <site site="psoas_r_psoas_r-P3"/>
      <site site="psoas_r_psoas_r-P4"/>
      <site site="psoas_r_psoas_r-P5"/>
    </spatial>
    <spatial name="quad_fem_r_tendon">
      <site site="quad_fem_r_quad_fem_r-P1"/>
      <site site="quad_fem_r_quad_fem_r-P2"/>
    </spatial>
    <spatial name="gem_r_tendon">
      <site site="gem_r_gem_r-P1"/>
      <site site="gem_r_gem_r-P2"/>
    </spatial>
    <spatial name="peri_r_tendon">
      <site site="peri_r_peri_r-P1"/>
      <site site="peri_r_peri_r-P2"/>
      <site site="peri_r_peri_r-P3"/>
    </spatial>
    <spatial name="rect_fem_r_tendon">
      <site site="rect_fem_r_rect_fem_r-P1"/>
      <site site="rect_fem_r_rect_fem_r-P2"/>
      <site site="rect_fem_r_rect_fem_r-P3"/>
    </spatial>
    <spatial name="vas_int_r_tendon">
      <site site="vas_int_r_vas_int_r-P1"/>
      <site site="vas_int_r_vas_int_r-P2"/>
      <site site="vas_int_r_vas_int_r-P3"/>
      <site site="vas_int_r_vas_int_r-P4"/>
    </spatial>
    <spatial name="vas_lat_r_tendon">
      <site site="vas_lat_r_vas_lat_r-P1"/>
      <site site="vas_lat_r_vas_lat_r-P2"/>
      <site site="vas_lat_r_vas_lat_r-P3"/>
      <site site="vas_lat_r_vas_lat_r-P4"/>
      <site site="vas_lat_r_vas_lat_r-P5"/>
    </spatial>
    <spatial name="med_gas_r_tendon">
      <site site="med_gas_r_med_gas_r-P1"/>
      <site site="med_gas_r_med_gas_r-P2"/>
      <site site="med_gas_r_med_gas_r-P3"/>
    </spatial>
    <spatial name="lat_gas_r_tendon">
      <site site="lat_gas_r_lat_gas_r-P1"/>
      <site site="lat_gas_r_lat_gas_r-P2"/>
      <site site="lat_gas_r_lat_gas_r-P3"/>
    </spatial>
    <spatial name="soleus_r_tendon">
      <site site="soleus_r_soleus_r-P1"/>
      <site site="soleus_r_soleus_r-P2"/>
    </spatial>
    <spatial name="tib_post_r_tendon">
      <site site="tib_post_r_tib_post_r-P1"/>
      <site site="tib_post_r_tib_post_r-P2"/>
      <site site="tib_post_r_tib_post_r-P3"/>
      <site site="tib_post_r_tib_post_r-P4"/>
    </spatial>
    <spatial name="flex_dig_r_tendon">
      <site site="flex_dig_r_flex_dig_r-P1"/>
      <site site="flex_dig_r_flex_dig_r-P2"/>
      <site site="flex_dig_r_flex_dig_r-P3"/>
      <site site="flex_dig_r_flex_dig_r-P4"/>
      <site site="flex_dig_r_flex_dig_r-P5"/>
      <site site="flex_dig_r_flex_dig_r-P6"/>
      <site site="flex_dig_r_flex_dig_r-P7"/>
      <site site="flex_dig_r_flex_dig_r-P8"/>
    </spatial>
    <spatial name="flex_hal_r_tendon">
      <site site="flex_hal_r_flex_hal_r-P1"/>
      <site site="flex_hal_r_flex_hal_r-P2"/>
      <site site="flex_hal_r_flex_hal_r-P3"/>
      <site site="flex_hal_r_flex_hal_r-P4"/>
      <site site="flex_hal_r_flex_hal_r-P5"/>
      <site site="flex_hal_r_flex_hal_r-P6"/>
      <site site="flex_hal_r_flex_hal_r-P7"/>
    </spatial>
    <spatial name="tib_ant_r_tendon">
      <site site="tib_ant_r_tib_ant_r-P1"/>
      <site site="tib_ant_r_tib_ant_r-P2"/>
      <site site="tib_ant_r_tib_ant_r-P3"/>
    </spatial>
    <spatial name="per_brev_r_tendon">
      <site site="per_brev_r_per_brev_r-P1"/>
      <site site="per_brev_r_per_brev_r-P2"/>
      <site site="per_brev_r_per_brev_r-P3"/>
      <site site="per_brev_r_per_brev_r-P4"/>
      <site site="per_brev_r_per_brev_r-P5"/>
    </spatial>
    <spatial name="per_long_r_tendon">
      <site site="per_long_r_per_long_r-P1"/>
      <site site="per_long_r_per_long_r-P2"/>
      <site site="per_long_r_per_long_r-P3"/>
      <site site="per_long_r_per_long_r-P4"/>
      <site site="per_long_r_per_long_r-P5"/>
      <site site="per_long_r_per_long_r-P6"/>
      <site site="per_long_r_per_long_r-P7"/>
    </spatial>
    <spatial name="per_tert_r_tendon">
      <site site="per_tert_r_per_tert_r-P1"/>
      <site site="per_tert_r_per_tert_r-P2"/>
      <site site="per_tert_r_per_tert_r-P3"/>
    </spatial>
    <spatial name="ext_dig_r_tendon">
      <site site="ext_dig_r_ext_dig_r-P1"/>
      <site site="ext_dig_r_ext_dig_r-P2"/>
      <site site="ext_dig_r_ext_dig_r-P3"/>
      <site site="ext_dig_r_ext_dig_r-P4"/>
      <site site="ext_dig_r_ext_dig_r-P5"/>
      <site site="ext_dig_r_ext_dig_r-P6"/>
    </spatial>
    <spatial name="ext_hal_r_tendon">
      <site site="ext_hal_r_ext_hal_r-P1"/>
      <site site="ext_hal_r_ext_hal_r-P2"/>
      <site site="ext_hal_r_ext_hal_r-P3"/>
      <site site="ext_hal_r_ext_hal_r-P4"/>
      <site site="ext_hal_r_ext_hal_r-P5"/>
      <site site="ext_hal_r_ext_hal_r-P6"/>
      <site site="ext_hal_r_ext_hal_r-P7"/>
    </spatial>
    <spatial name="glut_med1_l_tendon">
      <site site="glut_med1_l_glut_med1_l-P1"/>
      <site site="glut_med1_l_glut_med1_l-P2"/>
    </spatial>
    <spatial name="glut_med2_l_tendon">
      <site site="glut_med2_l_glut_med2_l-P1"/>
      <site site="glut_med2_l_glut_med2_l-P2"/>
    </spatial>
    <spatial name="glut_med3_l_tendon">
      <site site="glut_med3_l_glut_med3_l-P1"/>
      <site site="glut_med3_l_glut_med3_l-P2"/>
    </spatial>
    <spatial name="glut_min1_l_tendon">
      <site site="glut_min1_l_glut_min1_l-P1"/>
      <site site="glut_min1_l_glut_min1_l-P2"/>
    </spatial>
    <spatial name="glut_min2_l_tendon">
      <site site="glut_min2_l_glut_min2_l-P1"/>
      <site site="glut_min2_l_glut_min2_l-P2"/>
    </spatial>
    <spatial name="glut_min3_l_tendon">
      <site site="glut_min3_l_glut_min3_l-P1"/>
      <site site="glut_min3_l_glut_min3_l-P2"/>
    </spatial>
    <spatial name="semimem_l_tendon">
      <site site="semimem_l_semimem_l-P1"/>
      <site site="semimem_l_semimem_l-P2"/>
      <site site="semimem_l_semimem_l-P3"/>
    </spatial>
    <spatial name="semiten_l_tendon">
      <site site="semiten_l_semiten_l-P1"/>
      <site site="semiten_l_semiten_l-P2"/>
      <site site="semiten_l_semiten_l-P3"/>
      <site site="semiten_l_semiten_l-P4"/>
      <site site="semiten_l_semiten_l-P5"/>
    </spatial>
    <spatial name="bifemlh_l_tendon">
      <site site="bifemlh_l_bifemlh_l-P1"/>
      <site site="bifemlh_l_bifemlh_l-P2"/>
      <site site="bifemlh_l_bifemlh_l-P3"/>
    </spatial>
    <spatial name="bifemsh_l_tendon">
      <site site="bifemsh_l_bifemsh_l-P1"/>
      <site site="bifemsh_l_bifemsh_l-P2"/>
      <site site="bifemsh_l_bifemsh_l-P3"/>
    </spatial>
    <spatial name="sar_l_tendon">
      <site site="sar_l_sar_l-P1"/>
      <site site="sar_l_sar_l-P2"/>
      <site site="sar_l_sar_l-P3"/>
      <site site="sar_l_sar_l-P4"/>
      <site site="sar_l_sar_l-P5"/>
    </spatial>
    <spatial name="add_long_l_tendon">
      <site site="add_long_l_add_long_l-P1"/>
      <site site="add_long_l_add_long_l-P2"/>
    </spatial>
    <spatial name="add_brev_l_tendon">
      <site site="add_brev_l_add_brev_l-P1"/>
      <site site="add_brev_l_add_brev_l-P2"/>
    </spatial>
    <spatial name="add_mag1_l_tendon">
      <site site="add_mag1_l_add_mag1_l-P1"/>
      <site site="add_mag1_l_add_mag1_l-P2"/>
    </spatial>
    <spatial name="add_mag2_l_tendon">
      <site site="add_mag2_l_add_mag2_l-P1"/>
      <site site="add_mag2_l_add_mag2_l-P2"/>
    </spatial>
    <spatial name="add_mag3_l_tendon">
      <site site="add_mag3_l_add_mag3_l-P1"/>
      <site site="add_mag3_l_add_mag3_l-P2"/>
    </spatial>
    <spatial name="pect_l_tendon">
      <site site="pect_l_pect_l-P1"/>
      <site site="pect_l_pect_l-P2"/>
    </spatial>
    <spatial name="glut_max1_l_tendon">
      <site site="glut_max1_l_glut_max1_l-P1"/>
      <site site="glut_max1_l_glut_max1_l-P2"/>
      <site site="glut_max1_l_glut_max1_l-P3"/>
      <site site="glut_max1_l_glut_max1_l-P4"/>
    </spatial>
    <spatial name="glut_max2_l_tendon">
      <site site="glut_max2_l_glut_max2_l-P1"/>
      <site site="glut_max2_l_glut_max2_l-P2"/>
      <site site="glut_max2_l_glut_max2_l-P3"/>
      <site site="glut_max2_l_glut_max2_l-P4"/>
    </spatial>
    <spatial name="glut_max3_l_tendon">
      <site site="glut_max3_l_glut_max3_l-P1"/>
      <site site="glut_max3_l_glut_max3_l-P2"/>
      <site site="glut_max3_l_glut_max3_l-P3"/>
      <site site="glut_max3_l_glut_max3_l-P4"/>
    </spatial>
    <spatial name="iliacus_l_tendon">
      <site site="iliacus_l_iliacus_l-P1"/>
      <site site="iliacus_l_iliacus_l-P2"/>
      <site site="iliacus_l_iliacus_l-P3"/>
      <site site="iliacus_l_iliacus_l-P4"/>
      <site site="iliacus_l_iliacus_l-P5"/>
    </spatial>
    <spatial name="psoas_l_tendon">
      <site site="psoas_l_psoas_l-P1"/>
      <site site="psoas_l_psoas_l-P2"/>
      <site site="psoas_l_psoas_l-P3"/>
      <site site="psoas_l_psoas_l-P4"/>
      <site site="psoas_l_psoas_l-P5"/>
    </spatial>
    <spatial name="quad_fem_l_tendon">
      <site site="quad_fem_l_quad_fem_l-P1"/>
      <site site="quad_fem_l_quad_fem_l-P2"/>
    </spatial>
    <spatial name="gem_l_tendon">
      <site site="gem_l_gem_l-P1"/>
      <site site="gem_l_gem_l-P2"/>
    </spatial>
    <spatial name="peri_l_tendon">
      <site site="peri_l_peri_l-P1"/>
      <site site="peri_l_peri_l-P2"/>
      <site site="peri_l_peri_l-P3"/>
    </spatial>
    <spatial name="rect_fem_l_tendon">
      <site site="rect_fem_l_rect_fem_l-P1"/>
      <site site="rect_fem_l_rect_fem_l-P2"/>
      <site site="rect_fem_l_rect_fem_l-P3"/>
    </spatial>
    <spatial name="vas_int_l_tendon">
      <site site="vas_int_l_vas_int_l-P1"/>
      <site site="vas_int_l_vas_int_l-P2"/>
      <site site="vas_int_l_vas_int_l-P3"/>
      <site site="vas_int_l_vas_int_l-P4"/>
    </spatial>
    <spatial name="vas_lat_l_tendon">
      <site site="vas_lat_l_vas_lat_l-P1"/>
      <site site="vas_lat_l_vas_lat_l-P2"/>
      <site site="vas_lat_l_vas_lat_l-P3"/>
      <site site="vas_lat_l_vas_lat_l-P4"/>
      <site site="vas_lat_l_vas_lat_l-P5"/>
    </spatial>
    <spatial name="ercspn_r_tendon">
      <site site="ercspn_r_ercspn_r-P1"/>
      <site site="ercspn_r_ercspn_r-P2"/>
    </spatial>
    <spatial name="ercspn_l_tendon">
      <site site="ercspn_l_ercspn_l-P1"/>
      <site site="ercspn_l_ercspn_l-P2"/>
    </spatial>
    <spatial name="intobl_r_tendon">
      <site site="intobl_r_intobl_r-P1"/>
      <site site="intobl_r_intobl_r-P2"/>
    </spatial>
    <spatial name="intobl_l_tendon">
      <site site="intobl_l_intobl_l-P1"/>
      <site site="intobl_l_intobl_l-P2"/>
    </spatial>
    <spatial name="extobl_r_tendon">
      <site site="extobl_r_extobl_r-P1"/>
      <site site="extobl_r_extobl_r-P2"/>
    </spatial>
    <spatial name="extobl_l_tendon">
      <site site="extobl_l_extobl_l-P1"/>
      <site site="extobl_l_extobl_l-P2"/>
    </spatial>
  </tendon>
  <actuator>
    <!-- Leave this comment here to make 'actuator' element pretty printed !-->
    <muscle name="glut_med1_r" lengthrange="0.01 1" force="819" tendon="glut_med1_r_tendon" class="muscle" timeconst="0.01 0.04"/>
    <muscle name="glut_med2_r" lengthrange="0.01 1" force="573" tendon="glut_med2_r_tendon" class="muscle" timeconst="0.01 0.04"/>
    <muscle name="glut_med3_r" lengthrange="0.01 1" force="653" tendon="glut_med3_r_tendon" class="muscle" timeconst="0.01 0.04"/>
    <muscle name="glut_min1_r" lengthrange="0.01 1" force="270" tendon="glut_min1_r_tendon" class="muscle" timeconst="0.01 0.04"/>
    <muscle name="glut_min2_r" lengthrange="0.01 1" force="285" tendon="glut_min2_r_tendon" class="muscle" timeconst="0.01 0.04"/>
    <muscle name="glut_min3_r" lengthrange="0.01 1" force="323" tendon="glut_min3_r_tendon" class="muscle" timeconst="0.01 0.04"/>
    <muscle name="semimem_r" lengthrange="0.01 1" force="1288" tendon="semimem_r_tendon" class="muscle" timeconst="0.01 0.04"/>
    <muscle name="semiten_r" lengthrange="0.01 1" force="410" tendon="semiten_r_tendon" class="muscle" timeconst="0.01 0.04"/>
    <muscle name="bifemlh_r" lengthrange="0.01 1" force="896" tendon="bifemlh_r_tendon" class="muscle" timeconst="0.01 0.04"/>
    <muscle name="bifemsh_r" lengthrange="0.01 1" force="804" tendon="bifemsh_r_tendon" class="muscle" timeconst="0.01 0.04"/>
    <muscle name="sar_r" lengthrange="0.01 1" force="156" tendon="sar_r_tendon" class="muscle" timeconst="0.01 0.04"/>
    <muscle name="add_long_r" lengthrange="0.01 1" force="627" tendon="add_long_r_tendon" class="muscle" timeconst="0.01 0.04"/>
    <muscle name="add_brev_r" lengthrange="0.01 1" force="429" tendon="add_brev_r_tendon" class="muscle" timeconst="0.01 0.04"/>
    <muscle name="add_mag1_r" lengthrange="0.01 1" force="381" tendon="add_mag1_r_tendon" class="muscle" timeconst="0.01 0.04"/>
    <muscle name="add_mag2_r" lengthrange="0.01 1" force="343" tendon="add_mag2_r_tendon" class="muscle" timeconst="0.01 0.04"/>
    <muscle name="add_mag3_r" lengthrange="0.01 1" force="488" tendon="add_mag3_r_tendon" class="muscle" timeconst="0.01 0.04"/>
    <muscle name="tfl_r" lengthrange="0.01 1" force="233" tendon="tfl_r_tendon" class="muscle" timeconst="0.01 0.04"/>
    <muscle name="pect_r" lengthrange="0.01 1" force="266" tendon="pect_r_tendon" class="muscle" timeconst="0.01 0.04"/>
    <muscle name="grac_r" lengthrange="0.01 1" force="162" tendon="grac_r_tendon" class="muscle" timeconst="0.01 0.04"/>
    <muscle name="glut_max1_r" lengthrange="0.01 1" force="573" tendon="glut_max1_r_tendon" class="muscle" timeconst="0.01 0.04"/>
    <muscle name="glut_max2_r" lengthrange="0.01 1" force="819" tendon="glut_max2_r_tendon" class="muscle" timeconst="0.01 0.04"/>
    <muscle name="glut_max3_r" lengthrange="0.01 1" force="552" tendon="glut_max3_r_tendon" class="muscle" timeconst="0.01 0.04"/>
    <muscle name="iliacus_r" lengthrange="0.01 1" force="1073" tendon="iliacus_r_tendon" class="muscle" timeconst="0.01 0.04"/>
    <muscle name="psoas_r" lengthrange="0.01 1" force="1113" tendon="psoas_r_tendon" class="muscle" timeconst="0.01 0.04"/>
    <muscle name="quad_fem_r" lengthrange="0.01 1" force="381" tendon="quad_fem_r_tendon" class="muscle" timeconst="0.01 0.04"/>
    <muscle name="gem_r" lengthrange="0.01 1" force="164" tendon="gem_r_tendon" class="muscle" timeconst="0.01 0.04"/>
    <muscle name="peri_r" lengthrange="0.01 1" force="444" tendon="peri_r_tendon" class="muscle" timeconst="0.01 0.04"/>
    <muscle name="rect_fem_r" lengthrange="0.01 1" force="1169" tendon="rect_fem_r_tendon" class="muscle" timeconst="0.01 0.04"/>
    <muscle name="vas_int_r" lengthrange="0.01 1" force="1365" tendon="vas_int_r_tendon" class="muscle" timeconst="0.01 0.04"/>
    <muscle name="vas_lat_r" lengthrange="0.01 1" force="1871" tendon="vas_lat_r_tendon" class="muscle" timeconst="0.01 0.04"/>
    <muscle name="med_gas_r" lengthrange="0.01 1" force="1558" tendon="med_gas_r_tendon" class="muscle" timeconst="0.01 0.04"/>
    <muscle name="lat_gas_r" lengthrange="0.01 1" force="683" tendon="lat_gas_r_tendon" class="muscle" timeconst="0.01 0.04"/>
    <muscle name="soleus_r" lengthrange="0.01 1" force="3549" tendon="soleus_r_tendon" class="muscle" timeconst="0.01 0.04"/>
    <muscle name="tib_post_r" lengthrange="0.01 1" force="1588" tendon="tib_post_r_tendon" class="muscle" timeconst="0.01 0.04"/>
    <muscle name="flex_dig_r" lengthrange="0.01 1" force="310" tendon="flex_dig_r_tendon" class="muscle" timeconst="0.01 0.04"/>
    <muscle name="flex_hal_r" lengthrange="0.01 1" force="322" tendon="flex_hal_r_tendon" class="muscle" timeconst="0.01 0.04"/>
    <muscle name="tib_ant_r" lengthrange="0.01 1" force="905" tendon="tib_ant_r_tendon" class="muscle" timeconst="0.01 0.04"/>
    <muscle name="per_brev_r" lengthrange="0.01 1" force="435" tendon="per_brev_r_tendon" class="muscle" timeconst="0.01 0.04"/>
    <muscle name="per_long_r" lengthrange="0.01 1" force="943" tendon="per_long_r_tendon" class="muscle" timeconst="0.01 0.04"/>
    <muscle name="per_tert_r" lengthrange="0.01 1" force="180" tendon="per_tert_r_tendon" class="muscle" timeconst="0.01 0.04"/>
    <muscle name="ext_dig_r" lengthrange="0.01 1" force="512" tendon="ext_dig_r_tendon" class="muscle" timeconst="0.01 0.04"/>
    <muscle name="ext_hal_r" lengthrange="0.01 1" force="162" tendon="ext_hal_r_tendon" class="muscle" timeconst="0.01 0.04"/>
    <muscle name="glut_med1_l" lengthrange="0.01 1" force="819" tendon="glut_med1_l_tendon" class="muscle" timeconst="0.01 0.04"/>
    <muscle name="glut_med2_l" lengthrange="0.01 1" force="573" tendon="glut_med2_l_tendon" class="muscle" timeconst="0.01 0.04"/>
    <muscle name="glut_med3_l" lengthrange="0.01 1" force="653" tendon="glut_med3_l_tendon" class="muscle" timeconst="0.01 0.04"/>
    <muscle name="glut_min1_l" lengthrange="0.01 1" force="270" tendon="glut_min1_l_tendon" class="muscle" timeconst="0.01 0.04"/>
    <muscle name="glut_min2_l" lengthrange="0.01 1" force="285" tendon="glut_min2_l_tendon" class="muscle" timeconst="0.01 0.04"/>
    <muscle name="glut_min3_l" lengthrange="0.01 1" force="323" tendon="glut_min3_l_tendon" class="muscle" timeconst="0.01 0.04"/>
    <muscle name="semimem_l" lengthrange="0.01 1" force="1288" tendon="semimem_l_tendon" class="muscle" timeconst="0.01 0.04"/>
    <muscle name="semiten_l" lengthrange="0.01 1" force="410" tendon="semiten_l_tendon" class="muscle" timeconst="0.01 0.04"/>
    <muscle name="bifemlh_l" lengthrange="0.01 1" force="896" tendon="bifemlh_l_tendon" class="muscle" timeconst="0.01 0.04"/>
    <muscle name="bifemsh_l" lengthrange="0.01 1" force="804" tendon="bifemsh_l_tendon" class="muscle" timeconst="0.01 0.04"/>
    <muscle name="sar_l" lengthrange="0.01 1" force="156" tendon="sar_l_tendon" class="muscle" timeconst="0.01 0.04"/>
    <muscle name="add_long_l" lengthrange="0.01 1" force="627" tendon="add_long_l_tendon" class="muscle" timeconst="0.01 0.04"/>
    <muscle name="add_brev_l" lengthrange="0.01 1" force="429" tendon="add_brev_l_tendon" class="muscle" timeconst="0.01 0.04"/>
    <muscle name="add_mag1_l" lengthrange="0.01 1" force="381" tendon="add_mag1_l_tendon" class="muscle" timeconst="0.01 0.04"/>
    <muscle name="add_mag2_l" lengthrange="0.01 1" force="343" tendon="add_mag2_l_tendon" class="muscle" timeconst="0.01 0.04"/>
    <muscle name="add_mag3_l" lengthrange="0.01 1" force="488" tendon="add_mag3_l_tendon" class="muscle" timeconst="0.01 0.04"/>
    <muscle name="pect_l" lengthrange="0.01 1" force="266" tendon="pect_l_tendon" class="muscle" timeconst="0.01 0.04"/>
    <muscle name="glut_max1_l" lengthrange="0.01 1" force="573" tendon="glut_max1_l_tendon" class="muscle" timeconst="0.01 0.04"/>
    <muscle name="glut_max2_l" lengthrange="0.01 1" force="819" tendon="glut_max2_l_tendon" class="muscle" timeconst="0.01 0.04"/>
    <muscle name="glut_max3_l" lengthrange="0.01 1" force="552" tendon="glut_max3_l_tendon" class="muscle" timeconst="0.01 0.04"/>
    <muscle name="iliacus_l" lengthrange="0.01 1" force="1073" tendon="iliacus_l_tendon" class="muscle" timeconst="0.01 0.04"/>
    <muscle name="psoas_l" lengthrange="0.01 1" force="1113" tendon="psoas_l_tendon" class="muscle" timeconst="0.01 0.04"/>
    <muscle name="quad_fem_l" lengthrange="0.01 1" force="381" tendon="quad_fem_l_tendon" class="muscle" timeconst="0.01 0.04"/>
    <muscle name="gem_l" lengthrange="0.01 1" force="164" tendon="gem_l_tendon" class="muscle" timeconst="0.01 0.04"/>
    <muscle name="peri_l" lengthrange="0.01 1" force="444" tendon="peri_l_tendon" class="muscle" timeconst="0.01 0.04"/>
    <muscle name="rect_fem_l" lengthrange="0.01 1" force="1169" tendon="rect_fem_l_tendon" class="muscle" timeconst="0.01 0.04"/>
    <muscle name="vas_int_l" lengthrange="0.01 1" force="1365" tendon="vas_int_l_tendon" class="muscle" timeconst="0.01 0.04"/>
    <muscle name="vas_lat_l" lengthrange="0.01 1" force="1871" tendon="vas_lat_l_tendon" class="muscle" timeconst="0.01 0.04"/>
    <muscle name="ercspn_r" lengthrange="0.01 1" force="2500" tendon="ercspn_r_tendon" class="muscle" timeconst="0.01 0.04"/>
    <muscle name="ercspn_l" lengthrange="0.01 1" force="2500" tendon="ercspn_l_tendon" class="muscle" timeconst="0.01 0.04"/>
    <muscle name="intobl_r" lengthrange="0.01 1" force="900" tendon="intobl_r_tendon" class="muscle" timeconst="0.01 0.04"/>
    <muscle name="intobl_l" lengthrange="0.01 1" force="900" tendon="intobl_l_tendon" class="muscle" timeconst="0.01 0.04"/>
    <muscle name="extobl_r" lengthrange="0.01 1" force="900" tendon="extobl_r_tendon" class="muscle" timeconst="0.01 0.04"/>
    <muscle name="extobl_l" lengthrange="0.01 1" force="900" tendon="extobl_l_tendon" class="muscle" timeconst="0.01 0.04"/>
  </actuator>
  <equality>
    <!-- Leave this comment here to make 'equality' element pretty printed !-->
    <joint joint1="knee_r_translation1" joint2="knee_angle_r" polycoef="-0.003639 -0.006267 0.002807 0.00134 -0.0006776" solimp="0.9999 0.9999 0.001 0.5 2" active="true"/>
    <joint joint1="knee_r_translation2" joint2="knee_angle_r" polycoef="-0.3957 0.003413 -0.005587 0.0006697 0.0005674" solimp="0.9999 0.9999 0.001 0.5 2" active="true"/>
    <joint joint1="knee_l_translation1" joint2="knee_angle_l" polycoef="-0.003639 -0.006267 0.002807 0.00134 -0.0006776" solimp="0.9999 0.9999 0.001 0.5 2" active="true"/>
    <joint joint1="knee_l_translation2" joint2="knee_angle_l" polycoef="-0.3957 0.003413 -0.005587 0.0006697 0.0005674" solimp="0.9999 0.9999 0.001 0.5 2" active="true"/>
    <joint joint1="semimem_r_semimem_r-P2_x" joint2="knee_angle_r" polycoef="-0.0342 -0.003438 0 0 0" solimp="0.9999 0.9999 0.001 0.5 2"/>
    <joint joint1="semimem_r_semimem_r-P2_y" joint2="knee_angle_r" polycoef="-0.03615 0.005519 0 0 0" solimp="0.9999 0.9999 0.001 0.5 2"/>
    <joint joint1="semiten_r_semiten_r-P2_x" joint2="knee_angle_r" polycoef="-0.04135 -0.003884 0 0 0" solimp="0.9999 0.9999 0.001 0.5 2"/>
    <joint joint1="semiten_r_semiten_r-P2_y" joint2="knee_angle_r" polycoef="-0.03045 0.01068 0 0 0" solimp="0.9999 0.9999 0.001 0.5 2"/>
    <joint joint1="grac_r_grac_r-P2_x" joint2="knee_angle_r" polycoef="-0.02602 -0.003147 0 0 0" solimp="0.9999 0.9999 0.001 0.5 2"/>
    <joint joint1="grac_r_grac_r-P2_y" joint2="knee_angle_r" polycoef="-0.03341 0.008653 0 0 0" solimp="0.9999 0.9999 0.001 0.5 2"/>
    <joint joint1="grac_r_grac_r-P2_z" joint2="knee_angle_r" polycoef="-0.03759 -0.0008552 0 0 0" solimp="0.9999 0.9999 0.001 0.5 2"/>
    <joint joint1="iliacus_r_iliacus_r-P3_x" joint2="hip_flexion_r" polycoef="-0.0288 1.757e-18 0.0006842 0 0" solimp="0.9999 0.9999 0.001 0.5 2"/>
    <joint joint1="iliacus_r_iliacus_r-P3_y" joint2="hip_flexion_r" polycoef="-0.0805 4.686e-18 0.005815 0 0" solimp="0.9999 0.9999 0.001 0.5 2"/>
    <joint joint1="psoas_r_psoas_r-P3_x" joint2="hip_flexion_r" polycoef="-0.0288 3.808e-18 0.00114 0 0" solimp="0.9999 0.9999 0.001 0.5 2"/>
    <joint joint1="psoas_r_psoas_r-P3_y" joint2="hip_flexion_r" polycoef="-0.0805 4.686e-18 0.005359 0 0" solimp="0.9999 0.9999 0.001 0.5 2"/>
    <joint joint1="psoas_r_psoas_r-P3_z" joint2="hip_flexion_r" polycoef="0.0816 -1.406e-17 -0.0013 0 0" solimp="0.9999 0.9999 0.001 0.5 2"/>
    <joint joint1="rect_fem_r_rect_fem_r-P3_x" joint2="knee_angle_r" polycoef="0.06259 0.04199 0.01152 -0.007248 -0.004008" solimp="0.9999 0.9999 0.001 0.5 2"/>
    <joint joint1="rect_fem_r_rect_fem_r-P3_y" joint2="knee_angle_r" polycoef="0.02032 -0.01159 -0.008624 -0.002308 -0.0002292" solimp="0.9999 0.9999 0.001 0.5 2"/>
    <joint joint1="vas_int_r_vas_int_r-P3_y" joint2="knee_angle_r" polycoef="-0.2234 0.08578 0 0 0" solimp="0.9999 0.9999 0.001 0.5 2"/>
    <joint joint1="vas_int_r_vas_int_r-P3_z" joint2="knee_angle_r" polycoef="0.02673 0.01014 0 0 0" solimp="0.9999 0.9999 0.001 0.5 2"/>
    <joint joint1="vas_int_r_vas_int_r-P4_x" joint2="knee_angle_r" polycoef="0.05647 0.04555 0.01393 -0.007247 -0.004235" solimp="0.9999 0.9999 0.001 0.5 2"/>
    <joint joint1="vas_int_r_vas_int_r-P4_y" joint2="knee_angle_r" polycoef="0.02476 -0.006322 -0.00661 -0.003684 -0.0008973" solimp="0.9999 0.9999 0.001 0.5 2"/>
    <joint joint1="vas_lat_r_vas_lat_r-P3_x" joint2="knee_angle_r" polycoef="0.02761 -0.004056 0 0 0" solimp="0.9999 0.9999 0.001 0.5 2"/>
    <joint joint1="vas_lat_r_vas_lat_r-P3_y" joint2="knee_angle_r" polycoef="-0.2702 0.06343 0 0 0" solimp="0.9999 0.9999 0.001 0.5 2"/>
    <joint joint1="vas_lat_r_vas_lat_r-P3_z" joint2="knee_angle_r" polycoef="0.03933 0.008993 0 0 0" solimp="0.9999 0.9999 0.001 0.5 2"/>
    <joint joint1="vas_lat_r_vas_lat_r-P4_x" joint2="knee_angle_r" polycoef="0.02678 0.0007053 0 0 0" solimp="0.9999 0.9999 0.001 0.5 2"/>
    <joint joint1="vas_lat_r_vas_lat_r-P4_y" joint2="knee_angle_r" polycoef="-0.2718 0.07282 0 0 0" solimp="0.9999 0.9999 0.001 0.5 2"/>
    <joint joint1="vas_lat_r_vas_lat_r-P4_z" joint2="knee_angle_r" polycoef="0.03917 0.009918 0 0 0" solimp="0.9999 0.9999 0.001 0.5 2"/>
    <joint joint1="vas_lat_r_vas_lat_r-P5_x" joint2="knee_angle_r" polycoef="0.06077 0.04082 0.01117 -0.006856 -0.003839" solimp="0.9999 0.9999 0.001 0.5 2"/>
    <joint joint1="vas_lat_r_vas_lat_r-P5_y" joint2="knee_angle_r" polycoef="0.01899 -0.01009 -0.007756 -0.002434 -0.0003548" solimp="0.9999 0.9999 0.001 0.5 2"/>
    <joint joint1="med_gas_r_med_gas_r-P2_x" joint2="knee_angle_r" polycoef="-0.02915 -0.004849 0 0 0" solimp="0.9999 0.9999 0.001 0.5 2"/>
    <joint joint1="med_gas_r_med_gas_r-P2_y" joint2="knee_angle_r" polycoef="-0.4015 -0.0041 0 0 0" solimp="0.9999 0.9999 0.001 0.5 2"/>
    <joint joint1="med_gas_r_med_gas_r-P2_z" joint2="knee_angle_r" polycoef="-0.02562 -0.001014 0 0 0" solimp="0.9999 0.9999 0.001 0.5 2"/>
    <joint joint1="lat_gas_r_lat_gas_r-P2_x" joint2="knee_angle_r" polycoef="-0.02938 -0.003527 0 0 0" solimp="0.9999 0.9999 0.001 0.5 2"/>
    <joint joint1="lat_gas_r_lat_gas_r-P2_y" joint2="knee_angle_r" polycoef="-0.4012 -0.003174 0 0 0" solimp="0.9999 0.9999 0.001 0.5 2"/>
    <joint joint1="semimem_l_semimem_l-P2_x" joint2="knee_angle_l" polycoef="-0.0342 -0.003438 0 0 0" solimp="0.9999 0.9999 0.001 0.5 2"/>
    <joint joint1="semimem_l_semimem_l-P2_y" joint2="knee_angle_l" polycoef="-0.03615 0.005519 0 0 0" solimp="0.9999 0.9999 0.001 0.5 2"/>
    <joint joint1="semiten_l_semiten_l-P2_x" joint2="knee_angle_l" polycoef="-0.04135 -0.003884 0 0 0" solimp="0.9999 0.9999 0.001 0.5 2"/>
    <joint joint1="semiten_l_semiten_l-P2_y" joint2="knee_angle_l" polycoef="-0.03045 0.01068 0 0 0" solimp="0.9999 0.9999 0.001 0.5 2"/>
    <joint joint1="iliacus_l_iliacus_l-P3_x" joint2="hip_flexion_l" polycoef="-0.0288 1.757e-18 0.0006842 0 0" solimp="0.9999 0.9999 0.001 0.5 2"/>
    <joint joint1="iliacus_l_iliacus_l-P3_y" joint2="hip_flexion_l" polycoef="-0.0805 4.686e-18 0.005815 0 0" solimp="0.9999 0.9999 0.001 0.5 2"/>
    <joint joint1="psoas_l_psoas_l-P3_x" joint2="hip_flexion_l" polycoef="-0.0288 3.808e-18 0.00114 0 0" solimp="0.9999 0.9999 0.001 0.5 2"/>
    <joint joint1="psoas_l_psoas_l-P3_y" joint2="hip_flexion_l" polycoef="-0.0805 4.686e-18 0.005359 0 0" solimp="0.9999 0.9999 0.001 0.5 2"/>
    <joint joint1="psoas_l_psoas_l-P3_z" joint2="hip_flexion_l" polycoef="-0.0816 1.406e-17 0.0013 0 0" solimp="0.9999 0.9999 0.001 0.5 2"/>
    <joint joint1="rect_fem_l_rect_fem_l-P3_x" joint2="knee_angle_l" polycoef="0.06259 0.04199 0.01152 -0.007248 -0.004008" solimp="0.9999 0.9999 0.001 0.5 2"/>
    <joint joint1="rect_fem_l_rect_fem_l-P3_y" joint2="knee_angle_l" polycoef="0.02032 -0.01159 -0.008624 -0.002308 -0.0002292" solimp="0.9999 0.9999 0.001 0.5 2"/>
    <joint joint1="vas_int_l_vas_int_l-P3_y" joint2="knee_angle_l" polycoef="-0.2234 0.08578 0 0 0" solimp="0.9999 0.9999 0.001 0.5 2"/>
    <joint joint1="vas_int_l_vas_int_l-P3_z" joint2="knee_angle_l" polycoef="0.02673 0.01014 0 0 0" solimp="0.9999 0.9999 0.001 0.5 2"/>
    <joint joint1="vas_int_l_vas_int_l-P4_x" joint2="knee_angle_l" polycoef="0.05647 0.04555 0.01393 -0.007247 -0.004235" solimp="0.9999 0.9999 0.001 0.5 2"/>
    <joint joint1="vas_int_l_vas_int_l-P4_y" joint2="knee_angle_l" polycoef="0.02476 -0.006322 -0.00661 -0.003684 -0.0008973" solimp="0.9999 0.9999 0.001 0.5 2"/>
    <joint joint1="vas_lat_l_vas_lat_l-P3_x" joint2="knee_angle_l" polycoef="0.02761 -0.004056 0 0 0" solimp="0.9999 0.9999 0.001 0.5 2"/>
    <joint joint1="vas_lat_l_vas_lat_l-P3_y" joint2="knee_angle_l" polycoef="-0.2702 0.06343 0 0 0" solimp="0.9999 0.9999 0.001 0.5 2"/>
    <joint joint1="vas_lat_l_vas_lat_l-P3_z" joint2="knee_angle_l" polycoef="0.03933 0.008993 0 0 0" solimp="0.9999 0.9999 0.001 0.5 2"/>
    <joint joint1="vas_lat_l_vas_lat_l-P4_x" joint2="knee_angle_l" polycoef="0.02678 0.0007053 0 0 0" solimp="0.9999 0.9999 0.001 0.5 2"/>
    <joint joint1="vas_lat_l_vas_lat_l-P4_y" joint2="knee_angle_l" polycoef="-0.2718 0.07282 0 0 0" solimp="0.9999 0.9999 0.001 0.5 2"/>
    <joint joint1="vas_lat_l_vas_lat_l-P4_z" joint2="knee_angle_l" polycoef="0.03917 0.009918 0 0 0" solimp="0.9999 0.9999 0.001 0.5 2"/>
    <joint joint1="vas_lat_l_vas_lat_l-P5_x" joint2="knee_angle_l" polycoef="0.06077 0.04082 0.01117 -0.006856 -0.003839" solimp="0.9999 0.9999 0.001 0.5 2"/>
    <joint joint1="vas_lat_l_vas_lat_l-P5_y" joint2="knee_angle_l" polycoef="0.01899 -0.01009 -0.007756 -0.002434 -0.0003548" solimp="0.9999 0.9999 0.001 0.5 2"/>
  </equality>
  <contact>
    <!-- Leave this comment here to make 'contact' element pretty printed !-->
    <pair geom1="ground-plane" geom2="pelvis_geom_1"/>
    <pair geom1="ground-plane" geom2="pelvis_geom_2"/>
    <pair geom1="ground-plane" geom2="pelvis_geom_3"/>
    <pair geom1="ground-plane" geom2="femur_r_geom_1"/>
    <pair geom1="ground-plane" geom2="tibia_r_geom_1"/>
    <pair geom1="ground-plane" geom2="tibia_r_geom_2"/>
    <pair geom1="ground-plane" geom2="talus_r_geom_1"/>
    <pair geom1="ground-plane" geom2="calcn_r_geom_1"/>
    <pair geom1="ground-plane" geom2="toes_r_geom_1"/>
    <pair geom1="ground-plane" geom2="femur_l_geom_1"/>
    <pair geom1="ground-plane" geom2="tibia_l_geom_1"/>
    <pair geom1="ground-plane" geom2="tibia_l_geom_2"/>
    <pair geom1="ground-plane" geom2="AnkleAssembly_geom_1"/>
    <pair geom1="ground-plane" geom2="Foot_geom_1"/>
    <pair geom1="ground-plane" geom2="torso_geom_1"/>
    <pair geom1="ground-plane" geom2="torso_geom_2"/>
    <pair geom1="ground-plane" geom2="torso_geom_3"/>
    <pair geom1="ground-plane" geom2="torso_geom_4"/>
  </contact>
  <keyframe>
    <key name="default-pose" qpos="0 0.95 0 0 0 0 0 0 0 -0.003639 -0.3957 0 0 0 0 -0.0342 -0.03615 -0.04135 -0.03045 -0.02602 -0.03341 -0.03759 0.06259 0.02032 0.05647 0.02476 0.06077 0.01899 -0.2234 0.02673 0.02761 -0.2702 0.03933 0.02678 -0.2718 0.03917 -0.02915 -0.4015 -0.02562 -0.02938 -0.4012 0 0 0 -0.003639 -0.3957 0 -0 0 -0.0342 -0.03615 -0.04135 -0.03045 0.06259 0.02032 0.05647 0.02476 0.06077 0.01899 -0.2234 0.02673 0.02761 -0.2702 0.03933 0.02678 -0.2718 0.03917 0 0 0 -0.0288 -0.0805 -0.0288 -0.0805 0.0816 -0.0288 -0.0805 -0.0288 -0.0805 -0.0816"/>
  </keyframe>
</mujoco>
