<mujoco model="template">
  <!-- This model has been converted from an OpenSim model. Model conversion by MyoConverter https://github.com/MyoHub/myoconverter. This model is licensed under Apache 2.0. -->
  <compiler angle="radian" autolimits="true"/>
  <!--option timestep="0.005" collision="predefined"/-->
  <size njmax="1000" nconmax="400" nkey="1" nuser_jnt="1"/>
  <visual>
    <scale framelength="0.5" framewidth="0.01"/>
  </visual>
  <statistic meansize="0.295006" extent="2.54254" center="0.271269 0 0"/>
  <default class="main">
    <joint limited="true" armature="1e-05" damping="0.05"/>
    <geom margin="0.001" rgba="0.8 0.6 0.4 1"/>
    <site size="0.001 0.005 0.005"/>
    <tendon limited="false" width="0.005" rgba="0.95 0.3 0.3 1"/>
    <default class="muscle">
      <general ctrllimited="true" ctrlrange="0 1" dyntype="muscle" gaintype="muscle" biastype="muscle" dynprm="0.01 0.04 0 0 0 0 0 0 0 0" gainprm="0.75 1.05 -1 200 0.5 1.6 1.5 1.3 1.2 0" biasprm="0.75 1.05 -1 200 0.5 1.6 1.5 1.3 1.2 0"/>
    </default>
    <default class="motor">
      <general gainprm="5 0 0 0 0 0 0 0 0 0"/>
    </default>
  </default>
  <asset>
    <texture type="skybox" builtin="gradient" rgb1="1 1 1" rgb2="0.6 0.8 1" width="256" height="1536"/>
    <mesh name="pelvis_geom_1_sacrum" file="../meshes/sacrum.stl"/>
    <mesh name="pelvis_geom_2_pelvis" file="Geometry/pelvis.stl"/>
    <mesh name="pelvis_geom_3_l_pelvis" file="../meshes/l_pelvis.stl"/>
    <mesh name="femur_r_geom_1_femur_r" file="../meshes/r_femur.stl"/>
    <mesh name="tibia_r_geom_1_tibia_r" file="../meshes/r_tibia.stl"/>
    <mesh name="tibia_r_geom_2_fibula" file="../meshes/r_fibula.stl"/>
    <mesh name="talus_r_geom_1_talus" file="../meshes/r_talus.stl"/>
    <mesh name="calcn_r_geom_1_foot" file="../meshes/r_foot.stl"/>
    <mesh name="toes_r_geom_1_bofoot" file="../meshes/r_bofoot.stl"/>
    <mesh name="femur_l_geom_1_femur_l" file="../meshes/l_femur.stl"/>
    <mesh name="tibia_l_geom_1_tibia_l" file="../meshes/l_tibia.stl"/>
    <mesh name="tibia_l_geom_2_l_fibula" file="../meshes/l_fibula.stl"/>
    <mesh name="AnkleAssembly_geom_1_AnkleAssembly" file="Geometry/AnkleAssembly.stl"/>
    <mesh name="Foot_geom_1_Foot_Amp" file="Geometry/Foot_Amp.stl"/>
    <mesh name="torso_geom_1_hat_spine" file="../meshes/hat_spine.stl"/>
    <mesh name="torso_geom_2_hat_jaw" file="../meshes/hat_jaw.stl"/>
    <mesh name="torso_geom_3_hat_skull" file="../meshes/hat_skull.stl"/>
    <mesh name="torso_geom_4_hat_ribs" file="../meshes/hat_ribs_scap.stl"/>
  </asset>
  <worldbody>
    <light pos="0 0 0" dir="0 0 -1" directional="true"/>
    <body name="ground" quat="0.707035 0.707179 0 0">
      <geom name="ground-plane" size="10 10 0.125" quat="0.707035 -0.707179 0 0" type="plane" rgba="1 0.7 0.4 1"/>
    </body>
    <body name="pelvis" quat="0.707035 0.707179 0 0" pos="0 0 0.945">
      <inertial pos="-0.0707 0 0" mass="11.777" diaginertia="0.1028 0.0871 0.0579"/>
      <joint name="pelvis_tx" pos="0 0 0" axis="1 0 0" limited="false" type="slide" range="-5 5" damping="0"/>
      <joint name="pelvis_ty" pos="0 0 0" axis="0 1 0" limited="false" type="slide" range="-1 2" damping="0" user="0.95"/>
      <joint name="pelvis_tz" pos="0 0 0" axis="0 0 1" limited="false" type="slide" range="-3 3" damping="0"/>
      <joint name="pelvis_tilt" pos="0 0 0" axis="0 0 1" limited="false" range="-1.571 1.571" damping="0"/>
      <joint name="pelvis_list" pos="0 0 0" axis="1 0 0" limited="false" range="-1.571 1.571" damping="0"/>
      <joint name="pelvis_rotation" pos="0 0 0" axis="0 1 0" limited="false" range="-1.571 1.571" damping="0"/>
      <geom name="pelvis_geom_1" type="mesh" rgba="1 1 1 1" mesh="pelvis_geom_1_sacrum"/>
      <geom name="pelvis_geom_2" type="mesh" rgba="1 1 1 1" mesh="pelvis_geom_2_pelvis"/>
      <geom name="pelvis_geom_3" type="mesh" rgba="1 1 1 1" mesh="pelvis_geom_3_l_pelvis"/>
      <site name="glut_med1_r_glut_med1_r-P1" pos="-0.0408 0.0304 0.1209"/>
      <site name="glut_med2_r_glut_med2_r-P1" pos="-0.0855 0.0445 0.0766"/>
      <site name="glut_med3_r_glut_med3_r-P1" pos="-0.1223 0.0105 0.0648"/>
      <site name="glut_min1_r_glut_min1_r-P1" pos="-0.0467 -0.008 0.1056"/>
      <site name="glut_min2_r_glut_min2_r-P1" pos="-0.0633 -0.0065 0.0991"/>
      <site name="glut_min3_r_glut_min3_r-P1" pos="-0.0834 -0.0063 0.0856"/>
      <site name="semimem_r_semimem_r-P1" pos="-0.1192 -0.09747 0.07151"/>
      <site name="semiten_r_semiten_r-P1" pos="-0.12635 -0.10988 0.06039"/>
      <site name="bifemlh_r_bifemlh_r-P1" pos="-0.12596 -0.10257 0.06944"/>
      <site name="sar_r_sar_r-P1" pos="-0.0153 -0.0013 0.1242"/>
      <site name="add_long_r_add_long_r-P1" pos="-0.0316 -0.0836 0.0169"/>
      <site name="add_brev_r_add_brev_r-P1" pos="-0.0587 -0.0915 0.0164"/>
      <site name="add_mag1_r_add_mag1_r-P1" pos="-0.0732 -0.1174 0.0255"/>
      <site name="add_mag2_r_add_mag2_r-P1" pos="-0.0831 -0.1192 0.0308"/>
      <site name="add_mag3_r_add_mag3_r-P1" pos="-0.11108 -0.11413 0.04882"/>
      <site name="tfl_r_tfl_r-P1" pos="-0.0311 0.0214 0.1241"/>
      <site name="pect_r_pect_r-P1" pos="-0.0431 -0.0768 0.0451"/>
      <site name="grac_r_grac_r-P1" pos="-0.07401 -0.1187 0.02794"/>
      <site name="glut_max1_r_glut_max1_r-P1" pos="-0.1195 0.0612 0.07"/>
      <site name="glut_max1_r_glut_max1_r-P2" pos="-0.1291 0.0012 0.0886"/>
      <site name="glut_max2_r_glut_max2_r-P1" pos="-0.1349 0.0176 0.0563"/>
      <site name="glut_max2_r_glut_max2_r-P2" pos="-0.1376 -0.052 0.0914"/>
      <site name="glut_max3_r_glut_max3_r-P1" pos="-0.1556 -0.0314 0.0058"/>
      <site name="glut_max3_r_glut_max3_r-P2" pos="-0.1529 -0.1052 0.0403"/>
      <site name="iliacus_r_iliacus_r-P1" pos="-0.0674 0.0365 0.0854"/>
      <site name="iliacus_r_iliacus_r-P2" pos="-0.0258 -0.055 0.0811"/>
      <site name="iliacus_r_iliacus_r-P3" pos="-0.0288 -0.0805 0.0816"/>
      <site name="psoas_r_psoas_r-P1" pos="-0.0647 0.0887 0.0289"/>
      <site name="psoas_r_psoas_r-P2" pos="-0.0238 -0.057 0.0759"/>
      <site name="psoas_r_psoas_r-P3" pos="-0.0288 -0.0805 0.0816"/>
      <site name="quad_fem_r_quad_fem_r-P1" pos="-0.1143 -0.1151 0.052"/>
      <site name="gem_r_gem_r-P1" pos="-0.1133 -0.082 0.0714"/>
      <site name="peri_r_peri_r-P1" pos="-0.1396 0.0003 0.0235"/>
      <site name="peri_r_peri_r-P2" pos="-0.1193 -0.0276 0.0657"/>
      <site name="rect_fem_r_rect_fem_r-P1" pos="-0.0295 -0.0311 0.0968"/>
      <site name="glut_med1_l_glut_med1_l-P1" pos="-0.0408 0.0304 -0.1209"/>
      <site name="glut_med2_l_glut_med2_l-P1" pos="-0.0855 0.0445 -0.0766"/>
      <site name="glut_med3_l_glut_med3_l-P1" pos="-0.1223 0.0105 -0.0648"/>
      <site name="glut_min1_l_glut_min1_l-P1" pos="-0.0467 -0.008 -0.1056"/>
      <site name="glut_min2_l_glut_min2_l-P1" pos="-0.0633 -0.0065 -0.0991"/>
      <site name="glut_min3_l_glut_min3_l-P1" pos="-0.0834 -0.0063 -0.0856"/>
      <site name="semimem_l_semimem_l-P1" pos="-0.1192 -0.09747 -0.07151"/>
      <site name="semiten_l_semiten_l-P1" pos="-0.12635 -0.10988 -0.06039"/>
      <site name="bifemlh_l_bifemlh_l-P1" pos="-0.12596 -0.10257 -0.06944"/>
      <site name="sar_l_sar_l-P1" pos="-0.0153 -0.0013 -0.1242"/>
      <site name="add_long_l_add_long_l-P1" pos="-0.0316 -0.0836 -0.0169"/>
      <site name="add_brev_l_add_brev_l-P1" pos="-0.0587 -0.0915 -0.0164"/>
      <site name="add_mag1_l_add_mag1_l-P1" pos="-0.0732 -0.1174 -0.0255"/>
      <site name="add_mag2_l_add_mag2_l-P1" pos="-0.0831 -0.1192 -0.0308"/>
      <site name="add_mag3_l_add_mag3_l-P1" pos="-0.11108 -0.11413 -0.04882"/>
      <site name="pect_l_pect_l-P1" pos="-0.0431 -0.0768 -0.0451"/>
      <site name="glut_max1_l_glut_max1_l-P1" pos="-0.1195 0.0612 -0.07"/>
      <site name="glut_max1_l_glut_max1_l-P2" pos="-0.1291 0.0012 -0.0886"/>
      <site name="glut_max2_l_glut_max2_l-P1" pos="-0.1349 0.0176 -0.0563"/>
      <site name="glut_max2_l_glut_max2_l-P2" pos="-0.1376 -0.052 -0.0914"/>
      <site name="glut_max3_l_glut_max3_l-P1" pos="-0.1556 -0.0314 -0.0058"/>
      <site name="glut_max3_l_glut_max3_l-P2" pos="-0.1529 -0.1052 -0.0403"/>
      <site name="iliacus_l_iliacus_l-P1" pos="-0.0674 0.0365 -0.0854"/>
      <site name="iliacus_l_iliacus_l-P2" pos="-0.0258 -0.055 -0.0811"/>
      <site name="iliacus_l_iliacus_l-P3" pos="-0.0288 -0.0805 -0.0816"/>
      <site name="psoas_l_psoas_l-P1" pos="-0.0647 0.0887 -0.0289"/>
      <site name="psoas_l_psoas_l-P2" pos="-0.0238 -0.057 -0.0759"/>
      <site name="psoas_l_psoas_l-P3" pos="-0.0288 -0.0805 -0.0816"/>
      <site name="quad_fem_l_quad_fem_l-P1" pos="-0.1143 -0.1151 -0.052"/>
      <site name="gem_l_gem_l-P1" pos="-0.1133 -0.082 -0.0714"/>
      <site name="peri_l_peri_l-P1" pos="-0.1396 0.0003 -0.0235"/>
      <site name="peri_l_peri_l-P2" pos="-0.1193 -0.0276 -0.0657"/>
      <site name="rect_fem_l_rect_fem_l-P1" pos="-0.0295 -0.0311 0.0968"/>
      <site name="ercspn_r_ercspn_r-P1" pos="-0.14 0.0439 0.0436"/>
      <site name="ercspn_l_ercspn_l-P1" pos="-0.14 0.0439 -0.0436"/>
      <site name="intobl_r_intobl_r-P1" pos="-0.04 0.07 0.1157"/>
      <site name="intobl_l_intobl_l-P1" pos="-0.04 0.07 -0.1157"/>
      <site name="extobl_r_extobl_r-P1" pos="-0.03 -0.0636 0.01"/>
      <site name="extobl_l_extobl_l-P1" pos="-0.03 -0.0636 -0.01"/>
      <body name="femur_r" pos="-0.0707 -0.0661 0.0835">
        <inertial pos="0 -0.17 0" quat="0.5 0.5 -0.5 0.5" mass="9.3014" diaginertia="0.1412 0.1339 0.0351"/>
        <joint name="hip_flexion_r" pos="0 0 0" axis="0 0 1" range="-2.094 2.094"/>
        <joint name="hip_adduction_r" pos="0 0 0" axis="1 0 0" range="-2.094 2.094"/>
        <joint name="hip_rotation_r" pos="0 0 0" axis="0 1 0" range="-2.094 2.094"/>
        <geom name="femur_r_geom_1" type="mesh" rgba="1 1 1 1" mesh="femur_r_geom_1_femur_r"/>
        <site name="glut_med1_r_glut_med1_r-P2" pos="-0.0218 -0.0117 0.0555"/>
        <site name="glut_med2_r_glut_med2_r-P2" pos="-0.0258 -0.0058 0.0527"/>
        <site name="glut_med3_r_glut_med3_r-P2" pos="-0.0309 -0.0047 0.0518"/>
        <site name="glut_min1_r_glut_min1_r-P2" pos="-0.0072 -0.0104 0.056"/>
        <site name="glut_min2_r_glut_min2_r-P2" pos="-0.0096 -0.0104 0.056"/>
        <site name="glut_min3_r_glut_min3_r-P2" pos="-0.0135 -0.0083 0.055"/>
        <site name="bifemsh_r_bifemsh_r-P1" pos="0.005 -0.2111 0.0234"/>
        <site name="sar_r_sar_r-P2" pos="-0.003 -0.3568 -0.0421"/>
        <site name="add_long_r_add_long_r-P2" pos="0.005 -0.2111 0.0234"/>
        <site name="add_brev_r_add_brev_r-P2" pos="0.0009 -0.1196 0.0294"/>
        <site name="add_mag1_r_add_mag1_r-P2" pos="-0.0045 -0.1211 0.0339"/>
        <site name="add_mag2_r_add_mag2_r-P2" pos="0.0054 -0.2285 0.0227"/>
        <site name="add_mag3_r_add_mag3_r-P2" pos="0.007 -0.3837 -0.0266"/>
        <site name="tfl_r_tfl_r-P2" pos="0.0294 -0.0995 0.0597"/>
        <site name="tfl_r_tfl_r-P3" pos="0.0054 -0.4049 0.0357"/>
        <site name="pect_r_pect_r-P2" pos="-0.0122 -0.0822 0.0253"/>
        <site name="glut_max1_r_glut_max1_r-P3" pos="-0.0457 -0.0248 0.0392"/>
        <site name="glut_max1_r_glut_max1_r-P4" pos="-0.0277 -0.0566 0.047"/>
        <site name="glut_max2_r_glut_max2_r-P3" pos="-0.0426 -0.053 0.0293"/>
        <site name="glut_max2_r_glut_max2_r-P4" pos="-0.0156 -0.1016 0.0419"/>
        <site name="glut_max3_r_glut_max3_r-P3" pos="-0.0299 -0.1041 0.0135"/>
        <site name="glut_max3_r_glut_max3_r-P4" pos="-0.006 -0.1419 0.0411"/>
        <site name="iliacus_r_iliacus_r-P4" pos="0.0017 -0.0543 0.0057"/>
        <site name="iliacus_r_iliacus_r-P5" pos="-0.0193 -0.0621 0.0129"/>
        <site name="psoas_r_psoas_r-P4" pos="0.0016 -0.0507 0.0038"/>
        <site name="psoas_r_psoas_r-P5" pos="-0.0188 -0.0597 0.0104"/>
        <site name="quad_fem_r_quad_fem_r-P2" pos="-0.0381 -0.0359 0.0366"/>
        <site name="gem_r_gem_r-P2" pos="-0.0142 -0.0033 0.0443"/>
        <site name="peri_r_peri_r-P3" pos="-0.0148 -0.0036 0.0437"/>
        <site name="rect_fem_r_rect_fem_r-P2" pos="0.0334 -0.403 0.0019"/>
        <site name="vas_int_r_vas_int_r-P1" pos="0.029 -0.1924 0.031"/>
        <site name="vas_int_r_vas_int_r-P2" pos="0.0335 -0.2084 0.0285"/>
        <site name="vas_int_r_vas_int_r-P3" pos="0.0343 -0.403 0.0055"/>
        <site name="vas_lat_r_vas_lat_r-P1" pos="0.0048 -0.1854 0.0349"/>
        <site name="vas_lat_r_vas_lat_r-P2" pos="0.0269 -0.2591 0.0409"/>
        <site name="vas_lat_r_vas_lat_r-P3" pos="0.0361 -0.403 0.0205"/>
        <site name="vas_lat_r_vas_lat_r-P4" pos="0.0253 -0.4243 0.0184"/>
        <site name="med_gas_r_med_gas_r-P1" pos="-0.019 -0.3929 -0.0235"/>
        <site name="med_gas_r_med_gas_r-P2" pos="-0.03 -0.4022 -0.0258"/>
        <site name="lat_gas_r_lat_gas_r-P1" pos="-0.022 -0.3946 0.0272"/>
        <site name="lat_gas_r_lat_gas_r-P2" pos="-0.03 -0.4018 0.0274"/>
        <body name="tibia_r" pos="0 -0.3957 0">
          <inertial pos="0 -0.1867 0" quat="0.5 0.5 -0.5 0.5" mass="3.7075" diaginertia="0.0511 0.0504 0.0051"/>
          <joint name="knee_angle_r" pos="0 0 0" axis="0 0 1" range="-2.094 0.1745"/>
          <geom name="tibia_r_geom_1" type="mesh" rgba="1 1 1 1" mesh="tibia_r_geom_1_tibia_r"/>
          <geom name="tibia_r_geom_2" type="mesh" rgba="1 1 1 1" mesh="tibia_r_geom_2_fibula"/>
          <site name="semimem_r_semimem_r-P2" pos="-0.0348 -0.03519 -0.01891"/>
          <site name="semimem_r_semimem_r-P3" pos="-0.027 -0.04771 -0.01957"/>
          <site name="semiten_r_semiten_r-P2" pos="-0.04203 -0.02859 -0.02277"/>
          <site name="semiten_r_semiten_r-P3" pos="-0.03322 -0.05282 -0.02288"/>
          <site name="semiten_r_semiten_r-P4" pos="-0.0113 -0.0746 -0.0245"/>
          <site name="semiten_r_semiten_r-P5" pos="0.0027 -0.0956 -0.0193"/>
          <site name="bifemlh_r_bifemlh_r-P2" pos="-0.0301 -0.036 0.02943"/>
          <site name="bifemlh_r_bifemlh_r-P3" pos="-0.0234 -0.0563 0.0343"/>
          <site name="bifemsh_r_bifemsh_r-P2" pos="-0.0301 -0.036 0.02943"/>
          <site name="bifemsh_r_bifemsh_r-P3" pos="-0.0234 -0.0563 0.0343"/>
          <site name="sar_r_sar_r-P3" pos="-0.0056 -0.0419 -0.0399"/>
          <site name="sar_r_sar_r-P4" pos="0.006 -0.0589 -0.0383"/>
          <site name="sar_r_sar_r-P5" pos="0.0243 -0.084 -0.0252"/>
          <site name="tfl_r_tfl_r-P4" pos="0.006 -0.0487 0.0297"/>
          <site name="grac_r_grac_r-P2" pos="-0.02657 -0.0319 -0.03774"/>
          <site name="grac_r_grac_r-P3" pos="-0.01943 -0.05153 -0.0358"/>
          <site name="grac_r_grac_r-P4" pos="0.006 -0.0836 -0.0228"/>
          <site name="rect_fem_r_rect_fem_r-P3" pos="0.04444 -0.02103 0.0014"/>
          <site name="vas_int_r_vas_int_r-P4" pos="0.03836 -0.02053 0.001799"/>
          <site name="vas_lat_r_vas_lat_r-P5" pos="0.04274 -0.02095 0.0165"/>
          <site name="soleus_r_soleus_r-P1" pos="-0.0024 -0.1533 0.0071"/>
          <site name="tib_post_r_tib_post_r-P1" pos="-0.0094 -0.1348 0.0019"/>
          <site name="tib_post_r_tib_post_r-P2" pos="-0.0144 -0.4051 -0.0229"/>
          <site name="flex_dig_r_flex_dig_r-P1" pos="-0.0083 -0.2046 -0.0018"/>
          <site name="flex_dig_r_flex_dig_r-P2" pos="-0.0154 -0.4051 -0.0196"/>
          <site name="flex_hal_r_flex_hal_r-P1" pos="-0.0079 -0.2334 0.0244"/>
          <site name="flex_hal_r_flex_hal_r-P2" pos="-0.0186 -0.4079 -0.0174"/>
          <site name="tib_ant_r_tib_ant_r-P1" pos="0.0179 -0.1624 0.0115"/>
          <site name="tib_ant_r_tib_ant_r-P2" pos="0.0329 -0.3951 -0.0177"/>
          <site name="per_brev_r_per_brev_r-P1" pos="-0.007 -0.2646 0.0325"/>
          <site name="per_brev_r_per_brev_r-P2" pos="-0.0198 -0.4184 0.0283"/>
          <site name="per_brev_r_per_brev_r-P3" pos="-0.0144 -0.4295 0.0289"/>
          <site name="per_long_r_per_long_r-P1" pos="0.0005 -0.1568 0.0362"/>
          <site name="per_long_r_per_long_r-P2" pos="-0.0207 -0.4205 0.0286"/>
          <site name="per_long_r_per_long_r-P3" pos="-0.0162 -0.4319 0.0289"/>
          <site name="per_tert_r_per_tert_r-P1" pos="0.001 -0.2804 0.0231"/>
          <site name="per_tert_r_per_tert_r-P2" pos="0.0229 -0.4069 0.0159"/>
          <site name="ext_dig_r_ext_dig_r-P1" pos="0.0032 -0.1381 0.0276"/>
          <site name="ext_dig_r_ext_dig_r-P2" pos="0.0289 -0.4007 0.0072"/>
          <site name="ext_hal_r_ext_hal_r-P1" pos="0.0012 -0.1767 0.0228"/>
          <site name="ext_hal_r_ext_hal_r-P2" pos="0.0326 -0.3985 -0.0085"/>
          <body name="talus_r" pos="0 -0.43 0">
            <inertial pos="0 0 0" mass="0.1" diaginertia="0.001 0.001 0.001"/>
            <joint name="ankle_angle_r" pos="0 0 0" axis="-0.105003 -0.174005 0.979131" limited="false" range="-1.571 1.571"/>
            <geom name="talus_r_geom_1" type="mesh" rgba="1 1 1 1" mesh="talus_r_geom_1_talus"/>
            <body name="calcn_r" pos="-0.04877 -0.04195 0.00792">
              <inertial pos="0.1 0.03 0" quat="0 0.707107 0 0.707107" mass="1.25" diaginertia="0.0041 0.0039 0.0014"/>
              <joint name="subtalar_angle_r" pos="0 0 0" axis="0.787215 0.604711 -0.120902" limited="false" range="-1.571 1.571"/>
              <geom name="calcn_r_geom_1" type="mesh" rgba="1 1 1 1" mesh="calcn_r_geom_1_foot"/>
              <site name="med_gas_r_med_gas_r-P3" pos="0 0.031 -0.0053"/>
              <site name="lat_gas_r_lat_gas_r-P3" pos="0 0.031 -0.0053"/>
              <site name="soleus_r_soleus_r-P2" pos="0 0.031 -0.0053"/>
              <site name="tib_post_r_tib_post_r-P3" pos="0.0417 0.0334 -0.0286"/>
              <site name="tib_post_r_tib_post_r-P4" pos="0.0772 0.0159 -0.0281"/>
              <site name="flex_dig_r_flex_dig_r-P3" pos="0.0436 0.0315 -0.028"/>
              <site name="flex_dig_r_flex_dig_r-P4" pos="0.0708 0.0176 -0.0263"/>
              <site name="flex_dig_r_flex_dig_r-P5" pos="0.1658 -0.0081 0.0116"/>
              <site name="flex_hal_r_flex_hal_r-P3" pos="0.0374 0.0276 -0.0241"/>
              <site name="flex_hal_r_flex_hal_r-P4" pos="0.1038 0.0068 -0.0256"/>
              <site name="flex_hal_r_flex_hal_r-P5" pos="0.1726 -0.0053 -0.0269"/>
              <site name="tib_ant_r_tib_ant_r-P3" pos="0.1166 0.0178 -0.0305"/>
              <site name="per_brev_r_per_brev_r-P4" pos="0.0471 0.027 0.0233"/>
              <site name="per_brev_r_per_brev_r-P5" pos="0.0677 0.0219 0.0343"/>
              <site name="per_long_r_per_long_r-P4" pos="0.0438 0.023 0.0221"/>
              <site name="per_long_r_per_long_r-P5" pos="0.0681 0.0106 0.0284"/>
              <site name="per_long_r_per_long_r-P6" pos="0.0852 0.0069 0.0118"/>
              <site name="per_long_r_per_long_r-P7" pos="0.1203 0.0085 -0.0184"/>
              <site name="per_tert_r_per_tert_r-P3" pos="0.0857 0.0228 0.0299"/>
              <site name="ext_dig_r_ext_dig_r-P3" pos="0.0922 0.0388 -0.0001"/>
              <site name="ext_dig_r_ext_dig_r-P4" pos="0.1616 0.0055 0.013"/>
              <site name="ext_hal_r_ext_hal_r-P3" pos="0.097 0.0389 -0.0211"/>
              <site name="ext_hal_r_ext_hal_r-P4" pos="0.1293 0.0309 -0.0257"/>
              <site name="ext_hal_r_ext_hal_r-P5" pos="0.1734 0.0139 -0.028"/>
              <body name="toes_r" pos="0.1788 -0.002 0.00108">
                <inertial pos="0.0346 0.006 -0.0175" quat="0.707107 0 0 0.707107" mass="0.2166" diaginertia="0.001 0.001 0.001"/>
                <joint name="mtp_angle_r" pos="0 0 0" axis="-0.581002 0 0.813902" limited="false" range="-1.571 1.571"/>
                <geom name="toes_r_geom_1" type="mesh" rgba="1 1 1 1" mesh="toes_r_geom_1_bofoot"/>
                <site name="flex_dig_r_flex_dig_r-P6" pos="-0.0019 -0.0078 0.0147"/>
                <site name="flex_dig_r_flex_dig_r-P7" pos="0.0285 -0.0071 0.0215"/>
                <site name="flex_dig_r_flex_dig_r-P8" pos="0.0441 -0.006 0.0242"/>
                <site name="flex_hal_r_flex_hal_r-P6" pos="0.0155 -0.0064 -0.0265"/>
                <site name="flex_hal_r_flex_hal_r-P7" pos="0.0562 -0.0102 -0.0181"/>
                <site name="ext_dig_r_ext_dig_r-P5" pos="0.0003 0.0047 0.0153"/>
                <site name="ext_dig_r_ext_dig_r-P6" pos="0.0443 -0.0004 0.025"/>
                <site name="ext_hal_r_ext_hal_r-P6" pos="0.0298 0.0041 -0.0245"/>
                <site name="ext_hal_r_ext_hal_r-P7" pos="0.0563 0.0034 -0.0186"/>
              </body>
            </body>
          </body>
        </body>
      </body>
      <body name="femur_l" pos="-0.0707 -0.0661 -0.0835">
        <inertial pos="0 -0.17 0" quat="0.5 0.5 -0.5 0.5" mass="9.3014" diaginertia="0.1412 0.1339 0.0351"/>
        <joint name="hip_flexion_l" pos="0 0 0" axis="0 0 1" range="-2.094 2.094"/>
        <joint name="hip_adduction_l" pos="0 0 0" axis="-1 0 0" range="-2.094 2.094"/>
        <joint name="hip_rotation_l" pos="0 0 0" axis="0 -1 0" range="-2.094 2.094"/>
        <geom name="femur_l_geom_1" type="mesh" rgba="1 1 1 1" mesh="femur_l_geom_1_femur_l"/>
        <site name="glut_med1_l_glut_med1_l-P2" pos="-0.0218 -0.0117 -0.0555"/>
        <site name="glut_med2_l_glut_med2_l-P2" pos="-0.0258 -0.0058 -0.0527"/>
        <site name="glut_med3_l_glut_med3_l-P2" pos="-0.0309 -0.0047 -0.0518"/>
        <site name="glut_min1_l_glut_min1_l-P2" pos="-0.0072 -0.0104 -0.056"/>
        <site name="glut_min2_l_glut_min2_l-P2" pos="-0.0096 -0.0104 -0.056"/>
        <site name="glut_min3_l_glut_min3_l-P2" pos="-0.0135 -0.0083 -0.055"/>
        <site name="bifemsh_l_bifemsh_l-P1" pos="0.005 -0.2111 -0.0234"/>
        <site name="sar_l_sar_l-P2" pos="-0.003 -0.3568 0.0421"/>
        <site name="add_long_l_add_long_l-P2" pos="0.005 -0.2111 -0.0234"/>
        <site name="add_brev_l_add_brev_l-P2" pos="0.0009 -0.1196 -0.0294"/>
        <site name="add_mag1_l_add_mag1_l-P2" pos="-0.0045 -0.1211 -0.0339"/>
        <site name="add_mag2_l_add_mag2_l-P2" pos="0.0054 -0.2285 -0.0227"/>
        <site name="add_mag3_l_add_mag3_l-P2" pos="0.007 -0.3837 0.0266"/>
        <site name="pect_l_pect_l-P2" pos="-0.0122 -0.0822 -0.0253"/>
        <site name="glut_max1_l_glut_max1_l-P3" pos="-0.0457 -0.0248 -0.0392"/>
        <site name="glut_max1_l_glut_max1_l-P4" pos="-0.0277 -0.0566 -0.047"/>
        <site name="glut_max2_l_glut_max2_l-P3" pos="-0.0426 -0.053 -0.0293"/>
        <site name="glut_max2_l_glut_max2_l-P4" pos="-0.0156 -0.1016 -0.0419"/>
        <site name="glut_max3_l_glut_max3_l-P3" pos="-0.0299 -0.1041 -0.0135"/>
        <site name="glut_max3_l_glut_max3_l-P4" pos="-0.006 -0.1419 -0.0411"/>
        <site name="iliacus_l_iliacus_l-P4" pos="0.0017 -0.0543 -0.0057"/>
        <site name="iliacus_l_iliacus_l-P5" pos="-0.0193 -0.0621 -0.0129"/>
        <site name="psoas_l_psoas_l-P4" pos="0.0016 -0.0507 -0.0038"/>
        <site name="psoas_l_psoas_l-P5" pos="-0.0188 -0.0597 -0.0104"/>
        <site name="quad_fem_l_quad_fem_l-P2" pos="-0.0381 -0.0359 -0.0366"/>
        <site name="gem_l_gem_l-P2" pos="-0.0142 -0.0033 -0.0443"/>
        <site name="peri_l_peri_l-P3" pos="-0.0148 -0.0036 -0.0437"/>
        <site name="rect_fem_l_rect_fem_l-P2" pos="0.0334 -0.403 0.0019"/>
        <site name="vas_int_l_vas_int_l-P1" pos="0.029 -0.1924 0.031"/>
        <site name="vas_int_l_vas_int_l-P2" pos="0.0335 -0.2084 0.0285"/>
        <site name="vas_int_l_vas_int_l-P3" pos="0.0343 -0.403 0.0055"/>
        <site name="vas_lat_l_vas_lat_l-P1" pos="0.0048 -0.1854 0.0349"/>
        <site name="vas_lat_l_vas_lat_l-P2" pos="0.0269 -0.2591 0.0409"/>
        <site name="vas_lat_l_vas_lat_l-P3" pos="0.0361 -0.403 0.0205"/>
        <site name="vas_lat_l_vas_lat_l-P4" pos="0.0253 -0.4243 0.0184"/>
        <body name="tibia_l" pos="0 -0.3957 0">
          <inertial pos="0 -0.1867 0" quat="0.5 0.5 -0.5 0.5" mass="3.7075" diaginertia="0.0511 0.0504 0.0051"/>
          <joint name="knee_angle_l" pos="0 0 0" axis="0 0 1" range="-2.094 0.1745"/>
          <geom name="tibia_l_geom_1" type="mesh" rgba="1 1 1 1" mesh="tibia_l_geom_1_tibia_l"/>
          <geom name="tibia_l_geom_2" type="mesh" rgba="1 1 1 1" mesh="tibia_l_geom_2_l_fibula"/>
          <site name="semimem_l_semimem_l-P2" pos="-0.0348 -0.03519 0.01891"/>
          <site name="semimem_l_semimem_l-P3" pos="-0.027 -0.04771 0.01957"/>
          <site name="semiten_l_semiten_l-P2" pos="-0.04203 -0.02859 0.02277"/>
          <site name="semiten_l_semiten_l-P3" pos="-0.03322 -0.05282 0.02288"/>
          <site name="semiten_l_semiten_l-P4" pos="-0.0113 -0.0746 0.0245"/>
          <site name="semiten_l_semiten_l-P5" pos="0.0027 -0.0956 0.0193"/>
          <site name="bifemlh_l_bifemlh_l-P2" pos="-0.0301 -0.036 -0.02943"/>
          <site name="bifemlh_l_bifemlh_l-P3" pos="-0.0234 -0.0563 -0.0343"/>
          <site name="bifemsh_l_bifemsh_l-P2" pos="-0.0301 -0.036 -0.02943"/>
          <site name="bifemsh_l_bifemsh_l-P3" pos="-0.0234 -0.0563 -0.0343"/>
          <site name="sar_l_sar_l-P3" pos="-0.0056 -0.0419 0.0399"/>
          <site name="sar_l_sar_l-P4" pos="0.006 -0.0589 0.0383"/>
          <site name="sar_l_sar_l-P5" pos="0.0243 -0.084 0.0252"/>
          <site name="rect_fem_l_rect_fem_l-P3" pos="0.04444 -0.02103 0.0014"/>
          <site name="vas_int_l_vas_int_l-P4" pos="0.03836 -0.02053 0.001799"/>
          <site name="vas_lat_l_vas_lat_l-P5" pos="0.04274 -0.02095 0.0165"/>
          <body name="AnkleAssembly" pos="-0.04 -0.116 -0.05">
            <inertial pos="0.04136 -0.24932 0.04006" quat="0.341335 0.435693 -0.739061 0.383994" mass="1.71" diaginertia="0.00220091 0.00207699 0.0012951"/>
            <geom name="AnkleAssembly_geom_1" type="mesh" rgba="0.87 0.56 0.34 1" mesh="AnkleAssembly_geom_1_AnkleAssembly"/>
            <body name="Foot">
              <inertial pos="0.06215 -0.35314 0.04496" quat="0.130389 0.68448 0.215635 0.684096" mass="0.76" diaginertia="0.00184373 0.001789 0.001"/>
              <joint name="zR_FootToAnkleAssembly" armature="0.0060" pos="0.02 -0.288 0.06" axis="0 -2.654e-06 1" range="-0.45 0.6" type="hinge"/>
              <joint name="yR_FootToAnkleAssembly" armature="0.0060" pos="0.02 -0.288 0.06" axis="1 -2.654e-06 -7.041e-12" range="-0.8727 0.5236" type="hinge"/>
              <geom name="Foot_geom_1" type="mesh" rgba="0.301961 0.301961 0.301961 1" mesh="Foot_geom_1_Foot_Amp"/>
            </body>
          </body>
        </body>
      </body>
      <body name="torso" pos="-0.1007 0.0815 0">
        <inertial pos="-0.03 0.32 0" quat="0.707107 0.707107 0 0" mass="34.2366" diaginertia="1.4745 1.4314 0.7555"/>
        <joint name="lumbar_extension" pos="0 0 0" axis="0 0 1" range="-1.571 1.571"/>
        <joint name="lumbar_bending" pos="0 0 0" axis="1 0 0" range="-1.571 1.571"/>
        <joint name="lumbar_rotation" pos="0 0 0" axis="0 1 0" range="-1.571 1.571"/>
        <geom name="torso_geom_1" type="mesh" rgba="1 1 1 1" mesh="torso_geom_1_hat_spine"/>
        <geom name="torso_geom_2" type="mesh" rgba="1 1 1 1" mesh="torso_geom_2_hat_jaw"/>
        <geom name="torso_geom_3" type="mesh" rgba="1 1 1 1" mesh="torso_geom_3_hat_skull"/>
        <geom name="torso_geom_4" type="mesh" rgba="1 1 1 1" mesh="torso_geom_4_hat_ribs"/>
        <site name="ercspn_r_ercspn_r-P2" pos="-0.055 0.11 0.0241"/>
        <site name="ercspn_l_ercspn_l-P2" pos="-0.055 0.11 -0.0241"/>
        <site name="intobl_r_intobl_r-P2" pos="0.07 0.16 0.015"/>
        <site name="intobl_l_intobl_l-P2" pos="0.07 0.16 -0.015"/>
        <site name="extobl_r_extobl_r-P2" pos="0.065 0.11 0.11"/>
        <site name="extobl_l_extobl_l-P2" pos="0.065 0.11 -0.11"/>
      </body>
    </body>
  </worldbody>
  <contact>
    <pair geom1="ground-plane" geom2="pelvis_geom_1"/>
    <pair geom1="ground-plane" geom2="pelvis_geom_2"/>
    <pair geom1="ground-plane" geom2="pelvis_geom_3"/>
    <pair geom1="ground-plane" geom2="femur_r_geom_1"/>
    <pair geom1="ground-plane" geom2="tibia_r_geom_1"/>
    <pair geom1="ground-plane" geom2="tibia_r_geom_2"/>
    <pair geom1="ground-plane" geom2="talus_r_geom_1"/>
    <pair geom1="ground-plane" geom2="calcn_r_geom_1"/>
    <pair geom1="ground-plane" geom2="toes_r_geom_1"/>
    <pair geom1="ground-plane" geom2="femur_l_geom_1"/>
    <pair geom1="ground-plane" geom2="tibia_l_geom_1"/>
    <pair geom1="ground-plane" geom2="tibia_l_geom_2"/>
    <pair geom1="ground-plane" geom2="AnkleAssembly_geom_1"/>
    <pair geom1="ground-plane" geom2="Foot_geom_1"/>
    <pair geom1="ground-plane" geom2="torso_geom_1"/>
    <pair geom1="ground-plane" geom2="torso_geom_2"/>
    <pair geom1="ground-plane" geom2="torso_geom_3"/>
    <pair geom1="ground-plane" geom2="torso_geom_4"/>
  </contact>
  <tendon>
    <spatial name="glut_med1_r_tendon">
      <site site="glut_med1_r_glut_med1_r-P1"/>
      <site site="glut_med1_r_glut_med1_r-P2"/>
    </spatial>
    <spatial name="glut_med2_r_tendon">
      <site site="glut_med2_r_glut_med2_r-P1"/>
      <site site="glut_med2_r_glut_med2_r-P2"/>
    </spatial>
    <spatial name="glut_med3_r_tendon">
      <site site="glut_med3_r_glut_med3_r-P1"/>
      <site site="glut_med3_r_glut_med3_r-P2"/>
    </spatial>
    <spatial name="glut_min1_r_tendon">
      <site site="glut_min1_r_glut_min1_r-P1"/>
      <site site="glut_min1_r_glut_min1_r-P2"/>
    </spatial>
    <spatial name="glut_min2_r_tendon">
      <site site="glut_min2_r_glut_min2_r-P1"/>
      <site site="glut_min2_r_glut_min2_r-P2"/>
    </spatial>
    <spatial name="glut_min3_r_tendon">
      <site site="glut_min3_r_glut_min3_r-P1"/>
      <site site="glut_min3_r_glut_min3_r-P2"/>
    </spatial>
    <spatial name="semimem_r_tendon">
      <site site="semimem_r_semimem_r-P1"/>
      <site site="semimem_r_semimem_r-P2"/>
      <site site="semimem_r_semimem_r-P3"/>
    </spatial>
    <spatial name="semiten_r_tendon">
      <site site="semiten_r_semiten_r-P1"/>
      <site site="semiten_r_semiten_r-P2"/>
      <site site="semiten_r_semiten_r-P3"/>
      <site site="semiten_r_semiten_r-P4"/>
      <site site="semiten_r_semiten_r-P5"/>
    </spatial>
    <spatial name="bifemlh_r_tendon">
      <site site="bifemlh_r_bifemlh_r-P1"/>
      <site site="bifemlh_r_bifemlh_r-P2"/>
      <site site="bifemlh_r_bifemlh_r-P3"/>
    </spatial>
    <spatial name="bifemsh_r_tendon">
      <site site="bifemsh_r_bifemsh_r-P1"/>
      <site site="bifemsh_r_bifemsh_r-P2"/>
      <site site="bifemsh_r_bifemsh_r-P3"/>
    </spatial>
    <spatial name="sar_r_tendon">
      <site site="sar_r_sar_r-P1"/>
      <site site="sar_r_sar_r-P2"/>
      <site site="sar_r_sar_r-P3"/>
      <site site="sar_r_sar_r-P4"/>
      <site site="sar_r_sar_r-P5"/>
    </spatial>
    <spatial name="add_long_r_tendon">
      <site site="add_long_r_add_long_r-P1"/>
      <site site="add_long_r_add_long_r-P2"/>
    </spatial>
    <spatial name="add_brev_r_tendon">
      <site site="add_brev_r_add_brev_r-P1"/>
      <site site="add_brev_r_add_brev_r-P2"/>
    </spatial>
    <spatial name="add_mag1_r_tendon">
      <site site="add_mag1_r_add_mag1_r-P1"/>
      <site site="add_mag1_r_add_mag1_r-P2"/>
    </spatial>
    <spatial name="add_mag2_r_tendon">
      <site site="add_mag2_r_add_mag2_r-P1"/>
      <site site="add_mag2_r_add_mag2_r-P2"/>
    </spatial>
    <spatial name="add_mag3_r_tendon">
      <site site="add_mag3_r_add_mag3_r-P1"/>
      <site site="add_mag3_r_add_mag3_r-P2"/>
    </spatial>
    <spatial name="tfl_r_tendon">
      <site site="tfl_r_tfl_r-P1"/>
      <site site="tfl_r_tfl_r-P2"/>
      <site site="tfl_r_tfl_r-P3"/>
      <site site="tfl_r_tfl_r-P4"/>
    </spatial>
    <spatial name="pect_r_tendon">
      <site site="pect_r_pect_r-P1"/>
      <site site="pect_r_pect_r-P2"/>
    </spatial>
    <spatial name="grac_r_tendon">
      <site site="grac_r_grac_r-P1"/>
      <site site="grac_r_grac_r-P2"/>
      <site site="grac_r_grac_r-P3"/>
      <site site="grac_r_grac_r-P4"/>
    </spatial>
    <spatial name="glut_max1_r_tendon">
      <site site="glut_max1_r_glut_max1_r-P1"/>
      <site site="glut_max1_r_glut_max1_r-P2"/>
      <site site="glut_max1_r_glut_max1_r-P3"/>
      <site site="glut_max1_r_glut_max1_r-P4"/>
    </spatial>
    <spatial name="glut_max2_r_tendon">
      <site site="glut_max2_r_glut_max2_r-P1"/>
      <site site="glut_max2_r_glut_max2_r-P2"/>
      <site site="glut_max2_r_glut_max2_r-P3"/>
      <site site="glut_max2_r_glut_max2_r-P4"/>
    </spatial>
    <spatial name="glut_max3_r_tendon">
      <site site="glut_max3_r_glut_max3_r-P1"/>
      <site site="glut_max3_r_glut_max3_r-P2"/>
      <site site="glut_max3_r_glut_max3_r-P3"/>
      <site site="glut_max3_r_glut_max3_r-P4"/>
    </spatial>
    <spatial name="iliacus_r_tendon">
      <site site="iliacus_r_iliacus_r-P1"/>
      <site site="iliacus_r_iliacus_r-P2"/>
      <site site="iliacus_r_iliacus_r-P3"/>
      <site site="iliacus_r_iliacus_r-P4"/>
      <site site="iliacus_r_iliacus_r-P5"/>
    </spatial>
    <spatial name="psoas_r_tendon">
      <site site="psoas_r_psoas_r-P1"/>
      <site site="psoas_r_psoas_r-P2"/>
      <site site="psoas_r_psoas_r-P3"/>
      <site site="psoas_r_psoas_r-P4"/>
      <site site="psoas_r_psoas_r-P5"/>
    </spatial>
    <spatial name="quad_fem_r_tendon">
      <site site="quad_fem_r_quad_fem_r-P1"/>
      <site site="quad_fem_r_quad_fem_r-P2"/>
    </spatial>
    <spatial name="gem_r_tendon">
      <site site="gem_r_gem_r-P1"/>
      <site site="gem_r_gem_r-P2"/>
    </spatial>
    <spatial name="peri_r_tendon">
      <site site="peri_r_peri_r-P1"/>
      <site site="peri_r_peri_r-P2"/>
      <site site="peri_r_peri_r-P3"/>
    </spatial>
    <spatial name="rect_fem_r_tendon">
      <site site="rect_fem_r_rect_fem_r-P1"/>
      <site site="rect_fem_r_rect_fem_r-P2"/>
      <site site="rect_fem_r_rect_fem_r-P3"/>
    </spatial>
    <spatial name="vas_int_r_tendon">
      <site site="vas_int_r_vas_int_r-P1"/>
      <site site="vas_int_r_vas_int_r-P2"/>
      <site site="vas_int_r_vas_int_r-P3"/>
      <site site="vas_int_r_vas_int_r-P4"/>
    </spatial>
    <spatial name="vas_lat_r_tendon">
      <site site="vas_lat_r_vas_lat_r-P1"/>
      <site site="vas_lat_r_vas_lat_r-P2"/>
      <site site="vas_lat_r_vas_lat_r-P3"/>
      <site site="vas_lat_r_vas_lat_r-P4"/>
      <site site="vas_lat_r_vas_lat_r-P5"/>
    </spatial>
    <spatial name="med_gas_r_tendon">
      <site site="med_gas_r_med_gas_r-P1"/>
      <site site="med_gas_r_med_gas_r-P2"/>
      <site site="med_gas_r_med_gas_r-P3"/>
    </spatial>
    <spatial name="lat_gas_r_tendon">
      <site site="lat_gas_r_lat_gas_r-P1"/>
      <site site="lat_gas_r_lat_gas_r-P2"/>
      <site site="lat_gas_r_lat_gas_r-P3"/>
    </spatial>
    <spatial name="soleus_r_tendon">
      <site site="soleus_r_soleus_r-P1"/>
      <site site="soleus_r_soleus_r-P2"/>
    </spatial>
    <spatial name="tib_post_r_tendon">
      <site site="tib_post_r_tib_post_r-P1"/>
      <site site="tib_post_r_tib_post_r-P2"/>
      <site site="tib_post_r_tib_post_r-P3"/>
      <site site="tib_post_r_tib_post_r-P4"/>
    </spatial>
    <spatial name="flex_dig_r_tendon">
      <site site="flex_dig_r_flex_dig_r-P1"/>
      <site site="flex_dig_r_flex_dig_r-P2"/>
      <site site="flex_dig_r_flex_dig_r-P3"/>
      <site site="flex_dig_r_flex_dig_r-P4"/>
      <site site="flex_dig_r_flex_dig_r-P5"/>
      <site site="flex_dig_r_flex_dig_r-P6"/>
      <site site="flex_dig_r_flex_dig_r-P7"/>
      <site site="flex_dig_r_flex_dig_r-P8"/>
    </spatial>
    <spatial name="flex_hal_r_tendon">
      <site site="flex_hal_r_flex_hal_r-P1"/>
      <site site="flex_hal_r_flex_hal_r-P2"/>
      <site site="flex_hal_r_flex_hal_r-P3"/>
      <site site="flex_hal_r_flex_hal_r-P4"/>
      <site site="flex_hal_r_flex_hal_r-P5"/>
      <site site="flex_hal_r_flex_hal_r-P6"/>
      <site site="flex_hal_r_flex_hal_r-P7"/>
    </spatial>
    <spatial name="tib_ant_r_tendon">
      <site site="tib_ant_r_tib_ant_r-P1"/>
      <site site="tib_ant_r_tib_ant_r-P2"/>
      <site site="tib_ant_r_tib_ant_r-P3"/>
    </spatial>
    <spatial name="per_brev_r_tendon">
      <site site="per_brev_r_per_brev_r-P1"/>
      <site site="per_brev_r_per_brev_r-P2"/>
      <site site="per_brev_r_per_brev_r-P3"/>
      <site site="per_brev_r_per_brev_r-P4"/>
      <site site="per_brev_r_per_brev_r-P5"/>
    </spatial>
    <spatial name="per_long_r_tendon">
      <site site="per_long_r_per_long_r-P1"/>
      <site site="per_long_r_per_long_r-P2"/>
      <site site="per_long_r_per_long_r-P3"/>
      <site site="per_long_r_per_long_r-P4"/>
      <site site="per_long_r_per_long_r-P5"/>
      <site site="per_long_r_per_long_r-P6"/>
      <site site="per_long_r_per_long_r-P7"/>
    </spatial>
    <spatial name="per_tert_r_tendon">
      <site site="per_tert_r_per_tert_r-P1"/>
      <site site="per_tert_r_per_tert_r-P2"/>
      <site site="per_tert_r_per_tert_r-P3"/>
    </spatial>
    <spatial name="ext_dig_r_tendon">
      <site site="ext_dig_r_ext_dig_r-P1"/>
      <site site="ext_dig_r_ext_dig_r-P2"/>
      <site site="ext_dig_r_ext_dig_r-P3"/>
      <site site="ext_dig_r_ext_dig_r-P4"/>
      <site site="ext_dig_r_ext_dig_r-P5"/>
      <site site="ext_dig_r_ext_dig_r-P6"/>
    </spatial>
    <spatial name="ext_hal_r_tendon">
      <site site="ext_hal_r_ext_hal_r-P1"/>
      <site site="ext_hal_r_ext_hal_r-P2"/>
      <site site="ext_hal_r_ext_hal_r-P3"/>
      <site site="ext_hal_r_ext_hal_r-P4"/>
      <site site="ext_hal_r_ext_hal_r-P5"/>
      <site site="ext_hal_r_ext_hal_r-P6"/>
      <site site="ext_hal_r_ext_hal_r-P7"/>
    </spatial>
    <spatial name="glut_med1_l_tendon">
      <site site="glut_med1_l_glut_med1_l-P1"/>
      <site site="glut_med1_l_glut_med1_l-P2"/>
    </spatial>
    <spatial name="glut_med2_l_tendon">
      <site site="glut_med2_l_glut_med2_l-P1"/>
      <site site="glut_med2_l_glut_med2_l-P2"/>
    </spatial>
    <spatial name="glut_med3_l_tendon">
      <site site="glut_med3_l_glut_med3_l-P1"/>
      <site site="glut_med3_l_glut_med3_l-P2"/>
    </spatial>
    <spatial name="glut_min1_l_tendon">
      <site site="glut_min1_l_glut_min1_l-P1"/>
      <site site="glut_min1_l_glut_min1_l-P2"/>
    </spatial>
    <spatial name="glut_min2_l_tendon">
      <site site="glut_min2_l_glut_min2_l-P1"/>
      <site site="glut_min2_l_glut_min2_l-P2"/>
    </spatial>
    <spatial name="glut_min3_l_tendon">
      <site site="glut_min3_l_glut_min3_l-P1"/>
      <site site="glut_min3_l_glut_min3_l-P2"/>
    </spatial>
    <spatial name="semimem_l_tendon">
      <site site="semimem_l_semimem_l-P1"/>
      <site site="semimem_l_semimem_l-P2"/>
      <site site="semimem_l_semimem_l-P3"/>
    </spatial>
    <spatial name="semiten_l_tendon">
      <site site="semiten_l_semiten_l-P1"/>
      <site site="semiten_l_semiten_l-P2"/>
      <site site="semiten_l_semiten_l-P3"/>
      <site site="semiten_l_semiten_l-P4"/>
      <site site="semiten_l_semiten_l-P5"/>
    </spatial>
    <spatial name="bifemlh_l_tendon">
      <site site="bifemlh_l_bifemlh_l-P1"/>
      <site site="bifemlh_l_bifemlh_l-P2"/>
      <site site="bifemlh_l_bifemlh_l-P3"/>
    </spatial>
    <spatial name="bifemsh_l_tendon">
      <site site="bifemsh_l_bifemsh_l-P1"/>
      <site site="bifemsh_l_bifemsh_l-P2"/>
      <site site="bifemsh_l_bifemsh_l-P3"/>
    </spatial>
    <spatial name="sar_l_tendon">
      <site site="sar_l_sar_l-P1"/>
      <site site="sar_l_sar_l-P2"/>
      <site site="sar_l_sar_l-P3"/>
      <site site="sar_l_sar_l-P4"/>
      <site site="sar_l_sar_l-P5"/>
    </spatial>
    <spatial name="add_long_l_tendon">
      <site site="add_long_l_add_long_l-P1"/>
      <site site="add_long_l_add_long_l-P2"/>
    </spatial>
    <spatial name="add_brev_l_tendon">
      <site site="add_brev_l_add_brev_l-P1"/>
      <site site="add_brev_l_add_brev_l-P2"/>
    </spatial>
    <spatial name="add_mag1_l_tendon">
      <site site="add_mag1_l_add_mag1_l-P1"/>
      <site site="add_mag1_l_add_mag1_l-P2"/>
    </spatial>
    <spatial name="add_mag2_l_tendon">
      <site site="add_mag2_l_add_mag2_l-P1"/>
      <site site="add_mag2_l_add_mag2_l-P2"/>
    </spatial>
    <spatial name="add_mag3_l_tendon">
      <site site="add_mag3_l_add_mag3_l-P1"/>
      <site site="add_mag3_l_add_mag3_l-P2"/>
    </spatial>
    <spatial name="pect_l_tendon">
      <site site="pect_l_pect_l-P1"/>
      <site site="pect_l_pect_l-P2"/>
    </spatial>
    <spatial name="glut_max1_l_tendon">
      <site site="glut_max1_l_glut_max1_l-P1"/>
      <site site="glut_max1_l_glut_max1_l-P2"/>
      <site site="glut_max1_l_glut_max1_l-P3"/>
      <site site="glut_max1_l_glut_max1_l-P4"/>
    </spatial>
    <spatial name="glut_max2_l_tendon">
      <site site="glut_max2_l_glut_max2_l-P1"/>
      <site site="glut_max2_l_glut_max2_l-P2"/>
      <site site="glut_max2_l_glut_max2_l-P3"/>
      <site site="glut_max2_l_glut_max2_l-P4"/>
    </spatial>
    <spatial name="glut_max3_l_tendon">
      <site site="glut_max3_l_glut_max3_l-P1"/>
      <site site="glut_max3_l_glut_max3_l-P2"/>
      <site site="glut_max3_l_glut_max3_l-P3"/>
      <site site="glut_max3_l_glut_max3_l-P4"/>
    </spatial>
    <spatial name="iliacus_l_tendon">
      <site site="iliacus_l_iliacus_l-P1"/>
      <site site="iliacus_l_iliacus_l-P2"/>
      <site site="iliacus_l_iliacus_l-P3"/>
      <site site="iliacus_l_iliacus_l-P4"/>
      <site site="iliacus_l_iliacus_l-P5"/>
    </spatial>
    <spatial name="psoas_l_tendon">
      <site site="psoas_l_psoas_l-P1"/>
      <site site="psoas_l_psoas_l-P2"/>
      <site site="psoas_l_psoas_l-P3"/>
      <site site="psoas_l_psoas_l-P4"/>
      <site site="psoas_l_psoas_l-P5"/>
    </spatial>
    <spatial name="quad_fem_l_tendon">
      <site site="quad_fem_l_quad_fem_l-P1"/>
      <site site="quad_fem_l_quad_fem_l-P2"/>
    </spatial>
    <spatial name="gem_l_tendon">
      <site site="gem_l_gem_l-P1"/>
      <site site="gem_l_gem_l-P2"/>
    </spatial>
    <spatial name="peri_l_tendon">
      <site site="peri_l_peri_l-P1"/>
      <site site="peri_l_peri_l-P2"/>
      <site site="peri_l_peri_l-P3"/>
    </spatial>
    <spatial name="rect_fem_l_tendon">
      <site site="rect_fem_l_rect_fem_l-P1"/>
      <site site="rect_fem_l_rect_fem_l-P2"/>
      <site site="rect_fem_l_rect_fem_l-P3"/>
    </spatial>
    <spatial name="vas_int_l_tendon">
      <site site="vas_int_l_vas_int_l-P1"/>
      <site site="vas_int_l_vas_int_l-P2"/>
      <site site="vas_int_l_vas_int_l-P3"/>
      <site site="vas_int_l_vas_int_l-P4"/>
    </spatial>
    <spatial name="vas_lat_l_tendon">
      <site site="vas_lat_l_vas_lat_l-P1"/>
      <site site="vas_lat_l_vas_lat_l-P2"/>
      <site site="vas_lat_l_vas_lat_l-P3"/>
      <site site="vas_lat_l_vas_lat_l-P4"/>
      <site site="vas_lat_l_vas_lat_l-P5"/>
    </spatial>
    <spatial name="ercspn_r_tendon">
      <site site="ercspn_r_ercspn_r-P1"/>
      <site site="ercspn_r_ercspn_r-P2"/>
    </spatial>
    <spatial name="ercspn_l_tendon">
      <site site="ercspn_l_ercspn_l-P1"/>
      <site site="ercspn_l_ercspn_l-P2"/>
    </spatial>
    <spatial name="intobl_r_tendon">
      <site site="intobl_r_intobl_r-P1"/>
      <site site="intobl_r_intobl_r-P2"/>
    </spatial>
    <spatial name="intobl_l_tendon">
      <site site="intobl_l_intobl_l-P1"/>
      <site site="intobl_l_intobl_l-P2"/>
    </spatial>
    <spatial name="extobl_r_tendon">
      <site site="extobl_r_extobl_r-P1"/>
      <site site="extobl_r_extobl_r-P2"/>
    </spatial>
    <spatial name="extobl_l_tendon">
      <site site="extobl_l_extobl_l-P1"/>
      <site site="extobl_l_extobl_l-P2"/>
    </spatial>
  </tendon>
  <actuator>
    <general name="glut_med1_r" class="muscle" tendon="glut_med1_r_tendon" lengthrange="0.0469632 0.168445" gainprm="0.0375901 1.346 720.277 1 0 2 10 3.73792 1.4 0" biasprm="0.0375901 1.346 720.277 1 0 2 10 3.73792 1.4 0"/>
    <general name="glut_med2_r" class="muscle" tendon="glut_med2_r_tendon" lengthrange="0.0552468 0.170754" gainprm="0.214321 1.31783 549.954 1 0 2 10 1.4565 1.4 0" biasprm="0.214321 1.31783 549.954 1 0 2 10 1.4565 1.4 0"/>
    <general name="glut_med3_r" class="muscle" tendon="glut_med3_r_tendon" lengthrange="0.034202 0.154398" gainprm="0.0914381 1.35737 574.592 1 0 2 10 2.48755 1.4 0" biasprm="0.0914381 1.35737 574.592 1 0 2 10 2.48755 1.4 0"/>
    <general name="glut_min1_r" class="muscle" tendon="glut_min1_r_tendon" lengthrange="0.00954758 0.12394" gainprm="0.164681 1.28825 263.42 1 0 2 10 3.12803 1.4 0" biasprm="0.164681 1.28825 263.42 1 0 2 10 3.12803 1.4 0"/>
    <general name="glut_min2_r" class="muscle" tendon="glut_min2_r_tendon" lengthrange="0.00879027 0.119789" gainprm="0.0880422 1.51889 248.464 1 0 2 10 2.54012 1.4 0" biasprm="0.0880422 1.51889 248.464 1 0 2 10 2.54012 1.4 0"/>
    <general name="glut_min3_r" class="muscle" tendon="glut_min3_r_tendon" lengthrange="0.00469494 0.117857" gainprm="0.0257654 1.57184 185.991 1 0 2 10 4.63818 1.4 0" biasprm="0.0257654 1.57184 185.991 1 0 2 10 4.63818 1.4 0"/>
    <general name="semimem_r" class="muscle" tendon="semimem_r_tendon" lengthrange="0.3322 0.51094" gainprm="0.0543415 1.47295 1061.3 1 0 2 10 3.8481 1.4 0" biasprm="0.0543415 1.47295 1061.3 1 0 2 10 3.8481 1.4 0"/>
    <general name="semiten_r" class="muscle" tendon="semiten_r_tendon" lengthrange="0.384414 0.588297" gainprm="0.559204 1.96909 402.691 1 0 2 10 0.992295 1.4 0" biasprm="0.559204 1.96909 402.691 1 0 2 10 0.992295 1.4 0"/>
    <general name="bifemlh_r" class="muscle" tendon="bifemlh_r_tendon" lengthrange="0.335471 0.526997" gainprm="0.253575 1.44182 857.232 1 0 2 10 3.46166 1.4 0" biasprm="0.253575 1.44182 857.232 1 0 2 10 3.46166 1.4 0"/>
    <general name="bifemsh_r" class="muscle" tendon="bifemsh_r_tendon" lengthrange="0.191264 0.249268" gainprm="0.666289 1.24497 687.788 1 0 2 10 1.70547 1.4 0" biasprm="0.666289 1.24497 687.788 1 0 2 10 1.70547 1.4 0"/>
    <general name="sar_r" class="muscle" tendon="sar_r_tendon" lengthrange="0.384394 0.581501" gainprm="0.623837 1.34169 134.181 1 0 2 10 2.01819 1.4 0" biasprm="0.623837 1.34169 134.181 1 0 2 10 2.01819 1.4 0"/>
    <general name="add_long_r" class="muscle" tendon="add_long_r_tendon" lengthrange="0.133441 0.291587" gainprm="0.337027 1.07656 625.245 1 0 2 10 3.3567 1.4 0" biasprm="0.337027 1.07656 625.245 1 0 2 10 3.3567 1.4 0"/>
    <general name="add_brev_r" class="muscle" tendon="add_brev_r_tendon" lengthrange="0.0504269 0.195868" gainprm="0.370446 1.28344 410.002 1 0 2 10 1.37821 1.4 0" biasprm="0.370446 1.28344 410.002 1 0 2 10 1.37821 1.4 0"/>
    <general name="add_mag1_r" class="muscle" tendon="add_mag1_r_tendon" lengthrange="0.0517283 0.203072" gainprm="0.145561 1.21012 422.543 1 0 2 10 2.27387 1.4 0" biasprm="0.145561 1.21012 422.543 1 0 2 10 2.27387 1.4 0"/>
    <general name="add_mag2_r" class="muscle" tendon="add_mag2_r_tendon" lengthrange="0.154271 0.304177" gainprm="0.401588 1.33365 331.227 1 0 2 10 1.56908 1.4 0" biasprm="0.401588 1.33365 331.227 1 0 2 10 1.56908 1.4 0"/>
    <general name="add_mag3_r" class="muscle" tendon="add_mag3_r_tendon" lengthrange="0.314002 0.454121" gainprm="0.524887 1.41744 473.353 1 0 2 10 1.2365 1.4 0" biasprm="0.524887 1.41744 473.353 1 0 2 10 1.2365 1.4 0"/>
    <general name="tfl_r" class="muscle" tendon="tfl_r_tendon" lengthrange="0.368658 0.585301" gainprm="0.0956582 1.16027 220.951 1 0 2 10 1.35407 1.4 0" biasprm="0.0956582 1.16027 220.951 1 0 2 10 1.35407 1.4 0"/>
    <general name="pect_r" class="muscle" tendon="pect_r_tendon" lengthrange="0.0384406 0.135284" gainprm="0.198464 1.26979 223.823 1 0 2 10 2.57642 1.4 0" biasprm="0.198464 1.26979 223.823 1 0 2 10 2.57642 1.4 0"/>
    <general name="grac_r" class="muscle" tendon="grac_r_tendon" lengthrange="0.374254 0.573288" gainprm="0.689111 1.07667 161.877 1 0 2 10 2.68483 1.4 0" biasprm="0.689111 1.07667 161.877 1 0 2 10 2.68483 1.4 0"/>
    <general name="glut_max1_r" class="muscle" tendon="glut_max1_r_tendon" lengthrange="0.125622 0.254802" gainprm="0.114053 1.48617 389.588 1 0 2 10 2.0886 1.4 0" biasprm="0.114053 1.48617 389.588 1 0 2 10 2.0886 1.4 0"/>
    <general name="glut_max2_r" class="muscle" tendon="glut_max2_r_tendon" lengthrange="0.143338 0.27783" gainprm="0.254055 1.21235 699.901 1 0 2 10 3.02147 1.4 0" biasprm="0.254055 1.21235 699.901 1 0 2 10 3.02147 1.4 0"/>
    <general name="glut_max3_r" class="muscle" tendon="glut_max3_r_tendon" lengthrange="0.144372 0.343714" gainprm="0.220893 1.10489 548.955 1 0 2 10 2.97941 1.4 0" biasprm="0.220893 1.10489 548.955 1 0 2 10 2.97941 1.4 0"/>
    <general name="iliacus_r" class="muscle" tendon="iliacus_r_tendon" lengthrange="0.161407 0.246786" gainprm="0.465998 1.05782 1036.72 1 0 2 10 3.58686 1.4 0" biasprm="0.465998 1.05782 1036.72 1 0 2 10 3.58686 1.4 0"/>
    <general name="psoas_r" class="muscle" tendon="psoas_r_tendon" lengthrange="0.240101 0.299458" gainprm="0.527851 1.39829 1052.03 1 0 2 10 1.21468 1.4 0" biasprm="0.527851 1.39829 1052.03 1 0 2 10 1.21468 1.4 0"/>
    <general name="quad_fem_r" class="muscle" tendon="quad_fem_r_tendon" lengthrange="0.00903833 0.1362" gainprm="0.0632298 1.62951 762 1 0 2 10 5 1.4 0" biasprm="0.0632298 1.62951 762 1 0 2 10 5 1.4 0"/>
    <general name="gem_r" class="muscle" tendon="gem_r_tendon" lengthrange="0.00600155 0.0936369" gainprm="0.0902481 1.84491 187.377 1 0 2 10 4.48044 1.4 0" biasprm="0.0902481 1.84491 187.377 1 0 2 10 4.48044 1.4 0"/>
    <general name="peri_r" class="muscle" tendon="peri_r_tendon" lengthrange="0.0740756 0.165184" gainprm="0.114824 1.80551 222 1 0 2 10 3.22306 1.4 0" biasprm="0.114824 1.80551 222 1 0 2 10 3.22306 1.4 0"/>
    <general name="rect_fem_r" class="muscle" tendon="rect_fem_r_tendon" lengthrange="0.361018 0.549733" gainprm="0.254405 1.38268 1121.43 1 0 2 10 3.09655 1.4 0" biasprm="0.254405 1.38268 1121.43 1 0 2 10 3.09655 1.4 0"/>
    <general name="vas_int_r" class="muscle" tendon="vas_int_r_tendon" lengthrange="0.220074 0.298905" gainprm="0.504396 1.19144 1343.51 1 0 2 10 1.82343 1.4 0" biasprm="0.504396 1.19144 1343.51 1 0 2 10 1.82343 1.4 0"/>
    <general name="vas_lat_r" class="muscle" tendon="vas_lat_r_tendon" lengthrange="0.256546 0.319536" gainprm="0.620832 1.12211 1845.65 1 0 2 10 2.29363 1.4 0" biasprm="0.620832 1.12211 1845.65 1 0 2 10 2.29363 1.4 0"/>
    <general name="med_gas_r" class="muscle" tendon="med_gas_r_tendon" lengthrange="0.36586 0.493438" gainprm="0.0384405 1.40802 1211.36 1 0 2 10 2.25721 1.4 0" biasprm="0.0384405 1.40802 1211.36 1 0 2 10 2.25721 1.4 0"/>
    <general name="lat_gas_r" class="muscle" tendon="lat_gas_r_tendon" lengthrange="0.361156 0.489857" gainprm="0.0301745 1.16862 687.131 1 0 2 10 1.18063 1.4 0" biasprm="0.0301745 1.16862 687.131 1 0 2 10 1.18063 1.4 0"/>
    <general name="soleus_r" class="muscle" tendon="soleus_r_tendon" lengthrange="0.229787 0.326724" gainprm="0.0671559 1.03993 3361.9 1 0 2 10 2.63593 1.4 0" biasprm="0.0671559 1.03993 3361.9 1 0 2 10 2.63593 1.4 0"/>
    <general name="tib_post_r" class="muscle" tendon="tib_post_r_tendon" lengthrange="0.325571 0.371613" gainprm="0.431593 1.25433 1551.56 1 0 2 10 4.09648 1.4 0" biasprm="0.431593 1.25433 1551.56 1 0 2 10 4.09648 1.4 0"/>
    <general name="flex_dig_r" class="muscle" tendon="flex_dig_r_tendon" lengthrange="0.404057 0.462336" gainprm="0.150326 1.32827 290.308 1 0 2 10 1.42319 1.4 0" biasprm="0.150326 1.32827 290.308 1 0 2 10 1.42319 1.4 0"/>
    <general name="flex_hal_r" class="muscle" tendon="flex_hal_r_tendon" lengthrange="0.389261 0.450446" gainprm="0.262351 1.14831 313.225 1 0 2 10 1.47693 1.4 0" biasprm="0.262351 1.14831 313.225 1 0 2 10 1.47693 1.4 0"/>
    <general name="tib_ant_r" class="muscle" tendon="tib_ant_r_tendon" lengthrange="0.259088 0.355378" gainprm="0.438248 1.12633 892.481 1 0 2 10 1.8944 1.4 0" biasprm="0.438248 1.12633 892.481 1 0 2 10 1.8944 1.4 0"/>
    <general name="per_brev_r" class="muscle" tendon="per_brev_r_tendon" lengthrange="0.192265 0.248314" gainprm="0.603327 1.37859 418.727 1 0 2 10 2.59782 1.4 0" biasprm="0.603327 1.37859 418.727 1 0 2 10 2.59782 1.4 0"/>
    <general name="per_long_r" class="muscle" tendon="per_long_r_tendon" lengthrange="0.377471 0.434675" gainprm="0.563705 1.28177 916.206 1 0 2 10 2.70273 1.4 0" biasprm="0.563705 1.28177 916.206 1 0 2 10 2.70273 1.4 0"/>
    <general name="per_tert_r" class="muscle" tendon="per_tert_r_tendon" lengthrange="0.147847 0.221696" gainprm="0.622031 1.6588 170.565 1 0 2 10 1.09324 1.4 0" biasprm="0.622031 1.6588 170.565 1 0 2 10 1.09324 1.4 0"/>
    <general name="ext_dig_r" class="muscle" tendon="ext_dig_r_tendon" lengthrange="0.405382 0.491544" gainprm="0.583642 1.15826 493.711 1 0 2 10 2.94816 1.4 0" biasprm="0.583642 1.15826 493.711 1 0 2 10 2.94816 1.4 0"/>
    <general name="ext_hal_r" class="muscle" tendon="ext_hal_r_tendon" lengthrange="0.367721 0.462542" gainprm="0.574132 1.10167 160.157 1 0 2 10 2.32899 1.4 0" biasprm="0.574132 1.10167 160.157 1 0 2 10 2.32899 1.4 0"/>
    <general name="glut_med1_l" class="muscle" tendon="glut_med1_l_tendon" lengthrange="0.0469632 0.168445" gainprm="0.0186282 1.24682 842.53 1 0 2 10 3.11374 1.4 0" biasprm="0.0186282 1.24682 842.53 1 0 2 10 3.11374 1.4 0"/>
    <general name="glut_med2_l" class="muscle" tendon="glut_med2_l_tendon" lengthrange="0.0552468 0.170754" gainprm="0.263765 1.10444 573.055 1 0 2 10 2.8862 1.4 0" biasprm="0.263765 1.10444 573.055 1 0 2 10 2.8862 1.4 0"/>
    <general name="glut_med3_l" class="muscle" tendon="glut_med3_l_tendon" lengthrange="0.034202 0.154398" gainprm="0.0444656 1.31209 605.274 1 0 2 10 2.63288 1.4 0" biasprm="0.0444656 1.31209 605.274 1 0 2 10 2.63288 1.4 0"/>
    <general name="glut_min1_l" class="muscle" tendon="glut_min1_l_tendon" lengthrange="0.00954758 0.12394" gainprm="0.169375 1.24271 266.242 1 0 2 10 4.04834 1.4 0" biasprm="0.169375 1.24271 266.242 1 0 2 10 4.04834 1.4 0"/>
    <general name="glut_min2_l" class="muscle" tendon="glut_min2_l_tendon" lengthrange="0.00879027 0.119789" gainprm="0.0837417 1.35443 268.069 1 0 2 10 3.95685 1.4 0" biasprm="0.0837417 1.35443 268.069 1 0 2 10 3.95685 1.4 0"/>
    <general name="glut_min3_l" class="muscle" tendon="glut_min3_l_tendon" lengthrange="0.00469494 0.117857" gainprm="0.311218 1.67475 161.5 1 0 2 10 3.79927 1.4 0" biasprm="0.311218 1.67475 161.5 1 0 2 10 3.79927 1.4 0"/>
    <general name="semimem_l" class="muscle" tendon="semimem_l_tendon" lengthrange="0.3322 0.51094" gainprm="0.231522 1.69216 837.184 1 0 2 10 2.94199 1.4 0" biasprm="0.231522 1.69216 837.184 1 0 2 10 2.94199 1.4 0"/>
    <general name="semiten_l" class="muscle" tendon="semiten_l_tendon" lengthrange="0.384414 0.588297" gainprm="0.586363 1.45368 394.962 1 0 2 10 1.96067 1.4 0" biasprm="0.586363 1.45368 394.962 1 0 2 10 1.96067 1.4 0"/>
    <general name="bifemlh_l" class="muscle" tendon="bifemlh_l_tendon" lengthrange="0.335471 0.526997" gainprm="0.23882 1.43098 865.704 1 0 2 10 3.57829 1.4 0" biasprm="0.23882 1.43098 865.704 1 0 2 10 3.57829 1.4 0"/>
    <general name="bifemsh_l" class="muscle" tendon="bifemsh_l_tendon" lengthrange="0.191264 0.249268" gainprm="0.683642 1.43914 668.488 1 0 2 10 1.33814 1.4 0" biasprm="0.683642 1.43914 668.488 1 0 2 10 1.33814 1.4 0"/>
    <general name="sar_l" class="muscle" tendon="sar_l_tendon" lengthrange="0.384394 0.581501" gainprm="0.592491 1.16432 143.051 1 0 2 10 2.6219 1.4 0" biasprm="0.592491 1.16432 143.051 1 0 2 10 2.6219 1.4 0"/>
    <general name="add_long_l" class="muscle" tendon="add_long_l_tendon" lengthrange="0.133441 0.291587" gainprm="0.328993 1.12603 619.356 1 0 2 10 1.55949 1.4 0" biasprm="0.328993 1.12603 619.356 1 0 2 10 1.55949 1.4 0"/>
    <general name="add_brev_l" class="muscle" tendon="add_brev_l_tendon" lengthrange="0.0504269 0.195868" gainprm="0.364253 1.25904 411.929 1 0 2 10 1.48767 1.4 0" biasprm="0.364253 1.25904 411.929 1 0 2 10 1.48767 1.4 0"/>
    <general name="add_mag1_l" class="muscle" tendon="add_mag1_l_tendon" lengthrange="0.0517283 0.203072" gainprm="0.10623 1.51778 349.293 1 0 2 10 2.04922 1.4 0" biasprm="0.10623 1.51778 349.293 1 0 2 10 2.04922 1.4 0"/>
    <general name="add_mag2_l" class="muscle" tendon="add_mag2_l_tendon" lengthrange="0.154271 0.304177" gainprm="0.42361 1.12599 344.927 1 0 2 10 3.69841 1.4 0" biasprm="0.42361 1.12599 344.927 1 0 2 10 3.69841 1.4 0"/>
    <general name="add_mag3_l" class="muscle" tendon="add_mag3_l_tendon" lengthrange="0.314002 0.454121" gainprm="0.545307 1.14616 487.359 1 0 2 10 3.2863 1.4 0" biasprm="0.545307 1.14616 487.359 1 0 2 10 3.2863 1.4 0"/>
    <general name="pect_l" class="muscle" tendon="pect_l_tendon" lengthrange="0.0384406 0.135284" gainprm="0.231091 1.05115 250.407 1 0 2 10 3.28938 1.4 0" biasprm="0.231091 1.05115 250.407 1 0 2 10 3.28938 1.4 0"/>
    <general name="glut_max1_l" class="muscle" tendon="glut_max1_l_tendon" lengthrange="0.125622 0.254802" gainprm="0.142603 1.19231 450.027 1 0 2 10 4.25793 1.4 0" biasprm="0.142603 1.19231 450.027 1 0 2 10 4.25793 1.4 0"/>
    <general name="glut_max2_l" class="muscle" tendon="glut_max2_l_tendon" lengthrange="0.143338 0.27783" gainprm="0.270509 1.0022 788.308 1 0 2 10 3.61274 1.4 0" biasprm="0.270509 1.0022 788.308 1 0 2 10 3.61274 1.4 0"/>
    <general name="glut_max3_l" class="muscle" tendon="glut_max3_l_tendon" lengthrange="0.144372 0.343714" gainprm="0.169868 1.26035 533.646 1 0 2 10 1.1135 1.4 0" biasprm="0.169868 1.26035 533.646 1 0 2 10 1.1135 1.4 0"/>
    <general name="iliacus_l" class="muscle" tendon="iliacus_l_tendon" lengthrange="0.161407 0.246786" gainprm="0.450924 1.08725 1026.57 1 0 2 10 2.53763 1.4 0" biasprm="0.450924 1.08725 1026.57 1 0 2 10 2.53763 1.4 0"/>
    <general name="psoas_l" class="muscle" tendon="psoas_l_tendon" lengthrange="0.240101 0.299458" gainprm="0.542045 1.22372 1081.76 1 0 2 10 1.90734 1.4 0" biasprm="0.542045 1.22372 1081.76 1 0 2 10 1.90734 1.4 0"/>
    <general name="quad_fem_l" class="muscle" tendon="quad_fem_l_tendon" lengthrange="0.00903833 0.1362" gainprm="0.0639989 1.75994 565.027 1 0 2 10 4.70389 1.4 0" biasprm="0.0639989 1.75994 565.027 1 0 2 10 4.70389 1.4 0"/>
    <general name="gem_l" class="muscle" tendon="gem_l_tendon" lengthrange="0.00600155 0.0936369" gainprm="0.0682677 1.73488 246.861 1 0 2 10 4.18471 1.4 0" biasprm="0.0682677 1.73488 246.861 1 0 2 10 4.18471 1.4 0"/>
    <general name="peri_l" class="muscle" tendon="peri_l_tendon" lengthrange="0.0740756 0.165184" gainprm="0.0211316 1.61712 226.342 1 0 2 10 4.90751 1.4 0" biasprm="0.0211316 1.61712 226.342 1 0 2 10 4.90751 1.4 0"/>
    <general name="rect_fem_l" class="muscle" tendon="rect_fem_l_tendon" lengthrange="0.231553 0.681649" gainprm="0.465264 1.95501 1937.29 1 0 2 10 4.63941 1.4 0" biasprm="0.465264 1.95501 1937.29 1 0 2 10 4.63941 1.4 0"/>
    <general name="vas_int_l" class="muscle" tendon="vas_int_l_tendon" lengthrange="0.220074 0.298905" gainprm="0.5018 1.26989 1331.77 1 0 2 10 1.32244 1.4 0" biasprm="0.5018 1.26989 1331.77 1 0 2 10 1.32244 1.4 0"/>
    <general name="vas_lat_l" class="muscle" tendon="vas_lat_l_tendon" lengthrange="0.256546 0.319536" gainprm="0.628404 1.0866 1834.96 1 0 2 10 3.91386 1.4 0" biasprm="0.628404 1.0866 1834.96 1 0 2 10 3.91386 1.4 0"/>
    <general name="ercspn_r" class="muscle" tendon="ercspn_r_tendon" lengthrange="0.0572059 0.194745" gainprm="0.377265 1.24384 2411.84 1 0 2 10 1.44431 1.4 0" biasprm="0.377265 1.24384 2411.84 1 0 2 10 1.44431 1.4 0"/>
    <general name="ercspn_l" class="muscle" tendon="ercspn_l_tendon" lengthrange="0.0572059 0.194745" gainprm="0.370827 1.25847 2419.95 1 0 2 10 1.30732 1.4 0" biasprm="0.370827 1.25847 2419.95 1 0 2 10 1.30732 1.4 0"/>
    <general name="intobl_r" class="muscle" tendon="intobl_r_tendon" lengthrange="0.0454006 0.306151" gainprm="0.0672691 1.68342 1107.35 1 0 2 10 4.62991 1.4 0" biasprm="0.0672691 1.68342 1107.35 1 0 2 10 4.62991 1.4 0"/>
    <general name="intobl_l" class="muscle" tendon="intobl_l_tendon" lengthrange="0.0454006 0.306151" gainprm="0.123147 1.87034 886.909 1 0 2 10 3.92027 1.4 0" biasprm="0.123147 1.87034 886.909 1 0 2 10 3.92027 1.4 0"/>
    <general name="extobl_r" class="muscle" tendon="extobl_r_tendon" lengthrange="0.0444131 0.329629" gainprm="0.0536369 1.34223 713.505 1 0 2 10 2.83967 1.4 0" biasprm="0.0536369 1.34223 713.505 1 0 2 10 2.83967 1.4 0"/>
    <general name="extobl_l" class="muscle" tendon="extobl_l_tendon" lengthrange="0.0444131 0.329629" gainprm="0.01 1 980.145 1 0 2 10 3.12315 1.4 0" biasprm="0.01 1 980.145 1 0 2 10 3.12315 1.4 0"/>
    <motor gear="200" joint="yR_FootToAnkleAssembly" name="yR_FootToAnkleAssembly"/>
    <motor gear="200" joint="zR_FootToAnkleAssembly" name="zR_FootToAnkleAssembly"/>
  </actuator>
  <keyframe>
    <key name="default-pose" qpos="0 0 0 0 0 0 0 0 0 -0.003639 0 0 0 0 0 0 -0.003639 0 0 0 0 0"/>
  </keyframe>
</mujoco>
