<mujoco model="template">
  <!-- This model has been converted from an OpenSim model. Model conversion by MyoConverter https://github.com/MyoHub/myoconverter. This model is licensed under Apache 2.0. -->
  <compiler angle="radian" autolimits="true"/>
  <option timestep="0.001" collision="predefined"/>
  <size njmax="1000" nconmax="400" nkey="1" nuser_jnt="1"/>
  <visual>
    <scale framelength="0.5" framewidth="0.01"/>
  </visual>
  <statistic meansize="0.0888517" extent="2.54254" center="0.271269 0 0"/>
  <default class="main">
    <joint limited="true" armature="1e-05" damping="0.05"/>
    <geom margin="0.001" rgba="0.8 0.6 0.4 1"/>
    <site size="0.001 0.005 0.005"/>
    <tendon limited="false" width="0.005" rgba="0.95 0.3 0.3 1"/>
    <default class="muscle">
      <general ctrllimited="true" ctrlrange="0 1" dyntype="muscle" gaintype="muscle" biastype="muscle" dynprm="0.01 0.04 0 0 0 0 0 0 0 0" gainprm="0.75 1.05 -1 200 0.5 1.6 1.5 1.3 1.2 0" biasprm="0.75 1.05 -1 200 0.5 1.6 1.5 1.3 1.2 0"/>
    </default>
    <default class="motor">
      <general gainprm="5 0 0 0 0 0 0 0 0 0"/>
    </default>
  </default>
  <asset>
    <texture type="skybox" builtin="gradient" rgb1="1 1 1" rgb2="0.6 0.8 1" width="256" height="1536"/>
    <mesh name="ground_geom_1_treadmill" file="Geometry/treadmill.stl"/>
    <mesh name="pelvis_geom_1_sacrum" file="Geometry/sacrum.stl"/>
    <mesh name="pelvis_geom_2_pelvis" file="Geometry/pelvis.stl"/>
    <mesh name="pelvis_geom_3_l_pelvis" file="Geometry/l_pelvis.stl"/>
    <mesh name="femur_r_geom_1_femur_r" file="Geometry/femur_r.stl"/>
    <mesh name="tibia_r_geom_1_tibia_r" file="Geometry/tibia_r.stl"/>
    <mesh name="tibia_r_geom_2_fibula" file="Geometry/fibula.stl"/>
    <mesh name="talus_r_geom_1_talus" file="Geometry/talus.stl"/>
    <mesh name="calcn_r_geom_1_foot" file="Geometry/foot.stl"/>
    <mesh name="toes_r_geom_1_bofoot" file="Geometry/bofoot.stl"/>
    <mesh name="femur_l_geom_1_femur_l" file="Geometry/femur_l.stl"/>
    <mesh name="tibia_l_geom_1_tibia_l" file="Geometry/tibia_l.stl"/>
    <mesh name="tibia_l_geom_2_l_fibula" file="Geometry/l_fibula.stl"/>
    <mesh name="AnkleAssembly_geom_1_AnkleAssembly" file="Geometry/AnkleAssembly.stl"/>
    <mesh name="Foot_geom_1_Foot_Amp" file="Geometry/Foot_Amp.stl"/>
    <mesh name="torso_geom_1_hat_spine" file="Geometry/hat_spine.stl"/>
    <mesh name="torso_geom_2_hat_jaw" file="Geometry/hat_jaw.stl"/>
    <mesh name="torso_geom_3_hat_skull" file="Geometry/hat_skull.stl"/>
    <mesh name="torso_geom_4_hat_ribs" file="Geometry/hat_ribs.stl"/>
  </asset>
  <worldbody>
    <light pos="0 0 0" dir="0 0 -1" directional="true"/>
    <body name="ground" quat="0.707035 0.707179 0 0">
      <geom name="ground-plane" size="10 10 0.125" quat="0.707035 -0.707179 0 0" type="plane" rgba="1 0.7 0.4 1"/>
      <geom name="ground_geom_1" type="mesh" rgba="1 1 1 0" mesh="ground_geom_1_treadmill"/>
    </body>
    <body name="pelvis" quat="0.707035 0.707179 0 0">
      <inertial pos="-0.0707 0 0" mass="11.777" diaginertia="0.1028 0.0871 0.0579"/>
      <joint name="pelvis_tx" pos="0 0 0" axis="1 0 0" limited="false" type="slide" range="-5 5" damping="0"/>
      <joint name="pelvis_ty" pos="0 0 0" axis="0 1 0" limited="false" type="slide" range="-1 2" damping="0" user="0.95"/>
      <joint name="pelvis_tz" pos="0 0 0" axis="0 0 1" limited="false" type="slide" range="-3 3" damping="0"/>
      <joint name="pelvis_tilt" pos="0 0 0" axis="0 0 1" limited="false" range="-1.571 1.571" damping="0"/>
      <joint name="pelvis_list" pos="0 0 0" axis="1 0 0" limited="false" range="-1.571 1.571" damping="0"/>
      <joint name="pelvis_rotation" pos="0 0 0" axis="0 1 0" limited="false" range="-1.571 1.571" damping="0"/>
      <geom name="pelvis_geom_1" type="mesh" rgba="1 1 1 1" mesh="pelvis_geom_1_sacrum"/>
      <geom name="pelvis_geom_2" type="mesh" rgba="1 1 1 1" mesh="pelvis_geom_2_pelvis"/>
      <geom name="pelvis_geom_3" type="mesh" rgba="1 1 1 1" mesh="pelvis_geom_3_l_pelvis"/>
      <site name="glut_med1_r_glut_med1_r-P1" pos="-0.0408 0.0304 0.1209"/>
      <site name="glut_med2_r_glut_med2_r-P1" pos="-0.0855 0.0445 0.0766"/>
      <site name="glut_med3_r_glut_med3_r-P1" pos="-0.1223 0.0105 0.0648"/>
      <site name="glut_min1_r_glut_min1_r-P1" pos="-0.0467 -0.008 0.1056"/>
      <site name="glut_min2_r_glut_min2_r-P1" pos="-0.0633 -0.0065 0.0991"/>
      <site name="glut_min3_r_glut_min3_r-P1" pos="-0.0834 -0.0063 0.0856"/>
      <site name="semimem_r_semimem_r-P1" pos="-0.1192 -0.09747 0.07151"/>
      <site name="semiten_r_semiten_r-P1" pos="-0.12635 -0.10988 0.06039"/>
      <site name="bifemlh_r_bifemlh_r-P1" pos="-0.12596 -0.10257 0.06944"/>
      <site name="sar_r_sar_r-P1" pos="-0.0153 -0.0013 0.1242"/>
      <site name="add_long_r_add_long_r-P1" pos="-0.0316 -0.0836 0.0169"/>
      <site name="add_brev_r_add_brev_r-P1" pos="-0.0587 -0.0915 0.0164"/>
      <site name="add_mag1_r_add_mag1_r-P1" pos="-0.0732 -0.1174 0.0255"/>
      <site name="add_mag2_r_add_mag2_r-P1" pos="-0.0831 -0.1192 0.0308"/>
      <site name="add_mag3_r_add_mag3_r-P1" pos="-0.11108 -0.11413 0.04882"/>
      <site name="tfl_r_tfl_r-P1" pos="-0.0311 0.0214 0.1241"/>
      <site name="pect_r_pect_r-P1" pos="-0.0431 -0.0768 0.0451"/>
      <site name="grac_r_grac_r-P1" pos="-0.07401 -0.1187 0.02794"/>
      <site name="glut_max1_r_glut_max1_r-P1" pos="-0.1195 0.0612 0.07"/>
      <site name="glut_max1_r_glut_max1_r-P2" pos="-0.1291 0.0012 0.0886"/>
      <site name="glut_max2_r_glut_max2_r-P1" pos="-0.1349 0.0176 0.0563"/>
      <site name="glut_max2_r_glut_max2_r-P2" pos="-0.1376 -0.052 0.0914"/>
      <site name="glut_max3_r_glut_max3_r-P1" pos="-0.1556 -0.0314 0.0058"/>
      <site name="glut_max3_r_glut_max3_r-P2" pos="-0.1529 -0.1052 0.0403"/>
      <site name="iliacus_r_iliacus_r-P1" pos="-0.0674 0.0365 0.0854"/>
      <site name="iliacus_r_iliacus_r-P2" pos="-0.0258 -0.055 0.0811"/>
      <site name="psoas_r_psoas_r-P1" pos="-0.0647 0.0887 0.0289"/>
      <site name="psoas_r_psoas_r-P2" pos="-0.0238 -0.057 0.0759"/>
      <site name="quad_fem_r_quad_fem_r-P1" pos="-0.1143 -0.1151 0.052"/>
      <site name="gem_r_gem_r-P1" pos="-0.1133 -0.082 0.0714"/>
      <site name="peri_r_peri_r-P1" pos="-0.1396 0.0003 0.0235"/>
      <site name="peri_r_peri_r-P2" pos="-0.1193 -0.0276 0.0657"/>
      <site name="rect_fem_r_rect_fem_r-P1" pos="-0.0295 -0.0311 0.0968"/>
      <site name="glut_med1_l_glut_med1_l-P1" pos="-0.0408 0.0304 -0.1209"/>
      <site name="glut_med2_l_glut_med2_l-P1" pos="-0.0855 0.0445 -0.0766"/>
      <site name="glut_med3_l_glut_med3_l-P1" pos="-0.1223 0.0105 -0.0648"/>
      <site name="glut_min1_l_glut_min1_l-P1" pos="-0.0467 -0.008 -0.1056"/>
      <site name="glut_min2_l_glut_min2_l-P1" pos="-0.0633 -0.0065 -0.0991"/>
      <site name="glut_min3_l_glut_min3_l-P1" pos="-0.0834 -0.0063 -0.0856"/>
      <site name="semimem_l_semimem_l-P1" pos="-0.1192 -0.09747 -0.07151"/>
      <site name="semiten_l_semiten_l-P1" pos="-0.12635 -0.10988 -0.06039"/>
      <site name="bifemlh_l_bifemlh_l-P1" pos="-0.12596 -0.10257 -0.06944"/>
      <site name="sar_l_sar_l-P1" pos="-0.0153 -0.0013 -0.1242"/>
      <site name="add_long_l_add_long_l-P1" pos="-0.0316 -0.0836 -0.0169"/>
      <site name="add_brev_l_add_brev_l-P1" pos="-0.0587 -0.0915 -0.0164"/>
      <site name="add_mag1_l_add_mag1_l-P1" pos="-0.0732 -0.1174 -0.0255"/>
      <site name="add_mag2_l_add_mag2_l-P1" pos="-0.0831 -0.1192 -0.0308"/>
      <site name="add_mag3_l_add_mag3_l-P1" pos="-0.11108 -0.11413 -0.04882"/>
      <site name="pect_l_pect_l-P1" pos="-0.0431 -0.0768 -0.0451"/>
      <site name="glut_max1_l_glut_max1_l-P1" pos="-0.1195 0.0612 -0.07"/>
      <site name="glut_max1_l_glut_max1_l-P2" pos="-0.1291 0.0012 -0.0886"/>
      <site name="glut_max2_l_glut_max2_l-P1" pos="-0.1349 0.0176 -0.0563"/>
      <site name="glut_max2_l_glut_max2_l-P2" pos="-0.1376 -0.052 -0.0914"/>
      <site name="glut_max3_l_glut_max3_l-P1" pos="-0.1556 -0.0314 -0.0058"/>
      <site name="glut_max3_l_glut_max3_l-P2" pos="-0.1529 -0.1052 -0.0403"/>
      <site name="iliacus_l_iliacus_l-P1" pos="-0.0674 0.0365 -0.0854"/>
      <site name="iliacus_l_iliacus_l-P2" pos="-0.0258 -0.055 -0.0811"/>
      <site name="psoas_l_psoas_l-P1" pos="-0.0647 0.0887 -0.0289"/>
      <site name="psoas_l_psoas_l-P2" pos="-0.0238 -0.057 -0.0759"/>
      <site name="quad_fem_l_quad_fem_l-P1" pos="-0.1143 -0.1151 -0.052"/>
      <site name="gem_l_gem_l-P1" pos="-0.1133 -0.082 -0.0714"/>
      <site name="peri_l_peri_l-P1" pos="-0.1396 0.0003 -0.0235"/>
      <site name="peri_l_peri_l-P2" pos="-0.1193 -0.0276 -0.0657"/>
      <site name="rect_fem_l_rect_fem_l-P1" pos="-0.0295 -0.0311 0.0968"/>
      <site name="ercspn_r_ercspn_r-P1" pos="-0.14 0.0439 0.0436"/>
      <site name="ercspn_l_ercspn_l-P1" pos="-0.14 0.0439 -0.0436"/>
      <site name="intobl_r_intobl_r-P1" pos="-0.04 0.07 0.1157"/>
      <site name="intobl_l_intobl_l-P1" pos="-0.04 0.07 -0.1157"/>
      <site name="extobl_r_extobl_r-P1" pos="-0.03 -0.0636 0.01"/>
      <site name="extobl_l_extobl_l-P1" pos="-0.03 -0.0636 -0.01"/>
      <body name="femur_r" pos="-0.0707 -0.0661 0.0835">
        <inertial pos="0 -0.17 0" quat="0.5 0.5 -0.5 0.5" mass="9.3014" diaginertia="0.1412 0.1339 0.0351"/>
        <joint name="hip_flexion_r" pos="0 0 0" axis="0 0 1" limited="false" range="-2.094 2.094"/>
        <joint name="hip_adduction_r" pos="0 0 0" axis="1 0 0" limited="false" range="-2.094 2.094"/>
        <joint name="hip_rotation_r" pos="0 0 0" axis="0 1 0" limited="false" range="-2.094 2.094"/>
        <geom name="femur_r_geom_1" type="mesh" rgba="1 1 1 1" mesh="femur_r_geom_1_femur_r"/>
        <site name="glut_med1_r_glut_med1_r-P2" pos="-0.0218 -0.0117 0.0555"/>
        <site name="glut_med2_r_glut_med2_r-P2" pos="-0.0258 -0.0058 0.0527"/>
        <site name="glut_med3_r_glut_med3_r-P2" pos="-0.0309 -0.0047 0.0518"/>
        <site name="glut_min1_r_glut_min1_r-P2" pos="-0.0072 -0.0104 0.056"/>
        <site name="glut_min2_r_glut_min2_r-P2" pos="-0.0096 -0.0104 0.056"/>
        <site name="glut_min3_r_glut_min3_r-P2" pos="-0.0135 -0.0083 0.055"/>
        <site name="bifemsh_r_bifemsh_r-P1" pos="0.005 -0.2111 0.0234"/>
        <site name="sar_r_sar_r-P2" pos="-0.003 -0.3568 -0.0421"/>
        <site name="add_long_r_add_long_r-P2" pos="0.005 -0.2111 0.0234"/>
        <site name="add_brev_r_add_brev_r-P2" pos="0.0009 -0.1196 0.0294"/>
        <site name="add_mag1_r_add_mag1_r-P2" pos="-0.0045 -0.1211 0.0339"/>
        <site name="add_mag2_r_add_mag2_r-P2" pos="0.0054 -0.2285 0.0227"/>
        <site name="add_mag3_r_add_mag3_r-P2" pos="0.007 -0.3837 -0.0266"/>
        <site name="tfl_r_tfl_r-P2" pos="0.0294 -0.0995 0.0597"/>
        <site name="tfl_r_tfl_r-P3" pos="0.0054 -0.4049 0.0357"/>
        <site name="pect_r_pect_r-P2" pos="-0.0122 -0.0822 0.0253"/>
        <site name="glut_max1_r_glut_max1_r-P3" pos="-0.0457 -0.0248 0.0392"/>
        <site name="glut_max1_r_glut_max1_r-P4" pos="-0.0277 -0.0566 0.047"/>
        <site name="glut_max2_r_glut_max2_r-P3" pos="-0.0426 -0.053 0.0293"/>
        <site name="glut_max2_r_glut_max2_r-P4" pos="-0.0156 -0.1016 0.0419"/>
        <site name="glut_max3_r_glut_max3_r-P3" pos="-0.0299 -0.1041 0.0135"/>
        <site name="glut_max3_r_glut_max3_r-P4" pos="-0.006 -0.1419 0.0411"/>
        <site name="iliacus_r_iliacus_r-P4" pos="0.0017 -0.0543 0.0057"/>
        <site name="iliacus_r_iliacus_r-P5" pos="-0.0193 -0.0621 0.0129"/>
        <site name="psoas_r_psoas_r-P4" pos="0.0016 -0.0507 0.0038"/>
        <site name="psoas_r_psoas_r-P5" pos="-0.0188 -0.0597 0.0104"/>
        <site name="quad_fem_r_quad_fem_r-P2" pos="-0.0381 -0.0359 0.0366"/>
        <site name="gem_r_gem_r-P2" pos="-0.0142 -0.0033 0.0443"/>
        <site name="peri_r_peri_r-P3" pos="-0.0148 -0.0036 0.0437"/>
        <site name="rect_fem_r_rect_fem_r-P2" pos="0.0334 -0.403 0.0019"/>
        <site name="vas_med_r_vas_med_r-P1" pos="0.014 -0.2099 0.0188"/>
        <site name="vas_med_r_vas_med_r-P2" pos="0.0356 -0.2769 0.0009"/>
        <site name="vas_int_r_vas_int_r-P1" pos="0.029 -0.1924 0.031"/>
        <site name="vas_int_r_vas_int_r-P2" pos="0.0335 -0.2084 0.0285"/>
        <site name="vas_lat_r_vas_lat_r-P1" pos="0.0048 -0.1854 0.0349"/>
        <site name="vas_lat_r_vas_lat_r-P2" pos="0.0269 -0.2591 0.0409"/>
        <site name="med_gas_r_med_gas_r-P1" pos="-0.019 -0.3929 -0.0235"/>
        <site name="lat_gas_r_lat_gas_r-P1" pos="-0.022 -0.3946 0.0272"/>
        <site name="vas_med_l_vas_med_l-P3" pos="0.037 -0.4048 -0.0125"/>
        <body name="tibia_r">
          <inertial pos="0 -0.1867 0" quat="0.5 0.5 -0.5 0.5" mass="3.7075" diaginertia="0.0511 0.0504 0.0051"/>
          <joint name="knee_r_translation1" pos="0 0 0" axis="1 0 0" type="slide" range="-0.005574 0.00411" user="-0.00363925"/>
          <joint name="knee_r_translation2" pos="0 0 0" axis="0 1 0" type="slide" range="-0.4226 -0.3953" user="-0.395713"/>
          <joint name="knee_angle_r" pos="0 0 0" axis="0 0 1" limited="false" range="-2.094 0.1745"/>
          <geom name="tibia_r_geom_1" type="mesh" rgba="1 1 1 1" mesh="tibia_r_geom_1_tibia_r"/>
          <geom name="tibia_r_geom_2" type="mesh" rgba="1 1 1 1" mesh="tibia_r_geom_2_fibula"/>
          <site name="semimem_r_semimem_r-P3" pos="-0.027 -0.04771 -0.01957"/>
          <site name="semiten_r_semiten_r-P3" pos="-0.03322 -0.05282 -0.02288"/>
          <site name="semiten_r_semiten_r-P4" pos="-0.0113 -0.0746 -0.0245"/>
          <site name="semiten_r_semiten_r-P5" pos="0.0027 -0.0956 -0.0193"/>
          <site name="bifemlh_r_bifemlh_r-P2" pos="-0.0301 -0.036 0.02943"/>
          <site name="bifemlh_r_bifemlh_r-P3" pos="-0.0234 -0.0563 0.0343"/>
          <site name="bifemsh_r_bifemsh_r-P2" pos="-0.0301 -0.036 0.02943"/>
          <site name="bifemsh_r_bifemsh_r-P3" pos="-0.0234 -0.0563 0.0343"/>
          <site name="sar_r_sar_r-P3" pos="-0.0056 -0.0419 -0.0399"/>
          <site name="sar_r_sar_r-P4" pos="0.006 -0.0589 -0.0383"/>
          <site name="sar_r_sar_r-P5" pos="0.0243 -0.084 -0.0252"/>
          <site name="tfl_r_tfl_r-P4" pos="0.006 -0.0487 0.0297"/>
          <site name="grac_r_grac_r-P3" pos="-0.01943 -0.05153 -0.0358"/>
          <site name="grac_r_grac_r-P4" pos="0.006 -0.0836 -0.0228"/>
          <site name="soleus_r_soleus_r-P1" pos="-0.0024 -0.1533 0.0071"/>
          <site name="tib_post_r_tib_post_r-P1" pos="-0.0094 -0.1348 0.0019"/>
          <site name="tib_post_r_tib_post_r-P2" pos="-0.0144 -0.4051 -0.0229"/>
          <site name="flex_dig_r_flex_dig_r-P1" pos="-0.0083 -0.2046 -0.0018"/>
          <site name="flex_dig_r_flex_dig_r-P2" pos="-0.0154 -0.4051 -0.0196"/>
          <site name="flex_hal_r_flex_hal_r-P1" pos="-0.0079 -0.2334 0.0244"/>
          <site name="flex_hal_r_flex_hal_r-P2" pos="-0.0186 -0.4079 -0.0174"/>
          <site name="tib_ant_r_tib_ant_r-P1" pos="0.0179 -0.1624 0.0115"/>
          <site name="tib_ant_r_tib_ant_r-P2" pos="0.0329 -0.3951 -0.0177"/>
          <site name="per_brev_r_per_brev_r-P1" pos="-0.007 -0.2646 0.0325"/>
          <site name="per_brev_r_per_brev_r-P2" pos="-0.0198 -0.4184 0.0283"/>
          <site name="per_brev_r_per_brev_r-P3" pos="-0.0144 -0.4295 0.0289"/>
          <site name="per_long_r_per_long_r-P1" pos="0.0005 -0.1568 0.0362"/>
          <site name="per_long_r_per_long_r-P2" pos="-0.0207 -0.4205 0.0286"/>
          <site name="per_long_r_per_long_r-P3" pos="-0.0162 -0.4319 0.0289"/>
          <site name="per_tert_r_per_tert_r-P1" pos="0.001 -0.2804 0.0231"/>
          <site name="per_tert_r_per_tert_r-P2" pos="0.0229 -0.4069 0.0159"/>
          <site name="ext_dig_r_ext_dig_r-P1" pos="0.0032 -0.1381 0.0276"/>
          <site name="ext_dig_r_ext_dig_r-P2" pos="0.0289 -0.4007 0.0072"/>
          <site name="ext_hal_r_ext_hal_r-P1" pos="0.0012 -0.1767 0.0228"/>
          <site name="ext_hal_r_ext_hal_r-P2" pos="0.0326 -0.3985 -0.0085"/>
          <body name="talus_r" pos="0 -0.43 0">
            <inertial pos="0 0 0" mass="0.1" diaginertia="0.001 0.001 0.001"/>
            <joint name="ankle_angle_r" pos="0 0 0" axis="-0.105003 -0.174005 0.979131" limited="false" range="-1.571 1.571"/>
            <geom name="talus_r_geom_1" type="mesh" rgba="1 1 1 1" mesh="talus_r_geom_1_talus"/>
            <body name="calcn_r" pos="-0.04877 -0.04195 0.00792">
              <inertial pos="0.1 0.03 0" quat="0 0.707107 0 0.707107" mass="1.25" diaginertia="0.0041 0.0039 0.0014"/>
              <joint name="subtalar_angle_r" pos="0 0 0" axis="0.787215 0.604711 -0.120902" limited="false" range="-1.571 1.571"/>
              <geom name="calcn_r_geom_1" type="mesh" rgba="1 1 1 1" mesh="calcn_r_geom_1_foot"/>
              <site name="med_gas_r_med_gas_r-P3" pos="0 0.031 -0.0053"/>
              <site name="lat_gas_r_lat_gas_r-P3" pos="0 0.031 -0.0053"/>
              <site name="soleus_r_soleus_r-P2" pos="0 0.031 -0.0053"/>
              <site name="tib_post_r_tib_post_r-P3" pos="0.0417 0.0334 -0.0286"/>
              <site name="tib_post_r_tib_post_r-P4" pos="0.0772 0.0159 -0.0281"/>
              <site name="flex_dig_r_flex_dig_r-P3" pos="0.0436 0.0315 -0.028"/>
              <site name="flex_dig_r_flex_dig_r-P4" pos="0.0708 0.0176 -0.0263"/>
              <site name="flex_dig_r_flex_dig_r-P5" pos="0.1658 -0.0081 0.0116"/>
              <site name="flex_hal_r_flex_hal_r-P3" pos="0.0374 0.0276 -0.0241"/>
              <site name="flex_hal_r_flex_hal_r-P4" pos="0.1038 0.0068 -0.0256"/>
              <site name="flex_hal_r_flex_hal_r-P5" pos="0.1726 -0.0053 -0.0269"/>
              <site name="tib_ant_r_tib_ant_r-P3" pos="0.1166 0.0178 -0.0305"/>
              <site name="per_brev_r_per_brev_r-P4" pos="0.0471 0.027 0.0233"/>
              <site name="per_brev_r_per_brev_r-P5" pos="0.0677 0.0219 0.0343"/>
              <site name="per_long_r_per_long_r-P4" pos="0.0438 0.023 0.0221"/>
              <site name="per_long_r_per_long_r-P5" pos="0.0681 0.0106 0.0284"/>
              <site name="per_long_r_per_long_r-P6" pos="0.0852 0.0069 0.0118"/>
              <site name="per_long_r_per_long_r-P7" pos="0.1203 0.0085 -0.0184"/>
              <site name="per_tert_r_per_tert_r-P3" pos="0.0857 0.0228 0.0299"/>
              <site name="ext_dig_r_ext_dig_r-P3" pos="0.0922 0.0388 -0.0001"/>
              <site name="ext_dig_r_ext_dig_r-P4" pos="0.1616 0.0055 0.013"/>
              <site name="ext_hal_r_ext_hal_r-P3" pos="0.097 0.0389 -0.0211"/>
              <site name="ext_hal_r_ext_hal_r-P4" pos="0.1293 0.0309 -0.0257"/>
              <site name="ext_hal_r_ext_hal_r-P5" pos="0.1734 0.0139 -0.028"/>
              <body name="toes_r" pos="0.1788 -0.002 0.00108">
                <inertial pos="0.0346 0.006 -0.0175" quat="0.707107 0 0 0.707107" mass="0.2166" diaginertia="0.001 0.001 0.001"/>
                <joint name="mtp_angle_r" pos="0 0 0" axis="-0.581002 0 0.813902" limited="false" range="-1.571 1.571"/>
                <geom name="toes_r_geom_1" type="mesh" rgba="1 1 1 1" mesh="toes_r_geom_1_bofoot"/>
                <site name="flex_dig_r_flex_dig_r-P6" pos="-0.0019 -0.0078 0.0147"/>
                <site name="flex_dig_r_flex_dig_r-P7" pos="0.0285 -0.0071 0.0215"/>
                <site name="flex_dig_r_flex_dig_r-P8" pos="0.0441 -0.006 0.0242"/>
                <site name="flex_hal_r_flex_hal_r-P6" pos="0.0155 -0.0064 -0.0265"/>
                <site name="flex_hal_r_flex_hal_r-P7" pos="0.0562 -0.0102 -0.0181"/>
                <site name="ext_dig_r_ext_dig_r-P5" pos="0.0003 0.0047 0.0153"/>
                <site name="ext_dig_r_ext_dig_r-P6" pos="0.0443 -0.0004 0.025"/>
                <site name="ext_hal_r_ext_hal_r-P6" pos="0.0298 0.0041 -0.0245"/>
                <site name="ext_hal_r_ext_hal_r-P7" pos="0.0563 0.0034 -0.0186"/>
              </body>
            </body>
          </body>
          <body name="semimem_r_semimem_r-P2" pos="0 0 -0.01957">
            <joint name="semimem_r_semimem_r-P2_x" pos="0 0 0" axis="1 0 0" type="slide" range="-0.0348 -0.027"/>
            <joint name="semimem_r_semimem_r-P2_y" pos="0 0 0" axis="0 1 0" type="slide" range="-0.04771 -0.03519"/>
            <geom size="0.0005" contype="2" conaffinity="2" rgba="0 0 1 0"/>
            <site name="semimem_r_semimem_r-P2" pos="0 0 0"/>
          </body>
          <body name="semiten_r_semiten_r-P2" pos="0 0 -0.02288">
            <joint name="semiten_r_semiten_r-P2_x" pos="0 0 0" axis="1 0 0" type="slide" range="-0.04203 -0.03322"/>
            <joint name="semiten_r_semiten_r-P2_y" pos="0 0 0" axis="0 1 0" type="slide" range="-0.05282 -0.02859"/>
            <geom size="0.0005" contype="2" conaffinity="2" rgba="0 0 1 0"/>
            <site name="semiten_r_semiten_r-P2" pos="0 0 0"/>
          </body>
          <body name="grac_r_grac_r-P2">
            <joint name="grac_r_grac_r-P2_x" pos="0 0 0" axis="1 0 0" type="slide" range="-0.02657 -0.01943"/>
            <joint name="grac_r_grac_r-P2_y" pos="0 0 0" axis="0 1 0" type="slide" range="-0.05153 -0.0319"/>
            <joint name="grac_r_grac_r-P2_z" pos="0 0 0" axis="0 0 1" type="slide" range="-0.03774 -0.0358"/>
            <geom size="0.0005" contype="2" conaffinity="2" rgba="0 0 1 0"/>
            <site name="grac_r_grac_r-P2" pos="0 0 0"/>
          </body>
          <body name="rect_fem_r_rect_fem_r-P3" pos="0 0 0.001399">
            <joint name="rect_fem_r_rect_fem_r-P3_x" pos="0 0 0" axis="1 0 0" type="slide" range="0.01558 0.0733"/>
            <joint name="rect_fem_r_rect_fem_r-P3_y" pos="0 0 0" axis="0 1 0" type="slide" range="-0.06738 0.02531"/>
            <geom size="0.0005" contype="2" conaffinity="2" rgba="0 0 1 0"/>
            <site name="rect_fem_r_rect_fem_r-P3" pos="0 0 0"/>
          </body>
          <body name="vas_med_r_vas_med_r-P5" pos="0 0 -0.0146">
            <joint name="vas_med_r_vas_med_r-P5_x" pos="0 0 0" axis="1 0 0" type="slide" range="0.009811 0.06795"/>
            <joint name="vas_med_r_vas_med_r-P5_y" pos="0 0 0" axis="0 1 0" type="slide" range="-0.06562 0.02433"/>
            <geom size="0.0005" contype="2" conaffinity="2" rgba="0 0 1 0"/>
            <site name="vas_med_r_vas_med_r-P5" pos="0 0 0"/>
          </body>
          <body name="vas_int_r_vas_int_r-P4" pos="0 0 0.001799">
            <joint name="vas_int_r_vas_int_r-P4_x" pos="0 0 0" axis="1 0 0" type="slide" range="0.008273 0.06844"/>
            <joint name="vas_int_r_vas_int_r-P4_y" pos="0 0 0" axis="0 1 0" type="slide" range="-0.06857 0.02752"/>
            <geom size="0.0005" contype="2" conaffinity="2" rgba="0 0 1 0"/>
            <site name="vas_int_r_vas_int_r-P4" pos="0 0 0"/>
          </body>
          <body name="vas_lat_r_vas_lat_r-P5" pos="0 0 0.0165">
            <joint name="vas_lat_r_vas_lat_r-P5_x" pos="0 0 0" axis="1 0 0" type="slide" range="0.01429 0.07119"/>
            <joint name="vas_lat_r_vas_lat_r-P5_y" pos="0 0 0" axis="0 1 0" type="slide" range="-0.06534 0.02344"/>
            <geom size="0.0005" contype="2" conaffinity="2" rgba="0 0 1 0"/>
            <site name="vas_lat_r_vas_lat_r-P5" pos="0 0 0"/>
          </body>
        </body>
        <body name="vas_med_r_vas_med_r-P3">
          <joint name="vas_med_r_vas_med_r-P3_x" pos="0 0 0" axis="1 0 0" type="slide" range="0.0356 0.037"/>
          <joint name="vas_med_r_vas_med_r-P3_y" pos="0 0 0" axis="0 1 0" type="slide" range="-0.4048 -0.2769"/>
          <joint name="vas_med_r_vas_med_r-P3_z" pos="0 0 0" axis="0 0 1" type="slide" range="-0.0125 0.0009"/>
          <geom size="0.0005" contype="2" conaffinity="2" rgba="0 0 1 0"/>
          <site name="vas_med_r_vas_med_r-P3" pos="0 0 0"/>
        </body>
        <body name="vas_med_r_vas_med_r-P4">
          <joint name="vas_med_r_vas_med_r-P4_x" pos="0 0 0" axis="1 0 0" type="slide" range="0.0274 0.0356"/>
          <joint name="vas_med_r_vas_med_r-P4_y" pos="0 0 0" axis="0 1 0" type="slide" range="-0.4255 -0.2769"/>
          <joint name="vas_med_r_vas_med_r-P4_z" pos="0 0 0" axis="0 0 1" type="slide" range="-0.0131 0.0009"/>
          <geom size="0.0005" contype="2" conaffinity="2" rgba="0 0 1 0"/>
          <site name="vas_med_r_vas_med_r-P4" pos="0 0 0"/>
        </body>
        <body name="vas_int_r_vas_int_r-P3" pos="0.0335 0 0">
          <joint name="vas_int_r_vas_int_r-P3_y" pos="0 0 0" axis="0 1 0" type="slide" range="-0.403 -0.2084"/>
          <joint name="vas_int_r_vas_int_r-P3_z" pos="0 0 0" axis="0 0 1" type="slide" range="0.0055 0.0285"/>
          <geom size="0.0005" contype="2" conaffinity="2" rgba="0 0 1 0"/>
          <site name="vas_int_r_vas_int_r-P3" pos="0 0 0"/>
        </body>
        <body name="vas_lat_r_vas_lat_r-P3">
          <joint name="vas_lat_r_vas_lat_r-P3_x" pos="0 0 0" axis="1 0 0" type="slide" range="0.0269 0.0361"/>
          <joint name="vas_lat_r_vas_lat_r-P3_y" pos="0 0 0" axis="0 1 0" type="slide" range="-0.403 -0.2591"/>
          <joint name="vas_lat_r_vas_lat_r-P3_z" pos="0 0 0" axis="0 0 1" type="slide" range="0.0205 0.0409"/>
          <geom size="0.0005" contype="2" conaffinity="2" rgba="0 0 1 0"/>
          <site name="vas_lat_r_vas_lat_r-P3" pos="0 0 0"/>
        </body>
        <body name="vas_lat_r_vas_lat_r-P4">
          <joint name="vas_lat_r_vas_lat_r-P4_x" pos="0 0 0" axis="1 0 0" type="slide" range="0.0253 0.0269"/>
          <joint name="vas_lat_r_vas_lat_r-P4_y" pos="0 0 0" axis="0 1 0" type="slide" range="-0.4243 -0.2591"/>
          <joint name="vas_lat_r_vas_lat_r-P4_z" pos="0 0 0" axis="0 0 1" type="slide" range="0.0184 0.0409"/>
          <geom size="0.0005" contype="2" conaffinity="2" rgba="0 0 1 0"/>
          <site name="vas_lat_r_vas_lat_r-P4" pos="0 0 0"/>
        </body>
        <body name="med_gas_r_med_gas_r-P2">
          <joint name="med_gas_r_med_gas_r-P2_x" pos="0 0 0" axis="1 0 0" type="slide" range="-0.03 -0.019"/>
          <joint name="med_gas_r_med_gas_r-P2_y" pos="0 0 0" axis="0 1 0" type="slide" range="-0.4022 -0.3929"/>
          <joint name="med_gas_r_med_gas_r-P2_z" pos="0 0 0" axis="0 0 1" type="slide" range="-0.0258 -0.0235"/>
          <geom size="0.0005" contype="2" conaffinity="2" rgba="0 0 1 0"/>
          <site name="med_gas_r_med_gas_r-P2" pos="0 0 0"/>
        </body>
        <body name="lat_gas_r_lat_gas_r-P2" pos="0 0 0.0272">
          <joint name="lat_gas_r_lat_gas_r-P2_x" pos="0 0 0" axis="1 0 0" type="slide" range="-0.03 -0.022"/>
          <joint name="lat_gas_r_lat_gas_r-P2_y" pos="0 0 0" axis="0 1 0" type="slide" range="-0.4018 -0.3946"/>
          <geom size="0.0005" contype="2" conaffinity="2" rgba="0 0 1 0"/>
          <site name="lat_gas_r_lat_gas_r-P2" pos="0 0 0"/>
        </body>
      </body>
      <body name="femur_l" pos="-0.0707 -0.0661 -0.0835">
        <inertial pos="0 -0.17 0" quat="0.5 0.5 -0.5 0.5" mass="9.3014" diaginertia="0.1412 0.1339 0.0351"/>
        <joint name="hip_flexion_l" pos="0 0 0" axis="0 0 1" limited="false" range="-2.094 2.094"/>
        <joint name="hip_adduction_l" pos="0 0 0" axis="-1 0 0" limited="false" range="-2.094 2.094"/>
        <joint name="hip_rotation_l" pos="0 0 0" axis="0 -1 0" limited="false" range="-2.094 2.094"/>
        <geom name="femur_l_geom_1" type="mesh" rgba="1 1 1 1" mesh="femur_l_geom_1_femur_l"/>
        <site name="glut_med1_l_glut_med1_l-P2" pos="-0.0218 -0.0117 -0.0555"/>
        <site name="glut_med2_l_glut_med2_l-P2" pos="-0.0258 -0.0058 -0.0527"/>
        <site name="glut_med3_l_glut_med3_l-P2" pos="-0.0309 -0.0047 -0.0518"/>
        <site name="glut_min1_l_glut_min1_l-P2" pos="-0.0072 -0.0104 -0.056"/>
        <site name="glut_min2_l_glut_min2_l-P2" pos="-0.0096 -0.0104 -0.056"/>
        <site name="glut_min3_l_glut_min3_l-P2" pos="-0.0135 -0.0083 -0.055"/>
        <site name="bifemsh_l_bifemsh_l-P1" pos="0.005 -0.2111 -0.0234"/>
        <site name="sar_l_sar_l-P2" pos="-0.003 -0.3568 0.0421"/>
        <site name="add_long_l_add_long_l-P2" pos="0.005 -0.2111 -0.0234"/>
        <site name="add_brev_l_add_brev_l-P2" pos="0.0009 -0.1196 -0.0294"/>
        <site name="add_mag1_l_add_mag1_l-P2" pos="-0.0045 -0.1211 -0.0339"/>
        <site name="add_mag2_l_add_mag2_l-P2" pos="0.0054 -0.2285 -0.0227"/>
        <site name="add_mag3_l_add_mag3_l-P2" pos="0.007 -0.3837 0.0266"/>
        <site name="pect_l_pect_l-P2" pos="-0.0122 -0.0822 -0.0253"/>
        <site name="glut_max1_l_glut_max1_l-P3" pos="-0.0457 -0.0248 -0.0392"/>
        <site name="glut_max1_l_glut_max1_l-P4" pos="-0.0277 -0.0566 -0.047"/>
        <site name="glut_max2_l_glut_max2_l-P3" pos="-0.0426 -0.053 -0.0293"/>
        <site name="glut_max2_l_glut_max2_l-P4" pos="-0.0156 -0.1016 -0.0419"/>
        <site name="glut_max3_l_glut_max3_l-P3" pos="-0.0299 -0.1041 -0.0135"/>
        <site name="glut_max3_l_glut_max3_l-P4" pos="-0.006 -0.1419 -0.0411"/>
        <site name="iliacus_l_iliacus_l-P4" pos="0.0017 -0.0543 -0.0057"/>
        <site name="iliacus_l_iliacus_l-P5" pos="-0.0193 -0.0621 -0.0129"/>
        <site name="psoas_l_psoas_l-P4" pos="0.0016 -0.0507 -0.0038"/>
        <site name="psoas_l_psoas_l-P5" pos="-0.0188 -0.0597 -0.0104"/>
        <site name="quad_fem_l_quad_fem_l-P2" pos="-0.0381 -0.0359 -0.0366"/>
        <site name="gem_l_gem_l-P2" pos="-0.0142 -0.0033 -0.0443"/>
        <site name="peri_l_peri_l-P3" pos="-0.0148 -0.0036 -0.0437"/>
        <site name="rect_fem_l_rect_fem_l-P2" pos="0.0334 -0.403 0.0019"/>
        <site name="vas_med_l_vas_med_l-P1" pos="0.014 -0.2099 0.0188"/>
        <site name="vas_med_l_vas_med_l-P2" pos="0.0356 -0.2769 0.0009"/>
        <site name="vas_int_l_vas_int_l-P1" pos="0.029 -0.1924 0.031"/>
        <site name="vas_int_l_vas_int_l-P2" pos="0.0335 -0.2084 0.0285"/>
        <site name="vas_lat_l_vas_lat_l-P1" pos="0.0048 -0.1854 0.0349"/>
        <site name="vas_lat_l_vas_lat_l-P2" pos="0.0269 -0.2591 0.0409"/>
        <body name="tibia_l">
          <inertial pos="0 -0.1867 0" quat="0.5 0.5 -0.5 0.5" mass="3.7075" diaginertia="0.0511 0.0504 0.0051"/>
          <joint name="knee_l_translation1" pos="0 0 0" axis="1 0 0" type="slide" range="-0.005574 0.00411" user="-0.00363925"/>
          <joint name="knee_l_translation2" pos="0 0 0" axis="0 1 0" type="slide" range="-0.4226 -0.3953" user="-0.395713"/>
          <joint name="knee_angle_l" pos="0 0 0" axis="0 0 1" limited="false" range="-2.094 0.1745"/>
          <geom name="tibia_l_geom_1" type="mesh" rgba="1 1 1 1" mesh="tibia_l_geom_1_tibia_l"/>
          <geom name="tibia_l_geom_2" type="mesh" rgba="1 1 1 1" mesh="tibia_l_geom_2_l_fibula"/>
          <site name="semimem_l_semimem_l-P3" pos="-0.027 -0.04771 0.01957"/>
          <site name="semiten_l_semiten_l-P3" pos="-0.03322 -0.05282 0.02288"/>
          <site name="semiten_l_semiten_l-P4" pos="-0.0113 -0.0746 0.0245"/>
          <site name="semiten_l_semiten_l-P5" pos="0.0027 -0.0956 0.0193"/>
          <site name="bifemlh_l_bifemlh_l-P2" pos="-0.0301 -0.036 -0.02943"/>
          <site name="bifemlh_l_bifemlh_l-P3" pos="-0.0234 -0.0563 -0.0343"/>
          <site name="bifemsh_l_bifemsh_l-P2" pos="-0.0301 -0.036 -0.02943"/>
          <site name="bifemsh_l_bifemsh_l-P3" pos="-0.0234 -0.0563 -0.0343"/>
          <site name="sar_l_sar_l-P3" pos="-0.0056 -0.0419 0.0399"/>
          <site name="sar_l_sar_l-P4" pos="0.006 -0.0589 0.0383"/>
          <site name="sar_l_sar_l-P5" pos="0.0243 -0.084 0.0252"/>
          <body name="AnkleAssembly" pos="-0.04 -0.124 -0.05">
            <inertial pos="0.04136 -0.24932 0.04006" quat="0.341335 0.435693 -0.739061 0.383994" mass="1.71" diaginertia="0.00220091 0.00207699 0.0012951"/>
            <geom name="AnkleAssembly_geom_1" type="mesh" rgba="0.87 0.56 0.34 1" mesh="AnkleAssembly_geom_1_AnkleAssembly"/>
            <body name="Foot">
              <inertial pos="0.06215 -0.35314 0.04496" quat="0.130389 0.68448 0.215635 0.684096" mass="0.76" diaginertia="0.00184373 0.001789 0.001"/>
              <joint name="yR_FootToAnkleAssembly" pos="0 0 0" axis="1 -2.654e-06 -7.041e-12" range="-0.8727 0.5236"/>
              <joint name="zR_FootToAnkleAssembly" pos="0 0 0" axis="0 -2.654e-06 1" range="-0.45 0.6"/>
              <geom name="Foot_geom_1" type="mesh" rgba="0.301961 0.301961 0.301961 1" mesh="Foot_geom_1_Foot_Amp"/>
            </body>
          </body>
          <body name="semimem_l_semimem_l-P2" pos="0 0 0.01891">
            <joint name="semimem_l_semimem_l-P2_x" pos="0 0 0" axis="1 0 0" type="slide" range="-0.0348 -0.027"/>
            <joint name="semimem_l_semimem_l-P2_y" pos="0 0 0" axis="0 1 0" type="slide" range="-0.04771 -0.03519"/>
            <geom size="0.0005" contype="2" conaffinity="2" rgba="0 0 1 0"/>
            <site name="semimem_l_semimem_l-P2" pos="0 0 0"/>
          </body>
          <body name="semiten_l_semiten_l-P2" pos="0 0 0.02277">
            <joint name="semiten_l_semiten_l-P2_x" pos="0 0 0" axis="1 0 0" type="slide" range="-0.04203 -0.03322"/>
            <joint name="semiten_l_semiten_l-P2_y" pos="0 0 0" axis="0 1 0" type="slide" range="-0.05282 -0.02859"/>
            <geom size="0.0005" contype="2" conaffinity="2" rgba="0 0 1 0"/>
            <site name="semiten_l_semiten_l-P2" pos="0 0 0"/>
          </body>
          <body name="rect_fem_l_rect_fem_l-P3" pos="0 0 0.001399">
            <joint name="rect_fem_l_rect_fem_l-P3_x" pos="0 0 0" axis="1 0 0" type="slide" range="0.01558 0.0733"/>
            <joint name="rect_fem_l_rect_fem_l-P3_y" pos="0 0 0" axis="0 1 0" type="slide" range="-0.06738 0.02531"/>
            <geom size="0.0005" contype="2" conaffinity="2" rgba="0 0 1 0"/>
            <site name="rect_fem_l_rect_fem_l-P3" pos="0 0 0"/>
          </body>
          <body name="vas_med_l_vas_med_r-P5" pos="0 0 -0.0146">
            <joint name="vas_med_l_vas_med_r-P5_x" pos="0 0 0" axis="1 0 0" type="slide" range="0.009811 0.06795"/>
            <joint name="vas_med_l_vas_med_r-P5_y" pos="0 0 0" axis="0 1 0" type="slide" range="-0.06562 0.02433"/>
            <geom size="0.0005" contype="2" conaffinity="2" rgba="0 0 1 0"/>
            <site name="vas_med_l_vas_med_r-P5" pos="0 0 0"/>
          </body>
          <body name="vas_int_l_vas_int_l-P4" pos="0 0 0.001799">
            <joint name="vas_int_l_vas_int_l-P4_x" pos="0 0 0" axis="1 0 0" type="slide" range="0.008273 0.06844"/>
            <joint name="vas_int_l_vas_int_l-P4_y" pos="0 0 0" axis="0 1 0" type="slide" range="-0.06857 0.02752"/>
            <geom size="0.0005" contype="2" conaffinity="2" rgba="0 0 1 0"/>
            <site name="vas_int_l_vas_int_l-P4" pos="0 0 0"/>
          </body>
          <body name="vas_lat_l_vas_lat_l-P5" pos="0 0 0.0165">
            <joint name="vas_lat_l_vas_lat_l-P5_x" pos="0 0 0" axis="1 0 0" type="slide" range="0.01429 0.07119"/>
            <joint name="vas_lat_l_vas_lat_l-P5_y" pos="0 0 0" axis="0 1 0" type="slide" range="-0.06534 0.02344"/>
            <geom size="0.0005" contype="2" conaffinity="2" rgba="0 0 1 0"/>
            <site name="vas_lat_l_vas_lat_l-P5" pos="0 0 0"/>
          </body>
        </body>
        <body name="vas_med_l_vas_med_r-P4">
          <joint name="vas_med_l_vas_med_r-P4_x" pos="0 0 0" axis="1 0 0" type="slide" range="0.0274 0.0356"/>
          <joint name="vas_med_l_vas_med_r-P4_y" pos="0 0 0" axis="0 1 0" type="slide" range="-0.4255 -0.2769"/>
          <joint name="vas_med_l_vas_med_r-P4_z" pos="0 0 0" axis="0 0 1" type="slide" range="-0.0131 0.0009"/>
          <geom size="0.0005" contype="2" conaffinity="2" rgba="0 0 1 0"/>
          <site name="vas_med_l_vas_med_r-P4" pos="0 0 0"/>
        </body>
        <body name="vas_int_l_vas_int_l-P3" pos="0.0335 0 0">
          <joint name="vas_int_l_vas_int_l-P3_y" pos="0 0 0" axis="0 1 0" type="slide" range="-0.403 -0.2084"/>
          <joint name="vas_int_l_vas_int_l-P3_z" pos="0 0 0" axis="0 0 1" type="slide" range="0.0055 0.0285"/>
          <geom size="0.0005" contype="2" conaffinity="2" rgba="0 0 1 0"/>
          <site name="vas_int_l_vas_int_l-P3" pos="0 0 0"/>
        </body>
        <body name="vas_lat_l_vas_lat_l-P3">
          <joint name="vas_lat_l_vas_lat_l-P3_x" pos="0 0 0" axis="1 0 0" type="slide" range="0.0269 0.0361"/>
          <joint name="vas_lat_l_vas_lat_l-P3_y" pos="0 0 0" axis="0 1 0" type="slide" range="-0.403 -0.2591"/>
          <joint name="vas_lat_l_vas_lat_l-P3_z" pos="0 0 0" axis="0 0 1" type="slide" range="0.0205 0.0409"/>
          <geom size="0.0005" contype="2" conaffinity="2" rgba="0 0 1 0"/>
          <site name="vas_lat_l_vas_lat_l-P3" pos="0 0 0"/>
        </body>
        <body name="vas_lat_l_vas_lat_l-P4">
          <joint name="vas_lat_l_vas_lat_l-P4_x" pos="0 0 0" axis="1 0 0" type="slide" range="0.0253 0.0269"/>
          <joint name="vas_lat_l_vas_lat_l-P4_y" pos="0 0 0" axis="0 1 0" type="slide" range="-0.4243 -0.2591"/>
          <joint name="vas_lat_l_vas_lat_l-P4_z" pos="0 0 0" axis="0 0 1" type="slide" range="0.0184 0.0409"/>
          <geom size="0.0005" contype="2" conaffinity="2" rgba="0 0 1 0"/>
          <site name="vas_lat_l_vas_lat_l-P4" pos="0 0 0"/>
        </body>
      </body>
      <body name="torso" pos="-0.1007 0.0815 0">
        <inertial pos="-0.03 0.32 0" quat="0.707107 0.707107 0 0" mass="34.2366" diaginertia="1.4745 1.4314 0.7555"/>
        <joint name="lumbar_extension" pos="0 0 0" axis="0 0 1" limited="false" range="-1.571 1.571"/>
        <joint name="lumbar_bending" pos="0 0 0" axis="1 0 0" limited="false" range="-1.571 1.571"/>
        <joint name="lumbar_rotation" pos="0 0 0" axis="0 1 0" limited="false" range="-1.571 1.571"/>
        <geom name="torso_geom_1" type="mesh" rgba="1 1 1 1" mesh="torso_geom_1_hat_spine"/>
        <geom name="torso_geom_2" type="mesh" rgba="1 1 1 1" mesh="torso_geom_2_hat_jaw"/>
        <geom name="torso_geom_3" type="mesh" rgba="1 1 1 1" mesh="torso_geom_3_hat_skull"/>
        <geom name="torso_geom_4" type="mesh" rgba="1 1 1 1" mesh="torso_geom_4_hat_ribs"/>
        <site name="ercspn_r_ercspn_r-P2" pos="-0.055 0.11 0.0241"/>
        <site name="ercspn_l_ercspn_l-P2" pos="-0.055 0.11 -0.0241"/>
        <site name="intobl_r_intobl_r-P2" pos="0.07 0.16 0.015"/>
        <site name="intobl_l_intobl_l-P2" pos="0.07 0.16 -0.015"/>
        <site name="extobl_r_extobl_r-P2" pos="0.065 0.11 0.11"/>
        <site name="extobl_l_extobl_l-P2" pos="0.065 0.11 -0.11"/>
      </body>
      <body name="iliacus_r_iliacus_r-P3" pos="0 0 0.0811">
        <joint name="iliacus_r_iliacus_r-P3_x" pos="0 0 0" axis="1 0 0" type="slide" range="-0.0288 -0.0258"/>
        <joint name="iliacus_r_iliacus_r-P3_y" pos="0 0 0" axis="0 1 0" type="slide" range="-0.0805 -0.055"/>
        <geom size="0.0005" contype="2" conaffinity="2" rgba="0 0 1 0"/>
        <site name="iliacus_r_iliacus_r-P3" pos="0 0 0"/>
      </body>
      <body name="psoas_r_psoas_r-P3">
        <joint name="psoas_r_psoas_r-P3_x" pos="0 0 0" axis="1 0 0" type="slide" range="-0.0288 -0.0238"/>
        <joint name="psoas_r_psoas_r-P3_y" pos="0 0 0" axis="0 1 0" type="slide" range="-0.0805 -0.057"/>
        <joint name="psoas_r_psoas_r-P3_z" pos="0 0 0" axis="0 0 1" type="slide" range="0.0759 0.0816"/>
        <geom size="0.0005" contype="2" conaffinity="2" rgba="0 0 1 0"/>
        <site name="psoas_r_psoas_r-P3" pos="0 0 0"/>
      </body>
      <body name="iliacus_l_iliacus_l-P3" pos="0 0 -0.0816">
        <joint name="iliacus_l_iliacus_l-P3_x" pos="0 0 0" axis="1 0 0" type="slide" range="-0.0288 -0.0258"/>
        <joint name="iliacus_l_iliacus_l-P3_y" pos="0 0 0" axis="0 1 0" type="slide" range="-0.0805 -0.055"/>
        <geom size="0.0005" contype="2" conaffinity="2" rgba="0 0 1 0"/>
        <site name="iliacus_l_iliacus_l-P3" pos="0 0 0"/>
      </body>
      <body name="psoas_l_psoas_l-P3">
        <joint name="psoas_l_psoas_l-P3_x" pos="0 0 0" axis="1 0 0" type="slide" range="-0.0288 -0.0238"/>
        <joint name="psoas_l_psoas_l-P3_y" pos="0 0 0" axis="0 1 0" type="slide" range="-0.0805 -0.057"/>
        <joint name="psoas_l_psoas_l-P3_z" pos="0 0 0" axis="0 0 1" type="slide" range="-0.0816 -0.0759"/>
        <geom size="0.0005" contype="2" conaffinity="2" rgba="0 0 1 0"/>
        <site name="psoas_l_psoas_l-P3" pos="0 0 0"/>
      </body>
    </body>
  </worldbody>
  <contact>
    <pair geom1="ground-plane" geom2="pelvis_geom_1"/>
    <pair geom1="ground-plane" geom2="pelvis_geom_2"/>
    <pair geom1="ground-plane" geom2="pelvis_geom_3"/>
    <pair geom1="ground-plane" geom2="femur_r_geom_1"/>
    <pair geom1="ground-plane" geom2="tibia_r_geom_1"/>
    <pair geom1="ground-plane" geom2="tibia_r_geom_2"/>
    <pair geom1="ground-plane" geom2="talus_r_geom_1"/>
    <pair geom1="ground-plane" geom2="calcn_r_geom_1"/>
    <pair geom1="ground-plane" geom2="toes_r_geom_1"/>
    <pair geom1="ground-plane" geom2="femur_l_geom_1"/>
    <pair geom1="ground-plane" geom2="tibia_l_geom_1"/>
    <pair geom1="ground-plane" geom2="tibia_l_geom_2"/>
    <pair geom1="ground-plane" geom2="AnkleAssembly_geom_1"/>
    <pair geom1="ground-plane" geom2="Foot_geom_1"/>
    <pair geom1="ground-plane" geom2="torso_geom_1"/>
    <pair geom1="ground-plane" geom2="torso_geom_2"/>
    <pair geom1="ground-plane" geom2="torso_geom_3"/>
    <pair geom1="ground-plane" geom2="torso_geom_4"/>
  </contact>
  <equality>
    <joint joint1="knee_r_translation1" joint2="knee_angle_r" polycoef="-0.003639 -0.006267 0.002807 0.00134 -0.0006776" solimp="0.9999 0.9999 0.001 0.5 2"/>
    <joint joint1="knee_r_translation2" joint2="knee_angle_r" polycoef="-0.3957 0.003413 -0.005587 0.0006697 0.0005674" solimp="0.9999 0.9999 0.001 0.5 2"/>
    <joint joint1="knee_l_translation1" joint2="knee_angle_l" polycoef="-0.003639 -0.006267 0.002807 0.00134 -0.0006776" solimp="0.9999 0.9999 0.001 0.5 2"/>
    <joint joint1="knee_l_translation2" joint2="knee_angle_l" polycoef="-0.3957 0.003413 -0.005587 0.0006697 0.0005674" solimp="0.9999 0.9999 0.001 0.5 2"/>
    <joint joint1="semimem_r_semimem_r-P2_x" joint2="knee_angle_r" polycoef="-0.0342 -0.003438 0 0 0" solimp="0.9999 0.9999 0.001 0.5 2"/>
    <joint joint1="semimem_r_semimem_r-P2_y" joint2="knee_angle_r" polycoef="-0.03615 0.005519 0 0 0" solimp="0.9999 0.9999 0.001 0.5 2"/>
    <joint joint1="semiten_r_semiten_r-P2_x" joint2="knee_angle_r" polycoef="-0.04135 -0.003884 0 0 0" solimp="0.9999 0.9999 0.001 0.5 2"/>
    <joint joint1="semiten_r_semiten_r-P2_y" joint2="knee_angle_r" polycoef="-0.03045 0.01068 0 0 0" solimp="0.9999 0.9999 0.001 0.5 2"/>
    <joint joint1="grac_r_grac_r-P2_x" joint2="knee_angle_r" polycoef="-0.02602 -0.003147 0 0 0" solimp="0.9999 0.9999 0.001 0.5 2"/>
    <joint joint1="grac_r_grac_r-P2_y" joint2="knee_angle_r" polycoef="-0.03341 0.008653 0 0 0" solimp="0.9999 0.9999 0.001 0.5 2"/>
    <joint joint1="grac_r_grac_r-P2_z" joint2="knee_angle_r" polycoef="-0.03759 -0.0008552 0 0 0" solimp="0.9999 0.9999 0.001 0.5 2"/>
    <joint joint1="iliacus_r_iliacus_r-P3_x" joint2="hip_flexion_r" polycoef="-0.0288 0 0.0006842 0 0" solimp="0.9999 0.9999 0.001 0.5 2"/>
    <joint joint1="iliacus_r_iliacus_r-P3_y" joint2="hip_flexion_r" polycoef="-0.0805 0 0.005815 0 0" solimp="0.9999 0.9999 0.001 0.5 2"/>
    <joint joint1="psoas_r_psoas_r-P3_x" joint2="hip_flexion_r" polycoef="-0.0288 0 0.00114 0 0" solimp="0.9999 0.9999 0.001 0.5 2"/>
    <joint joint1="psoas_r_psoas_r-P3_y" joint2="hip_flexion_r" polycoef="-0.0805 0 0.005359 0 0" solimp="0.9999 0.9999 0.001 0.5 2"/>
    <joint joint1="psoas_r_psoas_r-P3_z" joint2="hip_flexion_r" polycoef="0.0816 0 -0.0013 0 0" solimp="0.9999 0.9999 0.001 0.5 2"/>
    <joint joint1="rect_fem_r_rect_fem_r-P3_x" joint2="knee_angle_r" polycoef="0.06259 0.04199 0.01152 -0.007248 -0.004008" solimp="0.9999 0.9999 0.001 0.5 2"/>
    <joint joint1="rect_fem_r_rect_fem_r-P3_y" joint2="knee_angle_r" polycoef="0.02032 -0.01159 -0.008624 -0.002308 -0.0002292" solimp="0.9999 0.9999 0.001 0.5 2"/>
    <joint joint1="vas_med_r_vas_med_r-P3_x" joint2="knee_angle_r" polycoef="0.03571 -0.0006171 0 0 0" solimp="0.9999 0.9999 0.001 0.5 2"/>
    <joint joint1="vas_med_r_vas_med_r-P3_y" joint2="knee_angle_r" polycoef="-0.2867 0.05638 0 0 0" solimp="0.9999 0.9999 0.001 0.5 2"/>
    <joint joint1="vas_med_r_vas_med_r-P3_z" joint2="knee_angle_r" polycoef="-0.0001308 0.005907 0 0 0" solimp="0.9999 0.9999 0.001 0.5 2"/>
    <joint joint1="vas_med_r_vas_med_r-P4_x" joint2="knee_angle_r" polycoef="0.03497 0.003615 0 0 0" solimp="0.9999 0.9999 0.001 0.5 2"/>
    <joint joint1="vas_med_r_vas_med_r-P4_y" joint2="knee_angle_r" polycoef="-0.2883 0.06551 0 0 0" solimp="0.9999 0.9999 0.001 0.5 2"/>
    <joint joint1="vas_med_r_vas_med_r-P4_z" joint2="knee_angle_r" polycoef="-0.0001769 0.006171 0 0 0" solimp="0.9999 0.9999 0.001 0.5 2"/>
    <joint joint1="vas_med_r_vas_med_r-P5_x" joint2="knee_angle_r" polycoef="0.05687 0.04264 0.01249 -0.006776 -0.003935" solimp="0.9999 0.9999 0.001 0.5 2"/>
    <joint joint1="vas_med_r_vas_med_r-P5_y" joint2="knee_angle_r" polycoef="0.02128 -0.006751 -0.006418 -0.003253 -0.0007658" solimp="0.9999 0.9999 0.001 0.5 2"/>
    <joint joint1="vas_int_r_vas_int_r-P3_y" joint2="knee_angle_r" polycoef="-0.2234 0.08578 0 0 0" solimp="0.9999 0.9999 0.001 0.5 2"/>
    <joint joint1="vas_int_r_vas_int_r-P3_z" joint2="knee_angle_r" polycoef="0.02673 0.01014 0 0 0" solimp="0.9999 0.9999 0.001 0.5 2"/>
    <joint joint1="vas_int_r_vas_int_r-P4_x" joint2="knee_angle_r" polycoef="0.05647 0.04555 0.01393 -0.007247 -0.004235" solimp="0.9999 0.9999 0.001 0.5 2"/>
    <joint joint1="vas_int_r_vas_int_r-P4_y" joint2="knee_angle_r" polycoef="0.02476 -0.006322 -0.00661 -0.003684 -0.0008973" solimp="0.9999 0.9999 0.001 0.5 2"/>
    <joint joint1="vas_lat_r_vas_lat_r-P3_x" joint2="knee_angle_r" polycoef="0.02761 -0.004056 0 0 0" solimp="0.9999 0.9999 0.001 0.5 2"/>
    <joint joint1="vas_lat_r_vas_lat_r-P3_y" joint2="knee_angle_r" polycoef="-0.2702 0.06343 0 0 0" solimp="0.9999 0.9999 0.001 0.5 2"/>
    <joint joint1="vas_lat_r_vas_lat_r-P3_z" joint2="knee_angle_r" polycoef="0.03933 0.008993 0 0 0" solimp="0.9999 0.9999 0.001 0.5 2"/>
    <joint joint1="vas_lat_r_vas_lat_r-P4_x" joint2="knee_angle_r" polycoef="0.02678 0.0007053 0 0 0" solimp="0.9999 0.9999 0.001 0.5 2"/>
    <joint joint1="vas_lat_r_vas_lat_r-P4_y" joint2="knee_angle_r" polycoef="-0.2718 0.07282 0 0 0" solimp="0.9999 0.9999 0.001 0.5 2"/>
    <joint joint1="vas_lat_r_vas_lat_r-P4_z" joint2="knee_angle_r" polycoef="0.03917 0.009918 0 0 0" solimp="0.9999 0.9999 0.001 0.5 2"/>
    <joint joint1="vas_lat_r_vas_lat_r-P5_x" joint2="knee_angle_r" polycoef="0.06077 0.04082 0.01117 -0.006856 -0.003839" solimp="0.9999 0.9999 0.001 0.5 2"/>
    <joint joint1="vas_lat_r_vas_lat_r-P5_y" joint2="knee_angle_r" polycoef="0.01899 -0.01009 -0.007756 -0.002434 -0.0003548" solimp="0.9999 0.9999 0.001 0.5 2"/>
    <joint joint1="med_gas_r_med_gas_r-P2_x" joint2="knee_angle_r" polycoef="-0.02915 -0.004849 0 0 0" solimp="0.9999 0.9999 0.001 0.5 2"/>
    <joint joint1="med_gas_r_med_gas_r-P2_y" joint2="knee_angle_r" polycoef="-0.4015 -0.0041 0 0 0" solimp="0.9999 0.9999 0.001 0.5 2"/>
    <joint joint1="med_gas_r_med_gas_r-P2_z" joint2="knee_angle_r" polycoef="-0.02562 -0.001014 0 0 0" solimp="0.9999 0.9999 0.001 0.5 2"/>
    <joint joint1="lat_gas_r_lat_gas_r-P2_x" joint2="knee_angle_r" polycoef="-0.02938 -0.003527 0 0 0" solimp="0.9999 0.9999 0.001 0.5 2"/>
    <joint joint1="lat_gas_r_lat_gas_r-P2_y" joint2="knee_angle_r" polycoef="-0.4012 -0.003174 0 0 0" solimp="0.9999 0.9999 0.001 0.5 2"/>
    <joint joint1="semimem_l_semimem_l-P2_x" joint2="knee_angle_l" polycoef="-0.0342 -0.003438 0 0 0" solimp="0.9999 0.9999 0.001 0.5 2"/>
    <joint joint1="semimem_l_semimem_l-P2_y" joint2="knee_angle_l" polycoef="-0.03615 0.005519 0 0 0" solimp="0.9999 0.9999 0.001 0.5 2"/>
    <joint joint1="semiten_l_semiten_l-P2_x" joint2="knee_angle_l" polycoef="-0.04135 -0.003884 0 0 0" solimp="0.9999 0.9999 0.001 0.5 2"/>
    <joint joint1="semiten_l_semiten_l-P2_y" joint2="knee_angle_l" polycoef="-0.03045 0.01068 0 0 0" solimp="0.9999 0.9999 0.001 0.5 2"/>
    <joint joint1="iliacus_l_iliacus_l-P3_x" joint2="hip_flexion_l" polycoef="-0.0288 0 0.0006842 0 0" solimp="0.9999 0.9999 0.001 0.5 2"/>
    <joint joint1="iliacus_l_iliacus_l-P3_y" joint2="hip_flexion_l" polycoef="-0.0805 0 0.005815 0 0" solimp="0.9999 0.9999 0.001 0.5 2"/>
    <joint joint1="psoas_l_psoas_l-P3_x" joint2="hip_flexion_l" polycoef="-0.0288 0 0.00114 0 0" solimp="0.9999 0.9999 0.001 0.5 2"/>
    <joint joint1="psoas_l_psoas_l-P3_y" joint2="hip_flexion_l" polycoef="-0.0805 0 0.005359 0 0" solimp="0.9999 0.9999 0.001 0.5 2"/>
    <joint joint1="psoas_l_psoas_l-P3_z" joint2="hip_flexion_l" polycoef="-0.0816 0 0.0013 0 0" solimp="0.9999 0.9999 0.001 0.5 2"/>
    <joint joint1="rect_fem_l_rect_fem_l-P3_x" joint2="knee_angle_l" polycoef="0.06259 0.04199 0.01152 -0.007248 -0.004008" solimp="0.9999 0.9999 0.001 0.5 2"/>
    <joint joint1="rect_fem_l_rect_fem_l-P3_y" joint2="knee_angle_l" polycoef="0.02032 -0.01159 -0.008624 -0.002308 -0.0002292" solimp="0.9999 0.9999 0.001 0.5 2"/>
    <joint joint1="vas_med_l_vas_med_r-P4_x" joint2="knee_angle_l" polycoef="0.03497 0.003615 0 0 0" solimp="0.9999 0.9999 0.001 0.5 2"/>
    <joint joint1="vas_med_l_vas_med_r-P4_y" joint2="knee_angle_l" polycoef="-0.2883 0.06551 0 0 0" solimp="0.9999 0.9999 0.001 0.5 2"/>
    <joint joint1="vas_med_l_vas_med_r-P4_z" joint2="knee_angle_l" polycoef="-0.0001769 0.006171 0 0 0" solimp="0.9999 0.9999 0.001 0.5 2"/>
    <joint joint1="vas_med_l_vas_med_r-P5_x" joint2="knee_angle_l" polycoef="0.05687 0.04264 0.01249 -0.006776 -0.003935" solimp="0.9999 0.9999 0.001 0.5 2"/>
    <joint joint1="vas_med_l_vas_med_r-P5_y" joint2="knee_angle_l" polycoef="0.02128 -0.006751 -0.006418 -0.003253 -0.0007658" solimp="0.9999 0.9999 0.001 0.5 2"/>
    <joint joint1="vas_int_l_vas_int_l-P3_y" joint2="knee_angle_l" polycoef="-0.2234 0.08578 0 0 0" solimp="0.9999 0.9999 0.001 0.5 2"/>
    <joint joint1="vas_int_l_vas_int_l-P3_z" joint2="knee_angle_l" polycoef="0.02673 0.01014 0 0 0" solimp="0.9999 0.9999 0.001 0.5 2"/>
    <joint joint1="vas_int_l_vas_int_l-P4_x" joint2="knee_angle_l" polycoef="0.05647 0.04555 0.01393 -0.007247 -0.004235" solimp="0.9999 0.9999 0.001 0.5 2"/>
    <joint joint1="vas_int_l_vas_int_l-P4_y" joint2="knee_angle_l" polycoef="0.02476 -0.006322 -0.00661 -0.003684 -0.0008973" solimp="0.9999 0.9999 0.001 0.5 2"/>
    <joint joint1="vas_lat_l_vas_lat_l-P3_x" joint2="knee_angle_l" polycoef="0.02761 -0.004056 0 0 0" solimp="0.9999 0.9999 0.001 0.5 2"/>
    <joint joint1="vas_lat_l_vas_lat_l-P3_y" joint2="knee_angle_l" polycoef="-0.2702 0.06343 0 0 0" solimp="0.9999 0.9999 0.001 0.5 2"/>
    <joint joint1="vas_lat_l_vas_lat_l-P3_z" joint2="knee_angle_l" polycoef="0.03933 0.008993 0 0 0" solimp="0.9999 0.9999 0.001 0.5 2"/>
    <joint joint1="vas_lat_l_vas_lat_l-P4_x" joint2="knee_angle_l" polycoef="0.02678 0.0007053 0 0 0" solimp="0.9999 0.9999 0.001 0.5 2"/>
    <joint joint1="vas_lat_l_vas_lat_l-P4_y" joint2="knee_angle_l" polycoef="-0.2718 0.07282 0 0 0" solimp="0.9999 0.9999 0.001 0.5 2"/>
    <joint joint1="vas_lat_l_vas_lat_l-P4_z" joint2="knee_angle_l" polycoef="0.03917 0.009918 0 0 0" solimp="0.9999 0.9999 0.001 0.5 2"/>
    <joint joint1="vas_lat_l_vas_lat_l-P5_x" joint2="knee_angle_l" polycoef="0.06077 0.04082 0.01117 -0.006856 -0.003839" solimp="0.9999 0.9999 0.001 0.5 2"/>
    <joint joint1="vas_lat_l_vas_lat_l-P5_y" joint2="knee_angle_l" polycoef="0.01899 -0.01009 -0.007756 -0.002434 -0.0003548" solimp="0.9999 0.9999 0.001 0.5 2"/>
  </equality>
  <tendon>
    <spatial name="glut_med1_r_tendon">
      <site site="glut_med1_r_glut_med1_r-P1"/>
      <site site="glut_med1_r_glut_med1_r-P2"/>
    </spatial>
    <spatial name="glut_med2_r_tendon">
      <site site="glut_med2_r_glut_med2_r-P1"/>
      <site site="glut_med2_r_glut_med2_r-P2"/>
    </spatial>
    <spatial name="glut_med3_r_tendon">
      <site site="glut_med3_r_glut_med3_r-P1"/>
      <site site="glut_med3_r_glut_med3_r-P2"/>
    </spatial>
    <spatial name="glut_min1_r_tendon">
      <site site="glut_min1_r_glut_min1_r-P1"/>
      <site site="glut_min1_r_glut_min1_r-P2"/>
    </spatial>
    <spatial name="glut_min2_r_tendon">
      <site site="glut_min2_r_glut_min2_r-P1"/>
      <site site="glut_min2_r_glut_min2_r-P2"/>
    </spatial>
    <spatial name="glut_min3_r_tendon">
      <site site="glut_min3_r_glut_min3_r-P1"/>
      <site site="glut_min3_r_glut_min3_r-P2"/>
    </spatial>
    <spatial name="semimem_r_tendon">
      <site site="semimem_r_semimem_r-P1"/>
      <site site="semimem_r_semimem_r-P2"/>
      <site site="semimem_r_semimem_r-P3"/>
    </spatial>
    <spatial name="semiten_r_tendon">
      <site site="semiten_r_semiten_r-P1"/>
      <site site="semiten_r_semiten_r-P2"/>
      <site site="semiten_r_semiten_r-P3"/>
      <site site="semiten_r_semiten_r-P4"/>
      <site site="semiten_r_semiten_r-P5"/>
    </spatial>
    <spatial name="bifemlh_r_tendon">
      <site site="bifemlh_r_bifemlh_r-P1"/>
      <site site="bifemlh_r_bifemlh_r-P2"/>
      <site site="bifemlh_r_bifemlh_r-P3"/>
    </spatial>
    <spatial name="bifemsh_r_tendon">
      <site site="bifemsh_r_bifemsh_r-P1"/>
      <site site="bifemsh_r_bifemsh_r-P2"/>
      <site site="bifemsh_r_bifemsh_r-P3"/>
    </spatial>
    <spatial name="sar_r_tendon">
      <site site="sar_r_sar_r-P1"/>
      <site site="sar_r_sar_r-P2"/>
      <site site="sar_r_sar_r-P3"/>
      <site site="sar_r_sar_r-P4"/>
      <site site="sar_r_sar_r-P5"/>
    </spatial>
    <spatial name="add_long_r_tendon">
      <site site="add_long_r_add_long_r-P1"/>
      <site site="add_long_r_add_long_r-P2"/>
    </spatial>
    <spatial name="add_brev_r_tendon">
      <site site="add_brev_r_add_brev_r-P1"/>
      <site site="add_brev_r_add_brev_r-P2"/>
    </spatial>
    <spatial name="add_mag1_r_tendon">
      <site site="add_mag1_r_add_mag1_r-P1"/>
      <site site="add_mag1_r_add_mag1_r-P2"/>
    </spatial>
    <spatial name="add_mag2_r_tendon">
      <site site="add_mag2_r_add_mag2_r-P1"/>
      <site site="add_mag2_r_add_mag2_r-P2"/>
    </spatial>
    <spatial name="add_mag3_r_tendon">
      <site site="add_mag3_r_add_mag3_r-P1"/>
      <site site="add_mag3_r_add_mag3_r-P2"/>
    </spatial>
    <spatial name="tfl_r_tendon">
      <site site="tfl_r_tfl_r-P1"/>
      <site site="tfl_r_tfl_r-P2"/>
      <site site="tfl_r_tfl_r-P3"/>
      <site site="tfl_r_tfl_r-P4"/>
    </spatial>
    <spatial name="pect_r_tendon">
      <site site="pect_r_pect_r-P1"/>
      <site site="pect_r_pect_r-P2"/>
    </spatial>
    <spatial name="grac_r_tendon">
      <site site="grac_r_grac_r-P1"/>
      <site site="grac_r_grac_r-P2"/>
      <site site="grac_r_grac_r-P3"/>
      <site site="grac_r_grac_r-P4"/>
    </spatial>
    <spatial name="glut_max1_r_tendon">
      <site site="glut_max1_r_glut_max1_r-P1"/>
      <site site="glut_max1_r_glut_max1_r-P2"/>
      <site site="glut_max1_r_glut_max1_r-P3"/>
      <site site="glut_max1_r_glut_max1_r-P4"/>
    </spatial>
    <spatial name="glut_max2_r_tendon">
      <site site="glut_max2_r_glut_max2_r-P1"/>
      <site site="glut_max2_r_glut_max2_r-P2"/>
      <site site="glut_max2_r_glut_max2_r-P3"/>
      <site site="glut_max2_r_glut_max2_r-P4"/>
    </spatial>
    <spatial name="glut_max3_r_tendon">
      <site site="glut_max3_r_glut_max3_r-P1"/>
      <site site="glut_max3_r_glut_max3_r-P2"/>
      <site site="glut_max3_r_glut_max3_r-P3"/>
      <site site="glut_max3_r_glut_max3_r-P4"/>
    </spatial>
    <spatial name="iliacus_r_tendon">
      <site site="iliacus_r_iliacus_r-P1"/>
      <site site="iliacus_r_iliacus_r-P2"/>
      <site site="iliacus_r_iliacus_r-P3"/>
      <site site="iliacus_r_iliacus_r-P4"/>
      <site site="iliacus_r_iliacus_r-P5"/>
    </spatial>
    <spatial name="psoas_r_tendon">
      <site site="psoas_r_psoas_r-P1"/>
      <site site="psoas_r_psoas_r-P2"/>
      <site site="psoas_r_psoas_r-P3"/>
      <site site="psoas_r_psoas_r-P4"/>
      <site site="psoas_r_psoas_r-P5"/>
    </spatial>
    <spatial name="quad_fem_r_tendon">
      <site site="quad_fem_r_quad_fem_r-P1"/>
      <site site="quad_fem_r_quad_fem_r-P2"/>
    </spatial>
    <spatial name="gem_r_tendon">
      <site site="gem_r_gem_r-P1"/>
      <site site="gem_r_gem_r-P2"/>
    </spatial>
    <spatial name="peri_r_tendon">
      <site site="peri_r_peri_r-P1"/>
      <site site="peri_r_peri_r-P2"/>
      <site site="peri_r_peri_r-P3"/>
    </spatial>
    <spatial name="rect_fem_r_tendon">
      <site site="rect_fem_r_rect_fem_r-P1"/>
      <site site="rect_fem_r_rect_fem_r-P2"/>
      <site site="rect_fem_r_rect_fem_r-P3"/>
    </spatial>
    <spatial name="vas_med_r_tendon">
      <site site="vas_med_r_vas_med_r-P1"/>
      <site site="vas_med_r_vas_med_r-P2"/>
      <site site="vas_med_r_vas_med_r-P3"/>
      <site site="vas_med_r_vas_med_r-P4"/>
      <site site="vas_med_r_vas_med_r-P5"/>
    </spatial>
    <spatial name="vas_int_r_tendon">
      <site site="vas_int_r_vas_int_r-P1"/>
      <site site="vas_int_r_vas_int_r-P2"/>
      <site site="vas_int_r_vas_int_r-P3"/>
      <site site="vas_int_r_vas_int_r-P4"/>
    </spatial>
    <spatial name="vas_lat_r_tendon">
      <site site="vas_lat_r_vas_lat_r-P1"/>
      <site site="vas_lat_r_vas_lat_r-P2"/>
      <site site="vas_lat_r_vas_lat_r-P3"/>
      <site site="vas_lat_r_vas_lat_r-P4"/>
      <site site="vas_lat_r_vas_lat_r-P5"/>
    </spatial>
    <spatial name="med_gas_r_tendon">
      <site site="med_gas_r_med_gas_r-P1"/>
      <site site="med_gas_r_med_gas_r-P2"/>
      <site site="med_gas_r_med_gas_r-P3"/>
    </spatial>
    <spatial name="lat_gas_r_tendon">
      <site site="lat_gas_r_lat_gas_r-P1"/>
      <site site="lat_gas_r_lat_gas_r-P2"/>
      <site site="lat_gas_r_lat_gas_r-P3"/>
    </spatial>
    <spatial name="soleus_r_tendon">
      <site site="soleus_r_soleus_r-P1"/>
      <site site="soleus_r_soleus_r-P2"/>
    </spatial>
    <spatial name="tib_post_r_tendon">
      <site site="tib_post_r_tib_post_r-P1"/>
      <site site="tib_post_r_tib_post_r-P2"/>
      <site site="tib_post_r_tib_post_r-P3"/>
      <site site="tib_post_r_tib_post_r-P4"/>
    </spatial>
    <spatial name="flex_dig_r_tendon">
      <site site="flex_dig_r_flex_dig_r-P1"/>
      <site site="flex_dig_r_flex_dig_r-P2"/>
      <site site="flex_dig_r_flex_dig_r-P3"/>
      <site site="flex_dig_r_flex_dig_r-P4"/>
      <site site="flex_dig_r_flex_dig_r-P5"/>
      <site site="flex_dig_r_flex_dig_r-P6"/>
      <site site="flex_dig_r_flex_dig_r-P7"/>
      <site site="flex_dig_r_flex_dig_r-P8"/>
    </spatial>
    <spatial name="flex_hal_r_tendon">
      <site site="flex_hal_r_flex_hal_r-P1"/>
      <site site="flex_hal_r_flex_hal_r-P2"/>
      <site site="flex_hal_r_flex_hal_r-P3"/>
      <site site="flex_hal_r_flex_hal_r-P4"/>
      <site site="flex_hal_r_flex_hal_r-P5"/>
      <site site="flex_hal_r_flex_hal_r-P6"/>
      <site site="flex_hal_r_flex_hal_r-P7"/>
    </spatial>
    <spatial name="tib_ant_r_tendon">
      <site site="tib_ant_r_tib_ant_r-P1"/>
      <site site="tib_ant_r_tib_ant_r-P2"/>
      <site site="tib_ant_r_tib_ant_r-P3"/>
    </spatial>
    <spatial name="per_brev_r_tendon">
      <site site="per_brev_r_per_brev_r-P1"/>
      <site site="per_brev_r_per_brev_r-P2"/>
      <site site="per_brev_r_per_brev_r-P3"/>
      <site site="per_brev_r_per_brev_r-P4"/>
      <site site="per_brev_r_per_brev_r-P5"/>
    </spatial>
    <spatial name="per_long_r_tendon">
      <site site="per_long_r_per_long_r-P1"/>
      <site site="per_long_r_per_long_r-P2"/>
      <site site="per_long_r_per_long_r-P3"/>
      <site site="per_long_r_per_long_r-P4"/>
      <site site="per_long_r_per_long_r-P5"/>
      <site site="per_long_r_per_long_r-P6"/>
      <site site="per_long_r_per_long_r-P7"/>
    </spatial>
    <spatial name="per_tert_r_tendon">
      <site site="per_tert_r_per_tert_r-P1"/>
      <site site="per_tert_r_per_tert_r-P2"/>
      <site site="per_tert_r_per_tert_r-P3"/>
    </spatial>
    <spatial name="ext_dig_r_tendon">
      <site site="ext_dig_r_ext_dig_r-P1"/>
      <site site="ext_dig_r_ext_dig_r-P2"/>
      <site site="ext_dig_r_ext_dig_r-P3"/>
      <site site="ext_dig_r_ext_dig_r-P4"/>
      <site site="ext_dig_r_ext_dig_r-P5"/>
      <site site="ext_dig_r_ext_dig_r-P6"/>
    </spatial>
    <spatial name="ext_hal_r_tendon">
      <site site="ext_hal_r_ext_hal_r-P1"/>
      <site site="ext_hal_r_ext_hal_r-P2"/>
      <site site="ext_hal_r_ext_hal_r-P3"/>
      <site site="ext_hal_r_ext_hal_r-P4"/>
      <site site="ext_hal_r_ext_hal_r-P5"/>
      <site site="ext_hal_r_ext_hal_r-P6"/>
      <site site="ext_hal_r_ext_hal_r-P7"/>
    </spatial>
    <spatial name="glut_med1_l_tendon">
      <site site="glut_med1_l_glut_med1_l-P1"/>
      <site site="glut_med1_l_glut_med1_l-P2"/>
    </spatial>
    <spatial name="glut_med2_l_tendon">
      <site site="glut_med2_l_glut_med2_l-P1"/>
      <site site="glut_med2_l_glut_med2_l-P2"/>
    </spatial>
    <spatial name="glut_med3_l_tendon">
      <site site="glut_med3_l_glut_med3_l-P1"/>
      <site site="glut_med3_l_glut_med3_l-P2"/>
    </spatial>
    <spatial name="glut_min1_l_tendon">
      <site site="glut_min1_l_glut_min1_l-P1"/>
      <site site="glut_min1_l_glut_min1_l-P2"/>
    </spatial>
    <spatial name="glut_min2_l_tendon">
      <site site="glut_min2_l_glut_min2_l-P1"/>
      <site site="glut_min2_l_glut_min2_l-P2"/>
    </spatial>
    <spatial name="glut_min3_l_tendon">
      <site site="glut_min3_l_glut_min3_l-P1"/>
      <site site="glut_min3_l_glut_min3_l-P2"/>
    </spatial>
    <spatial name="semimem_l_tendon">
      <site site="semimem_l_semimem_l-P1"/>
      <site site="semimem_l_semimem_l-P2"/>
      <site site="semimem_l_semimem_l-P3"/>
    </spatial>
    <spatial name="semiten_l_tendon">
      <site site="semiten_l_semiten_l-P1"/>
      <site site="semiten_l_semiten_l-P2"/>
      <site site="semiten_l_semiten_l-P3"/>
      <site site="semiten_l_semiten_l-P4"/>
      <site site="semiten_l_semiten_l-P5"/>
    </spatial>
    <spatial name="bifemlh_l_tendon">
      <site site="bifemlh_l_bifemlh_l-P1"/>
      <site site="bifemlh_l_bifemlh_l-P2"/>
      <site site="bifemlh_l_bifemlh_l-P3"/>
    </spatial>
    <spatial name="bifemsh_l_tendon">
      <site site="bifemsh_l_bifemsh_l-P1"/>
      <site site="bifemsh_l_bifemsh_l-P2"/>
      <site site="bifemsh_l_bifemsh_l-P3"/>
    </spatial>
    <spatial name="sar_l_tendon">
      <site site="sar_l_sar_l-P1"/>
      <site site="sar_l_sar_l-P2"/>
      <site site="sar_l_sar_l-P3"/>
      <site site="sar_l_sar_l-P4"/>
      <site site="sar_l_sar_l-P5"/>
    </spatial>
    <spatial name="add_long_l_tendon">
      <site site="add_long_l_add_long_l-P1"/>
      <site site="add_long_l_add_long_l-P2"/>
    </spatial>
    <spatial name="add_brev_l_tendon">
      <site site="add_brev_l_add_brev_l-P1"/>
      <site site="add_brev_l_add_brev_l-P2"/>
    </spatial>
    <spatial name="add_mag1_l_tendon">
      <site site="add_mag1_l_add_mag1_l-P1"/>
      <site site="add_mag1_l_add_mag1_l-P2"/>
    </spatial>
    <spatial name="add_mag2_l_tendon">
      <site site="add_mag2_l_add_mag2_l-P1"/>
      <site site="add_mag2_l_add_mag2_l-P2"/>
    </spatial>
    <spatial name="add_mag3_l_tendon">
      <site site="add_mag3_l_add_mag3_l-P1"/>
      <site site="add_mag3_l_add_mag3_l-P2"/>
    </spatial>
    <spatial name="pect_l_tendon">
      <site site="pect_l_pect_l-P1"/>
      <site site="pect_l_pect_l-P2"/>
    </spatial>
    <spatial name="glut_max1_l_tendon">
      <site site="glut_max1_l_glut_max1_l-P1"/>
      <site site="glut_max1_l_glut_max1_l-P2"/>
      <site site="glut_max1_l_glut_max1_l-P3"/>
      <site site="glut_max1_l_glut_max1_l-P4"/>
    </spatial>
    <spatial name="glut_max2_l_tendon">
      <site site="glut_max2_l_glut_max2_l-P1"/>
      <site site="glut_max2_l_glut_max2_l-P2"/>
      <site site="glut_max2_l_glut_max2_l-P3"/>
      <site site="glut_max2_l_glut_max2_l-P4"/>
    </spatial>
    <spatial name="glut_max3_l_tendon">
      <site site="glut_max3_l_glut_max3_l-P1"/>
      <site site="glut_max3_l_glut_max3_l-P2"/>
      <site site="glut_max3_l_glut_max3_l-P3"/>
      <site site="glut_max3_l_glut_max3_l-P4"/>
    </spatial>
    <spatial name="iliacus_l_tendon">
      <site site="iliacus_l_iliacus_l-P1"/>
      <site site="iliacus_l_iliacus_l-P2"/>
      <site site="iliacus_l_iliacus_l-P3"/>
      <site site="iliacus_l_iliacus_l-P4"/>
      <site site="iliacus_l_iliacus_l-P5"/>
    </spatial>
    <spatial name="psoas_l_tendon">
      <site site="psoas_l_psoas_l-P1"/>
      <site site="psoas_l_psoas_l-P2"/>
      <site site="psoas_l_psoas_l-P3"/>
      <site site="psoas_l_psoas_l-P4"/>
      <site site="psoas_l_psoas_l-P5"/>
    </spatial>
    <spatial name="quad_fem_l_tendon">
      <site site="quad_fem_l_quad_fem_l-P1"/>
      <site site="quad_fem_l_quad_fem_l-P2"/>
    </spatial>
    <spatial name="gem_l_tendon">
      <site site="gem_l_gem_l-P1"/>
      <site site="gem_l_gem_l-P2"/>
    </spatial>
    <spatial name="peri_l_tendon">
      <site site="peri_l_peri_l-P1"/>
      <site site="peri_l_peri_l-P2"/>
      <site site="peri_l_peri_l-P3"/>
    </spatial>
    <spatial name="rect_fem_l_tendon">
      <site site="rect_fem_l_rect_fem_l-P1"/>
      <site site="rect_fem_l_rect_fem_l-P2"/>
      <site site="rect_fem_l_rect_fem_l-P3"/>
    </spatial>
    <spatial name="vas_med_l_tendon">
      <site site="vas_med_l_vas_med_l-P1"/>
      <site site="vas_med_l_vas_med_l-P2"/>
      <site site="vas_med_l_vas_med_l-P3"/>
      <site site="vas_med_l_vas_med_r-P4"/>
      <site site="vas_med_l_vas_med_r-P5"/>
    </spatial>
    <spatial name="vas_int_l_tendon">
      <site site="vas_int_l_vas_int_l-P1"/>
      <site site="vas_int_l_vas_int_l-P2"/>
      <site site="vas_int_l_vas_int_l-P3"/>
      <site site="vas_int_l_vas_int_l-P4"/>
    </spatial>
    <spatial name="vas_lat_l_tendon">
      <site site="vas_lat_l_vas_lat_l-P1"/>
      <site site="vas_lat_l_vas_lat_l-P2"/>
      <site site="vas_lat_l_vas_lat_l-P3"/>
      <site site="vas_lat_l_vas_lat_l-P4"/>
      <site site="vas_lat_l_vas_lat_l-P5"/>
    </spatial>
    <spatial name="ercspn_r_tendon">
      <site site="ercspn_r_ercspn_r-P1"/>
      <site site="ercspn_r_ercspn_r-P2"/>
    </spatial>
    <spatial name="ercspn_l_tendon">
      <site site="ercspn_l_ercspn_l-P1"/>
      <site site="ercspn_l_ercspn_l-P2"/>
    </spatial>
    <spatial name="intobl_r_tendon">
      <site site="intobl_r_intobl_r-P1"/>
      <site site="intobl_r_intobl_r-P2"/>
    </spatial>
    <spatial name="intobl_l_tendon">
      <site site="intobl_l_intobl_l-P1"/>
      <site site="intobl_l_intobl_l-P2"/>
    </spatial>
    <spatial name="extobl_r_tendon">
      <site site="extobl_r_extobl_r-P1"/>
      <site site="extobl_r_extobl_r-P2"/>
    </spatial>
    <spatial name="extobl_l_tendon">
      <site site="extobl_l_extobl_l-P1"/>
      <site site="extobl_l_extobl_l-P2"/>
    </spatial>
  </tendon>
  <actuator>
    <general name="glut_med1_r" class="muscle" tendon="glut_med1_r_tendon" lengthrange="0.01 1" gainprm="0.75 1.05 819 200 0.5 1.6 1.5 1.3 1.2 0" biasprm="0.75 1.05 819 200 0.5 1.6 1.5 1.3 1.2 0"/>
    <general name="glut_med2_r" class="muscle" tendon="glut_med2_r_tendon" lengthrange="0.01 1" gainprm="0.75 1.05 573 200 0.5 1.6 1.5 1.3 1.2 0" biasprm="0.75 1.05 573 200 0.5 1.6 1.5 1.3 1.2 0"/>
    <general name="glut_med3_r" class="muscle" tendon="glut_med3_r_tendon" lengthrange="0.01 1" gainprm="0.75 1.05 653 200 0.5 1.6 1.5 1.3 1.2 0" biasprm="0.75 1.05 653 200 0.5 1.6 1.5 1.3 1.2 0"/>
    <general name="glut_min1_r" class="muscle" tendon="glut_min1_r_tendon" lengthrange="0.01 1" gainprm="0.75 1.05 270 200 0.5 1.6 1.5 1.3 1.2 0" biasprm="0.75 1.05 270 200 0.5 1.6 1.5 1.3 1.2 0"/>
    <general name="glut_min2_r" class="muscle" tendon="glut_min2_r_tendon" lengthrange="0.01 1" gainprm="0.75 1.05 285 200 0.5 1.6 1.5 1.3 1.2 0" biasprm="0.75 1.05 285 200 0.5 1.6 1.5 1.3 1.2 0"/>
    <general name="glut_min3_r" class="muscle" tendon="glut_min3_r_tendon" lengthrange="0.01 1" gainprm="0.75 1.05 323 200 0.5 1.6 1.5 1.3 1.2 0" biasprm="0.75 1.05 323 200 0.5 1.6 1.5 1.3 1.2 0"/>
    <general name="semimem_r" class="muscle" tendon="semimem_r_tendon" lengthrange="0.01 1" gainprm="0.75 1.05 1288 200 0.5 1.6 1.5 1.3 1.2 0" biasprm="0.75 1.05 1288 200 0.5 1.6 1.5 1.3 1.2 0"/>
    <general name="semiten_r" class="muscle" tendon="semiten_r_tendon" lengthrange="0.01 1" gainprm="0.75 1.05 410 200 0.5 1.6 1.5 1.3 1.2 0" biasprm="0.75 1.05 410 200 0.5 1.6 1.5 1.3 1.2 0"/>
    <general name="bifemlh_r" class="muscle" tendon="bifemlh_r_tendon" lengthrange="0.01 1" gainprm="0.75 1.05 896 200 0.5 1.6 1.5 1.3 1.2 0" biasprm="0.75 1.05 896 200 0.5 1.6 1.5 1.3 1.2 0"/>
    <general name="bifemsh_r" class="muscle" tendon="bifemsh_r_tendon" lengthrange="0.01 1" gainprm="0.75 1.05 804 200 0.5 1.6 1.5 1.3 1.2 0" biasprm="0.75 1.05 804 200 0.5 1.6 1.5 1.3 1.2 0"/>
    <general name="sar_r" class="muscle" tendon="sar_r_tendon" lengthrange="0.01 1" gainprm="0.75 1.05 156 200 0.5 1.6 1.5 1.3 1.2 0" biasprm="0.75 1.05 156 200 0.5 1.6 1.5 1.3 1.2 0"/>
    <general name="add_long_r" class="muscle" tendon="add_long_r_tendon" lengthrange="0.01 1" gainprm="0.75 1.05 627 200 0.5 1.6 1.5 1.3 1.2 0" biasprm="0.75 1.05 627 200 0.5 1.6 1.5 1.3 1.2 0"/>
    <general name="add_brev_r" class="muscle" tendon="add_brev_r_tendon" lengthrange="0.01 1" gainprm="0.75 1.05 429 200 0.5 1.6 1.5 1.3 1.2 0" biasprm="0.75 1.05 429 200 0.5 1.6 1.5 1.3 1.2 0"/>
    <general name="add_mag1_r" class="muscle" tendon="add_mag1_r_tendon" lengthrange="0.01 1" gainprm="0.75 1.05 381 200 0.5 1.6 1.5 1.3 1.2 0" biasprm="0.75 1.05 381 200 0.5 1.6 1.5 1.3 1.2 0"/>
    <general name="add_mag2_r" class="muscle" tendon="add_mag2_r_tendon" lengthrange="0.01 1" gainprm="0.75 1.05 343 200 0.5 1.6 1.5 1.3 1.2 0" biasprm="0.75 1.05 343 200 0.5 1.6 1.5 1.3 1.2 0"/>
    <general name="add_mag3_r" class="muscle" tendon="add_mag3_r_tendon" lengthrange="0.01 1" gainprm="0.75 1.05 488 200 0.5 1.6 1.5 1.3 1.2 0" biasprm="0.75 1.05 488 200 0.5 1.6 1.5 1.3 1.2 0"/>
    <general name="tfl_r" class="muscle" tendon="tfl_r_tendon" lengthrange="0.01 1" gainprm="0.75 1.05 233 200 0.5 1.6 1.5 1.3 1.2 0" biasprm="0.75 1.05 233 200 0.5 1.6 1.5 1.3 1.2 0"/>
    <general name="pect_r" class="muscle" tendon="pect_r_tendon" lengthrange="0.01 1" gainprm="0.75 1.05 266 200 0.5 1.6 1.5 1.3 1.2 0" biasprm="0.75 1.05 266 200 0.5 1.6 1.5 1.3 1.2 0"/>
    <general name="grac_r" class="muscle" tendon="grac_r_tendon" lengthrange="0.01 1" gainprm="0.75 1.05 162 200 0.5 1.6 1.5 1.3 1.2 0" biasprm="0.75 1.05 162 200 0.5 1.6 1.5 1.3 1.2 0"/>
    <general name="glut_max1_r" class="muscle" tendon="glut_max1_r_tendon" lengthrange="0.01 1" gainprm="0.75 1.05 573 200 0.5 1.6 1.5 1.3 1.2 0" biasprm="0.75 1.05 573 200 0.5 1.6 1.5 1.3 1.2 0"/>
    <general name="glut_max2_r" class="muscle" tendon="glut_max2_r_tendon" lengthrange="0.01 1" gainprm="0.75 1.05 819 200 0.5 1.6 1.5 1.3 1.2 0" biasprm="0.75 1.05 819 200 0.5 1.6 1.5 1.3 1.2 0"/>
    <general name="glut_max3_r" class="muscle" tendon="glut_max3_r_tendon" lengthrange="0.01 1" gainprm="0.75 1.05 552 200 0.5 1.6 1.5 1.3 1.2 0" biasprm="0.75 1.05 552 200 0.5 1.6 1.5 1.3 1.2 0"/>
    <general name="iliacus_r" class="muscle" tendon="iliacus_r_tendon" lengthrange="0.01 1" gainprm="0.75 1.05 1073 200 0.5 1.6 1.5 1.3 1.2 0" biasprm="0.75 1.05 1073 200 0.5 1.6 1.5 1.3 1.2 0"/>
    <general name="psoas_r" class="muscle" tendon="psoas_r_tendon" lengthrange="0.01 1" gainprm="0.75 1.05 1113 200 0.5 1.6 1.5 1.3 1.2 0" biasprm="0.75 1.05 1113 200 0.5 1.6 1.5 1.3 1.2 0"/>
    <general name="quad_fem_r" class="muscle" tendon="quad_fem_r_tendon" lengthrange="0.01 1" gainprm="0.75 1.05 381 200 0.5 1.6 1.5 1.3 1.2 0" biasprm="0.75 1.05 381 200 0.5 1.6 1.5 1.3 1.2 0"/>
    <general name="gem_r" class="muscle" tendon="gem_r_tendon" lengthrange="0.01 1" gainprm="0.75 1.05 164 200 0.5 1.6 1.5 1.3 1.2 0" biasprm="0.75 1.05 164 200 0.5 1.6 1.5 1.3 1.2 0"/>
    <general name="peri_r" class="muscle" tendon="peri_r_tendon" lengthrange="0.01 1" gainprm="0.75 1.05 444 200 0.5 1.6 1.5 1.3 1.2 0" biasprm="0.75 1.05 444 200 0.5 1.6 1.5 1.3 1.2 0"/>
    <general name="rect_fem_r" class="muscle" tendon="rect_fem_r_tendon" lengthrange="0.01 1" gainprm="0.75 1.05 1169 200 0.5 1.6 1.5 1.3 1.2 0" biasprm="0.75 1.05 1169 200 0.5 1.6 1.5 1.3 1.2 0"/>
    <general name="vas_med_r" class="muscle" tendon="vas_med_r_tendon" lengthrange="0.01 1" gainprm="0.75 1.05 1294 200 0.5 1.6 1.5 1.3 1.2 0" biasprm="0.75 1.05 1294 200 0.5 1.6 1.5 1.3 1.2 0"/>
    <general name="vas_int_r" class="muscle" tendon="vas_int_r_tendon" lengthrange="0.01 1" gainprm="0.75 1.05 1365 200 0.5 1.6 1.5 1.3 1.2 0" biasprm="0.75 1.05 1365 200 0.5 1.6 1.5 1.3 1.2 0"/>
    <general name="vas_lat_r" class="muscle" tendon="vas_lat_r_tendon" lengthrange="0.01 1" gainprm="0.75 1.05 1871 200 0.5 1.6 1.5 1.3 1.2 0" biasprm="0.75 1.05 1871 200 0.5 1.6 1.5 1.3 1.2 0"/>
    <general name="med_gas_r" class="muscle" tendon="med_gas_r_tendon" lengthrange="0.01 1" gainprm="0.75 1.05 1558 200 0.5 1.6 1.5 1.3 1.2 0" biasprm="0.75 1.05 1558 200 0.5 1.6 1.5 1.3 1.2 0"/>
    <general name="lat_gas_r" class="muscle" tendon="lat_gas_r_tendon" lengthrange="0.01 1" gainprm="0.75 1.05 683 200 0.5 1.6 1.5 1.3 1.2 0" biasprm="0.75 1.05 683 200 0.5 1.6 1.5 1.3 1.2 0"/>
    <general name="soleus_r" class="muscle" tendon="soleus_r_tendon" lengthrange="0.01 1" gainprm="0.75 1.05 3549 200 0.5 1.6 1.5 1.3 1.2 0" biasprm="0.75 1.05 3549 200 0.5 1.6 1.5 1.3 1.2 0"/>
    <general name="tib_post_r" class="muscle" tendon="tib_post_r_tendon" lengthrange="0.01 1" gainprm="0.75 1.05 1588 200 0.5 1.6 1.5 1.3 1.2 0" biasprm="0.75 1.05 1588 200 0.5 1.6 1.5 1.3 1.2 0"/>
    <general name="flex_dig_r" class="muscle" tendon="flex_dig_r_tendon" lengthrange="0.01 1" gainprm="0.75 1.05 310 200 0.5 1.6 1.5 1.3 1.2 0" biasprm="0.75 1.05 310 200 0.5 1.6 1.5 1.3 1.2 0"/>
    <general name="flex_hal_r" class="muscle" tendon="flex_hal_r_tendon" lengthrange="0.01 1" gainprm="0.75 1.05 322 200 0.5 1.6 1.5 1.3 1.2 0" biasprm="0.75 1.05 322 200 0.5 1.6 1.5 1.3 1.2 0"/>
    <general name="tib_ant_r" class="muscle" tendon="tib_ant_r_tendon" lengthrange="0.01 1" gainprm="0.75 1.05 905 200 0.5 1.6 1.5 1.3 1.2 0" biasprm="0.75 1.05 905 200 0.5 1.6 1.5 1.3 1.2 0"/>
    <general name="per_brev_r" class="muscle" tendon="per_brev_r_tendon" lengthrange="0.01 1" gainprm="0.75 1.05 435 200 0.5 1.6 1.5 1.3 1.2 0" biasprm="0.75 1.05 435 200 0.5 1.6 1.5 1.3 1.2 0"/>
    <general name="per_long_r" class="muscle" tendon="per_long_r_tendon" lengthrange="0.01 1" gainprm="0.75 1.05 943 200 0.5 1.6 1.5 1.3 1.2 0" biasprm="0.75 1.05 943 200 0.5 1.6 1.5 1.3 1.2 0"/>
    <general name="per_tert_r" class="muscle" tendon="per_tert_r_tendon" lengthrange="0.01 1" gainprm="0.75 1.05 180 200 0.5 1.6 1.5 1.3 1.2 0" biasprm="0.75 1.05 180 200 0.5 1.6 1.5 1.3 1.2 0"/>
    <general name="ext_dig_r" class="muscle" tendon="ext_dig_r_tendon" lengthrange="0.01 1" gainprm="0.75 1.05 512 200 0.5 1.6 1.5 1.3 1.2 0" biasprm="0.75 1.05 512 200 0.5 1.6 1.5 1.3 1.2 0"/>
    <general name="ext_hal_r" class="muscle" tendon="ext_hal_r_tendon" lengthrange="0.01 1" gainprm="0.75 1.05 162 200 0.5 1.6 1.5 1.3 1.2 0" biasprm="0.75 1.05 162 200 0.5 1.6 1.5 1.3 1.2 0"/>
    <general name="glut_med1_l" class="muscle" tendon="glut_med1_l_tendon" lengthrange="0.01 1" gainprm="0.75 1.05 819 200 0.5 1.6 1.5 1.3 1.2 0" biasprm="0.75 1.05 819 200 0.5 1.6 1.5 1.3 1.2 0"/>
    <general name="glut_med2_l" class="muscle" tendon="glut_med2_l_tendon" lengthrange="0.01 1" gainprm="0.75 1.05 573 200 0.5 1.6 1.5 1.3 1.2 0" biasprm="0.75 1.05 573 200 0.5 1.6 1.5 1.3 1.2 0"/>
    <general name="glut_med3_l" class="muscle" tendon="glut_med3_l_tendon" lengthrange="0.01 1" gainprm="0.75 1.05 653 200 0.5 1.6 1.5 1.3 1.2 0" biasprm="0.75 1.05 653 200 0.5 1.6 1.5 1.3 1.2 0"/>
    <general name="glut_min1_l" class="muscle" tendon="glut_min1_l_tendon" lengthrange="0.01 1" gainprm="0.75 1.05 270 200 0.5 1.6 1.5 1.3 1.2 0" biasprm="0.75 1.05 270 200 0.5 1.6 1.5 1.3 1.2 0"/>
    <general name="glut_min2_l" class="muscle" tendon="glut_min2_l_tendon" lengthrange="0.01 1" gainprm="0.75 1.05 285 200 0.5 1.6 1.5 1.3 1.2 0" biasprm="0.75 1.05 285 200 0.5 1.6 1.5 1.3 1.2 0"/>
    <general name="glut_min3_l" class="muscle" tendon="glut_min3_l_tendon" lengthrange="0.01 1" gainprm="0.75 1.05 323 200 0.5 1.6 1.5 1.3 1.2 0" biasprm="0.75 1.05 323 200 0.5 1.6 1.5 1.3 1.2 0"/>
    <general name="semimem_l" class="muscle" tendon="semimem_l_tendon" lengthrange="0.01 1" gainprm="0.75 1.05 1288 200 0.5 1.6 1.5 1.3 1.2 0" biasprm="0.75 1.05 1288 200 0.5 1.6 1.5 1.3 1.2 0"/>
    <general name="semiten_l" class="muscle" tendon="semiten_l_tendon" lengthrange="0.01 1" gainprm="0.75 1.05 410 200 0.5 1.6 1.5 1.3 1.2 0" biasprm="0.75 1.05 410 200 0.5 1.6 1.5 1.3 1.2 0"/>
    <general name="bifemlh_l" class="muscle" tendon="bifemlh_l_tendon" lengthrange="0.01 1" gainprm="0.75 1.05 896 200 0.5 1.6 1.5 1.3 1.2 0" biasprm="0.75 1.05 896 200 0.5 1.6 1.5 1.3 1.2 0"/>
    <general name="bifemsh_l" class="muscle" tendon="bifemsh_l_tendon" lengthrange="0.01 1" gainprm="0.75 1.05 804 200 0.5 1.6 1.5 1.3 1.2 0" biasprm="0.75 1.05 804 200 0.5 1.6 1.5 1.3 1.2 0"/>
    <general name="sar_l" class="muscle" tendon="sar_l_tendon" lengthrange="0.01 1" gainprm="0.75 1.05 156 200 0.5 1.6 1.5 1.3 1.2 0" biasprm="0.75 1.05 156 200 0.5 1.6 1.5 1.3 1.2 0"/>
    <general name="add_long_l" class="muscle" tendon="add_long_l_tendon" lengthrange="0.01 1" gainprm="0.75 1.05 627 200 0.5 1.6 1.5 1.3 1.2 0" biasprm="0.75 1.05 627 200 0.5 1.6 1.5 1.3 1.2 0"/>
    <general name="add_brev_l" class="muscle" tendon="add_brev_l_tendon" lengthrange="0.01 1" gainprm="0.75 1.05 429 200 0.5 1.6 1.5 1.3 1.2 0" biasprm="0.75 1.05 429 200 0.5 1.6 1.5 1.3 1.2 0"/>
    <general name="add_mag1_l" class="muscle" tendon="add_mag1_l_tendon" lengthrange="0.01 1" gainprm="0.75 1.05 381 200 0.5 1.6 1.5 1.3 1.2 0" biasprm="0.75 1.05 381 200 0.5 1.6 1.5 1.3 1.2 0"/>
    <general name="add_mag2_l" class="muscle" tendon="add_mag2_l_tendon" lengthrange="0.01 1" gainprm="0.75 1.05 343 200 0.5 1.6 1.5 1.3 1.2 0" biasprm="0.75 1.05 343 200 0.5 1.6 1.5 1.3 1.2 0"/>
    <general name="add_mag3_l" class="muscle" tendon="add_mag3_l_tendon" lengthrange="0.01 1" gainprm="0.75 1.05 488 200 0.5 1.6 1.5 1.3 1.2 0" biasprm="0.75 1.05 488 200 0.5 1.6 1.5 1.3 1.2 0"/>
    <general name="pect_l" class="muscle" tendon="pect_l_tendon" lengthrange="0.01 1" gainprm="0.75 1.05 266 200 0.5 1.6 1.5 1.3 1.2 0" biasprm="0.75 1.05 266 200 0.5 1.6 1.5 1.3 1.2 0"/>
    <general name="glut_max1_l" class="muscle" tendon="glut_max1_l_tendon" lengthrange="0.01 1" gainprm="0.75 1.05 573 200 0.5 1.6 1.5 1.3 1.2 0" biasprm="0.75 1.05 573 200 0.5 1.6 1.5 1.3 1.2 0"/>
    <general name="glut_max2_l" class="muscle" tendon="glut_max2_l_tendon" lengthrange="0.01 1" gainprm="0.75 1.05 819 200 0.5 1.6 1.5 1.3 1.2 0" biasprm="0.75 1.05 819 200 0.5 1.6 1.5 1.3 1.2 0"/>
    <general name="glut_max3_l" class="muscle" tendon="glut_max3_l_tendon" lengthrange="0.01 1" gainprm="0.75 1.05 552 200 0.5 1.6 1.5 1.3 1.2 0" biasprm="0.75 1.05 552 200 0.5 1.6 1.5 1.3 1.2 0"/>
    <general name="iliacus_l" class="muscle" tendon="iliacus_l_tendon" lengthrange="0.01 1" gainprm="0.75 1.05 1073 200 0.5 1.6 1.5 1.3 1.2 0" biasprm="0.75 1.05 1073 200 0.5 1.6 1.5 1.3 1.2 0"/>
    <general name="psoas_l" class="muscle" tendon="psoas_l_tendon" lengthrange="0.01 1" gainprm="0.75 1.05 1113 200 0.5 1.6 1.5 1.3 1.2 0" biasprm="0.75 1.05 1113 200 0.5 1.6 1.5 1.3 1.2 0"/>
    <general name="quad_fem_l" class="muscle" tendon="quad_fem_l_tendon" lengthrange="0.01 1" gainprm="0.75 1.05 381 200 0.5 1.6 1.5 1.3 1.2 0" biasprm="0.75 1.05 381 200 0.5 1.6 1.5 1.3 1.2 0"/>
    <general name="gem_l" class="muscle" tendon="gem_l_tendon" lengthrange="0.01 1" gainprm="0.75 1.05 164 200 0.5 1.6 1.5 1.3 1.2 0" biasprm="0.75 1.05 164 200 0.5 1.6 1.5 1.3 1.2 0"/>
    <general name="peri_l" class="muscle" tendon="peri_l_tendon" lengthrange="0.01 1" gainprm="0.75 1.05 444 200 0.5 1.6 1.5 1.3 1.2 0" biasprm="0.75 1.05 444 200 0.5 1.6 1.5 1.3 1.2 0"/>
    <general name="rect_fem_l" class="muscle" tendon="rect_fem_l_tendon" lengthrange="0.01 1" gainprm="0.75 1.05 1169 200 0.5 1.6 1.5 1.3 1.2 0" biasprm="0.75 1.05 1169 200 0.5 1.6 1.5 1.3 1.2 0"/>
    <general name="vas_med_l" class="muscle" tendon="vas_med_l_tendon" lengthrange="0.01 1" gainprm="0.75 1.05 1294 200 0.5 1.6 1.5 1.3 1.2 0" biasprm="0.75 1.05 1294 200 0.5 1.6 1.5 1.3 1.2 0"/>
    <general name="vas_int_l" class="muscle" tendon="vas_int_l_tendon" lengthrange="0.01 1" gainprm="0.75 1.05 1365 200 0.5 1.6 1.5 1.3 1.2 0" biasprm="0.75 1.05 1365 200 0.5 1.6 1.5 1.3 1.2 0"/>
    <general name="vas_lat_l" class="muscle" tendon="vas_lat_l_tendon" lengthrange="0.01 1" gainprm="0.75 1.05 1871 200 0.5 1.6 1.5 1.3 1.2 0" biasprm="0.75 1.05 1871 200 0.5 1.6 1.5 1.3 1.2 0"/>
    <general name="ercspn_r" class="muscle" tendon="ercspn_r_tendon" lengthrange="0.01 1" gainprm="0.75 1.05 2500 200 0.5 1.6 1.5 1.3 1.2 0" biasprm="0.75 1.05 2500 200 0.5 1.6 1.5 1.3 1.2 0"/>
    <general name="ercspn_l" class="muscle" tendon="ercspn_l_tendon" lengthrange="0.01 1" gainprm="0.75 1.05 2500 200 0.5 1.6 1.5 1.3 1.2 0" biasprm="0.75 1.05 2500 200 0.5 1.6 1.5 1.3 1.2 0"/>
    <general name="intobl_r" class="muscle" tendon="intobl_r_tendon" lengthrange="0.01 1" gainprm="0.75 1.05 900 200 0.5 1.6 1.5 1.3 1.2 0" biasprm="0.75 1.05 900 200 0.5 1.6 1.5 1.3 1.2 0"/>
    <general name="intobl_l" class="muscle" tendon="intobl_l_tendon" lengthrange="0.01 1" gainprm="0.75 1.05 900 200 0.5 1.6 1.5 1.3 1.2 0" biasprm="0.75 1.05 900 200 0.5 1.6 1.5 1.3 1.2 0"/>
    <general name="extobl_r" class="muscle" tendon="extobl_r_tendon" lengthrange="0.01 1" gainprm="0.75 1.05 900 200 0.5 1.6 1.5 1.3 1.2 0" biasprm="0.75 1.05 900 200 0.5 1.6 1.5 1.3 1.2 0"/>
    <general name="extobl_l" class="muscle" tendon="extobl_l_tendon" lengthrange="0.01 1" gainprm="0.75 1.05 900 200 0.5 1.6 1.5 1.3 1.2 0" biasprm="0.75 1.05 900 200 0.5 1.6 1.5 1.3 1.2 0"/>
  </actuator>
  <keyframe>
    <key name="default-pose" qpos="0 0.95 0 0 0 0 0 0 0 -0.003639 -0.3957 0 0 0 0 -0.0342 -0.03615 -0.04135 -0.03045 -0.02602 -0.03341 -0.03759 0.06259 0.02032 0.05687 0.02128 0.05647 0.02476 0.06077 0.01899 0.03571 -0.2867 -0.0001308 0.03497 -0.2883 -0.0001769 -0.2234 0.02673 0.02761 -0.2702 0.03933 0.02678 -0.2718 0.03917 -0.02915 -0.4015 -0.02562 -0.02938 -0.4012 0 0 0 -0.003639 -0.3957 0 0 0 -0.0342 -0.03615 -0.04135 -0.03045 0.06259 0.02032 0.05687 0.02128 0.05647 0.02476 0.06077 0.01899 0.03497 -0.2883 -0.0001769 -0.2234 0.02673 0.02761 -0.2702 0.03933 0.02678 -0.2718 0.03917 0 0 0 -0.0288 -0.0805 -0.0288 -0.0805 0.0816 -0.0288 -0.0805 -0.0288 -0.0805 -0.0816"/>
  </keyframe>
</mujoco>
